Workbook

Sheet Summary
A1: Summary by quarter
A2: Every number is a formula over the Events sheet. 'Rule pass' = front expiry within 14 sessions of the last close before results (the playbook's run-up rule).
A3: Quarter | B3: Period | C3: Results events | D3: After close | E3: During market | F3: Weekend / holiday | G3: Avg three-day sum % | H3: % three-day positive | I3: Avg excess vs Nifty % | J3: Avg size of reaction move % | K3: % sales up YoY | L3: % profit up YoY | M3: Avg EBITDA margin chg YoY (pts) | N3: Avg expected move % (options) | O3: Avg actual / expected move (x) | P3: Avg IV drop % | Q3: Run-up trades (rule pass) | R3: Run-up avg return % (rule pass) | S3: Run-up win rate (rule pass)
A4: Q4 FY21 | B4: Jan-Mar 2021 | C4: =COUNTIFS(Events!$A$6:$A$4467,$A4) -> 189 | D4: =COUNTIFS(Events!$A$6:$A$4467,$A4,Events!$L$6:$L$4467,"After close") -> 119 | E4: =COUNTIFS(Events!$A$6:$A$4467,$A4,Events!$L$6:$L$4467,"During market") -> 47 | F4: =COUNTIFS(Events!$A$6:$A$4467,$A4,Events!$L$6:$L$4467,"Non-trading day") -> 21 | G4: =IFERROR(AVERAGEIFS(Events!$U$6:$U$4467,Events!$A$6:$A$4467,$A4),"") -> 0.010705195 | H4: =IFERROR(COUNTIFS(Events!$A$6:$A$4467,$A4,Events!$U$6:$U$4467,">0")/COUNTIFS(Events!$A$6:$A$4467,$A4,Events!$U$6:$U$4467,"<>"),"") -> 0.53439153 | I4: =IFERROR(AVERAGEIFS(Events!$X$6:$X$4467,Events!$A$6:$A$4467,$A4),"") -> 0.0039018948 | J4: =IFERROR(AVERAGEIFS(Events!$AD$6:$AD$4467,Events!$A$6:$A$4467,$A4),"") -> 0.032426424 | K4: =IFERROR(COUNTIFS(Events!$A$6:$A$4467,$A4,Events!$AV$6:$AV$4467,">0")/COUNTIFS(Events!$A$6:$A$4467,$A4,Events!$AV$6:$AV$4467,"<>"),"") -> 0.8 | L4: =IFERROR(COUNTIFS(Events!$A$6:$A$4467,$A4,Events!$BB$6:$BB$4467,">0")/COUNTIFS(Events!$A$6:$A$4467,$A4,Events!$BB$6:$BB$4467,"<>"),"") -> 0.82142857 | M4: =IFERROR(AVERAGEIFS(Events!$AZ$6:$AZ$4467,Events!$A$6:$A$4467,$A4),"") -> 0.088731298 | N4: =IFERROR(AVERAGEIFS(Events!$CK$6:$CK$4467,Events!$A$6:$A$4467,$A4),"") -> 0.085260837 | O4: =IFERROR(AVERAGEIFS(Events!$CL$6:$CL$4467,Events!$A$6:$A$4467,$A4),"") -> 0.41877944 | P4: =IFERROR(AVERAGEIFS(Events!$CJ$6:$CJ$4467,Events!$A$6:$A$4467,$A4),"") -> -0.10430849 | Q4: =COUNTIFS(Events!$A$6:$A$4467,$A4,Events!$CN$6:$CN$4467,"Yes",Events!$CM$6:$CM$4467,"<>") -> 40 | R4: =IFERROR(AVERAGEIFS(Events!$CM$6:$CM$4467,Events!$A$6:$A$4467,$A4,Events!$CN$6:$CN$4467,"Yes"),"") -> -0.067049031 | S4: =IFERROR(COUNTIFS(Events!$A$6:$A$4467,$A4,Events!$CM$6:$CM$4467,">0",Events!$CN$6:$CN$4467,"Yes")/COUNTIFS(Events!$A$6:$A$4467,$A4,Events!$CM$6:$CM$4467,"<>",Events!$CN$6:$CN$4467,"Yes"),"") -> 0.3
A5: Q1 FY22 | B5: Apr-Jun 2021 | C5: =COUNTIFS(Events!$A$6:$A$4467,$A5) -> 191 | D5: =COUNTIFS(Events!$A$6:$A$4467,$A5,Events!$L$6:$L$4467,"After close") -> 98 | E5: =COUNTIFS(Events!$A$6:$A$4467,$A5,Events!$L$6:$L$4467,"During market") -> 71 | F5: =COUNTIFS(Events!$A$6:$A$4467,$A5,Events!$L$6:$L$4467,"Non-trading day") -> 21 | G5: =IFERROR(AVERAGEIFS(Events!$U$6:$U$4467,Events!$A$6:$A$4467,$A5),"") -> 0.0058594489 | H5: =IFERROR(COUNTIFS(Events!$A$6:$A$4467,$A5,Events!$U$6:$U$4467,">0")/COUNTIFS(Events!$A$6:$A$4467,$A5,Events!$U$6:$U$4467,"<>"),"") -> 0.57591623 | I5: =IFERROR(AVERAGEIFS(Events!$X$6:$X$4467,Events!$A$6:$A$4467,$A5),"") -> -0.0017520956 | J5: =IFERROR(AVERAGEIFS(Events!$AD$6:$AD$4467,Events!$A$6:$A$4467,$A5),"") -> 0.028354234 | K5: =IFERROR(COUNTIFS(Events!$A$6:$A$4467,$A5,Events!$AV$6:$AV$4467,">0")/COUNTIFS(Events!$A$6:$A$4467,$A5,Events!$AV$6:$AV$4467,"<>"),"") -> 0.87134503 | L5: =IFERROR(COUNTIFS(Events!$A$6:$A$4467,$A5,Events!$BB$6:$BB$4467,">0")/COUNTIFS(Events!$A$6:$A$4467,$A5,Events!$BB$6:$BB$4467,"<>"),"") -> 0.81538462 | M5: =IFERROR(AVERAGEIFS(Events!$AZ$6:$AZ$4467,Events!$A$6:$A$4467,$A5),"") -> 0.13180538 | N5: =IFERROR(AVERAGEIFS(Events!$CK$6:$CK$4467,Events!$A$6:$A$4467,$A5),"") -> 0.065773861 | O5: =IFERROR(AVERAGEIFS(Events!$CL$6:$CL$4467,Events!$A$6:$A$4467,$A5),"") -> 0.41804914 | P5: =IFERROR(AVERAGEIFS(Events!$CJ$6:$CJ$4467,Events!$A$6:$A$4467,$A5),"") -> -0.11812389 | Q5: =COUNTIFS(Events!$A$6:$A$4467,$A5,Events!$CN$6:$CN$4467,"Yes",Events!$CM$6:$CM$4467,"<>") -> 72 | R5: =IFERROR(AVERAGEIFS(Events!$CM$6:$CM$4467,Events!$A$6:$A$4467,$A5,Events!$CN$6:$CN$4467,"Yes"),"") -> -0.0046021713 | S5: =IFERROR(COUNTIFS(Events!$A$6:$A$4467,$A5,Events!$CM$6:$CM$4467,">0",Events!$CN$6:$CN$4467,"Yes")/COUNTIFS(Events!$A$6:$A$4467,$A5,Events!$CM$6:$CM$4467,"<>",Events!$CN$6:$CN$4467,"Yes"),"") -> 0.38888889
A6: Q2 FY22 | B6: Jul-Sep 2021 | C6: =COUNTIFS(Events!$A$6:$A$4467,$A6) -> 193 | D6: =COUNTIFS(Events!$A$6:$A$4467,$A6,Events!$L$6:$L$4467,"After close") -> 112 | E6: =COUNTIFS(Events!$A$6:$A$4467,$A6,Events!$L$6:$L$4467,"During market") -> 64 | F6: =COUNTIFS(Events!$A$6:$A$4467,$A6,Events!$L$6:$L$4467,"Non-trading day") -> 16 | G6: =IFERROR(AVERAGEIFS(Events!$U$6:$U$4467,Events!$A$6:$A$4467,$A6),"") -> -0.0066521881 | H6: =IFERROR(COUNTIFS(Events!$A$6:$A$4467,$A6,Events!$U$6:$U$4467,">0")/COUNTIFS(Events!$A$6:$A$4467,$A6,Events!$U$6:$U$4467,"<>"),"") -> 0.43005181 | I6: =IFERROR(AVERAGEIFS(Events!$X$6:$X$4467,Events!$A$6:$A$4467,$A6),"") -> -0.0015216204 | J6: =IFERROR(AVERAGEIFS(Events!$AD$6:$AD$4467,Events!$A$6:$A$4467,$A6),"") -> 0.032970392 | K6: =IFERROR(COUNTIFS(Events!$A$6:$A$4467,$A6,Events!$AV$6:$AV$4467,">0")/COUNTIFS(Events!$A$6:$A$4467,$A6,Events!$AV$6:$AV$4467,"<>"),"") -> 0.85142857 | L6: =IFERROR(COUNTIFS(Events!$A$6:$A$4467,$A6,Events!$BB$6:$BB$4467,">0")/COUNTIFS(Events!$A$6:$A$4467,$A6,Events!$BB$6:$BB$4467,"<>"),"") -> 0.80745342 | M6: =IFERROR(AVERAGEIFS(Events!$AZ$6:$AZ$4467,Events!$A$6:$A$4467,$A6),"") -> 0.15237023 | N6: =IFERROR(AVERAGEIFS(Events!$CK$6:$CK$4467,Events!$A$6:$A$4467,$A6),"") -> 0.087063293 | O6: =IFERROR(AVERAGEIFS(Events!$CL$6:$CL$4467,Events!$A$6:$A$4467,$A6),"") -> 0.41284431 | P6: =IFERROR(AVERAGEIFS(Events!$CJ$6:$CJ$4467,Events!$A$6:$A$4467,$A6),"") -> -0.12755009 | Q6: =COUNTIFS(Events!$A$6:$A$4467,$A6,Events!$CN$6:$CN$4467,"Yes",Events!$CM$6:$CM$4467,"<>") -> 61 | R6: =IFERROR(AVERAGEIFS(Events!$CM$6:$CM$4467,Events!$A$6:$A$4467,$A6,Events!$CN$6:$CN$4467,"Yes"),"") -> -0.035104556 | S6: =IFERROR(COUNTIFS(Events!$A$6:$A$4467,$A6,Events!$CM$6:$CM$4467,">0",Events!$CN$6:$CN$4467,"Yes")/COUNTIFS(Events!$A$6:$A$4467,$A6,Events!$CM$6:$CM$4467,"<>",Events!$CN$6:$CN$4467,"Yes"),"") -> 0.3442623
A7: Q3 FY22 | B7: Oct-Dec 2021 | C7: =COUNTIFS(Events!$A$6:$A$4467,$A7) -> 195 | D7: =COUNTIFS(Events!$A$6:$A$4467,$A7,Events!$L$6:$L$4467,"After close") -> 116 | E7: =COUNTIFS(Events!$A$6:$A$4467,$A7,Events!$L$6:$L$4467,"During market") -> 63 | F7: =COUNTIFS(Events!$A$6:$A$4467,$A7,Events!$L$6:$L$4467,"Non-trading day") -> 16 | G7: =IFERROR(AVERAGEIFS(Events!$U$6:$U$4467,Events!$A$6:$A$4467,$A7),"") -> -0.0075208755 | H7: =IFERROR(COUNTIFS(Events!$A$6:$A$4467,$A7,Events!$U$6:$U$4467,">0")/COUNTIFS(Events!$A$6:$A$4467,$A7,Events!$U$6:$U$4467,"<>"),"") -> 0.44102564 | I7: =IFERROR(AVERAGEIFS(Events!$X$6:$X$4467,Events!$A$6:$A$4467,$A7),"") -> 6.5916685e-05 | J7: =IFERROR(AVERAGEIFS(Events!$AD$6:$AD$4467,Events!$A$6:$A$4467,$A7),"") -> 0.02976176 | K7: =IFERROR(COUNTIFS(Events!$A$6:$A$4467,$A7,Events!$AV$6:$AV$4467,">0")/COUNTIFS(Events!$A$6:$A$4467,$A7,Events!$AV$6:$AV$4467,"<>"),"") -> 0.84023669 | L7: =IFERROR(COUNTIFS(Events!$A$6:$A$4467,$A7,Events!$BB$6:$BB$4467,">0")/COUNTIFS(Events!$A$6:$A$4467,$A7,Events!$BB$6:$BB$4467,"<>"),"") -> 0.63522013 | M7: =IFERROR(AVERAGEIFS(Events!$AZ$6:$AZ$4467,Events!$A$6:$A$4467,$A7),"") -> 0.029874892 | N7: =IFERROR(AVERAGEIFS(Events!$CK$6:$CK$4467,Events!$A$6:$A$4467,$A7),"") -> 0.074243253 | O7: =IFERROR(AVERAGEIFS(Events!$CL$6:$CL$4467,Events!$A$6:$A$4467,$A7),"") -> 0.39626993 | P7: =IFERROR(AVERAGEIFS(Events!$CJ$6:$CJ$4467,Events!$A$6:$A$4467,$A7),"") -> -0.071629841 | Q7: =COUNTIFS(Events!$A$6:$A$4467,$A7,Events!$CN$6:$CN$4467,"Yes",Events!$CM$6:$CM$4467,"<>") -> 64 | R7: =IFERROR(AVERAGEIFS(Events!$CM$6:$CM$4467,Events!$A$6:$A$4467,$A7,Events!$CN$6:$CN$4467,"Yes"),"") -> -0.08038067 | S7: =IFERROR(COUNTIFS(Events!$A$6:$A$4467,$A7,Events!$CM$6:$CM$4467,">0",Events!$CN$6:$CN$4467,"Yes")/COUNTIFS(Events!$A$6:$A$4467,$A7,Events!$CM$6:$CM$4467,"<>",Events!$CN$6:$CN$4467,"Yes"),"") -> 0.21875
A8: Q4 FY22 | B8: Jan-Mar 2022 | C8: =COUNTIFS(Events!$A$6:$A$4467,$A8) -> 197 | D8: =COUNTIFS(Events!$A$6:$A$4467,$A8,Events!$L$6:$L$4467,"After close") -> 132 | E8: =COUNTIFS(Events!$A$6:$A$4467,$A8,Events!$L$6:$L$4467,"During market") -> 45 | F8: =COUNTIFS(Events!$A$6:$A$4467,$A8,Events!$L$6:$L$4467,"Non-trading day") -> 19 | G8: =IFERROR(AVERAGEIFS(Events!$U$6:$U$4467,Events!$A$6:$A$4467,$A8),"") -> -0.0019315281 | H8: =IFERROR(COUNTIFS(Events!$A$6:$A$4467,$A8,Events!$U$6:$U$4467,">0")/COUNTIFS(Events!$A$6:$A$4467,$A8,Events!$U$6:$U$4467,"<>"),"") -> 0.46192893 | I8: =IFERROR(AVERAGEIFS(Events!$X$6:$X$4467,Events!$A$6:$A$4467,$A8),"") -> 0.00083488031 | J8: =IFERROR(AVERAGEIFS(Events!$AD$6:$AD$4467,Events!$A$6:$A$4467,$A8),"") -> 0.036187332 | K8: =IFERROR(COUNTIFS(Events!$A$6:$A$4467,$A8,Events!$AV$6:$AV$4467,">0")/COUNTIFS(Events!$A$6:$A$4467,$A8,Events!$AV$6:$AV$4467,"<>"),"") -> 0.87777778 | L8: =IFERROR(COUNTIFS(Events!$A$6:$A$4467,$A8,Events!$BB$6:$BB$4467,">0")/COUNTIFS(Events!$A$6:$A$4467,$A8,Events!$BB$6:$BB$4467,"<>"),"") -> 0.62130178 | M8: =IFERROR(AVERAGEIFS(Events!$AZ$6:$AZ$4467,Events!$A$6:$A$4467,$A8),"") -> -0.023466717 | N8: =IFERROR(AVERAGEIFS(Events!$CK$6:$CK$4467,Events!$A$6:$A$4467,$A8),"") -> 0.07953462 | O8: =IFERROR(AVERAGEIFS(Events!$CL$6:$CL$4467,Events!$A$6:$A$4467,$A8),"") -> 0.4518504 | P8: =IFERROR(AVERAGEIFS(Events!$CJ$6:$CJ$4467,Events!$A$6:$A$4467,$A8),"") -> -0.061597619 | Q8: =COUNTIFS(Events!$A$6:$A$4467,$A8,Events!$CN$6:$CN$4467,"Yes",Events!$CM$6:$CM$4467,"<>") -> 50 | R8: =IFERROR(AVERAGEIFS(Events!$CM$6:$CM$4467,Events!$A$6:$A$4467,$A8,Events!$CN$6:$CN$4467,"Yes"),"") -> 0.083495076 | S8: =IFERROR(COUNTIFS(Events!$A$6:$A$4467,$A8,Events!$CM$6:$CM$4467,">0",Events!$CN$6:$CN$4467,"Yes")/COUNTIFS(Events!$A$6:$A$4467,$A8,Events!$CM$6:$CM$4467,"<>",Events!$CN$6:$CN$4467,"Yes"),"") -> 0.54
A9: Q1 FY23 | B9: Apr-Jun 2022 | C9: =COUNTIFS(Events!$A$6:$A$4467,$A9) -> 197 | D9: =COUNTIFS(Events!$A$6:$A$4467,$A9,Events!$L$6:$L$4467,"After close") -> 104 | E9: =COUNTIFS(Events!$A$6:$A$4467,$A9,Events!$L$6:$L$4467,"During market") -> 72 | F9: =COUNTIFS(Events!$A$6:$A$4467,$A9,Events!$L$6:$L$4467,"Non-trading day") -> 21 | G9: =IFERROR(AVERAGEIFS(Events!$U$6:$U$4467,Events!$A$6:$A$4467,$A9),"") -> 0.0090473029 | H9: =IFERROR(COUNTIFS(Events!$A$6:$A$4467,$A9,Events!$U$6:$U$4467,">0")/COUNTIFS(Events!$A$6:$A$4467,$A9,Events!$U$6:$U$4467,"<>"),"") -> 0.55837563 | I9: =IFERROR(AVERAGEIFS(Events!$X$6:$X$4467,Events!$A$6:$A$4467,$A9),"") -> -0.0053427416 | J9: =IFERROR(AVERAGEIFS(Events!$AD$6:$AD$4467,Events!$A$6:$A$4467,$A9),"") -> 0.026505183 | K9: =IFERROR(COUNTIFS(Events!$A$6:$A$4467,$A9,Events!$AV$6:$AV$4467,">0")/COUNTIFS(Events!$A$6:$A$4467,$A9,Events!$AV$6:$AV$4467,"<>"),"") -> 0.86896552 | L9: =IFERROR(COUNTIFS(Events!$A$6:$A$4467,$A9,Events!$BB$6:$BB$4467,">0")/COUNTIFS(Events!$A$6:$A$4467,$A9,Events!$BB$6:$BB$4467,"<>"),"") -> 0.70769231 | M9: =IFERROR(AVERAGEIFS(Events!$AZ$6:$AZ$4467,Events!$A$6:$A$4467,$A9),"") -> 0.017465402 | N9: =IFERROR(AVERAGEIFS(Events!$CK$6:$CK$4467,Events!$A$6:$A$4467,$A9),"") -> 0.067476234 | O9: =IFERROR(AVERAGEIFS(Events!$CL$6:$CL$4467,Events!$A$6:$A$4467,$A9),"") -> 0.38709844 | P9: =IFERROR(AVERAGEIFS(Events!$CJ$6:$CJ$4467,Events!$A$6:$A$4467,$A9),"") -> -0.065711374 | Q9: =COUNTIFS(Events!$A$6:$A$4467,$A9,Events!$CN$6:$CN$4467,"Yes",Events!$CM$6:$CM$4467,"<>") -> 82 | R9: =IFERROR(AVERAGEIFS(Events!$CM$6:$CM$4467,Events!$A$6:$A$4467,$A9,Events!$CN$6:$CN$4467,"Yes"),"") -> -0.0088894086 | S9: =IFERROR(COUNTIFS(Events!$A$6:$A$4467,$A9,Events!$CM$6:$CM$4467,">0",Events!$CN$6:$CN$4467,"Yes")/COUNTIFS(Events!$A$6:$A$4467,$A9,Events!$CM$6:$CM$4467,"<>",Events!$CN$6:$CN$4467,"Yes"),"") -> 0.30487805
A10: Q2 FY23 | B10: Jul-Sep 2022 | C10: =COUNTIFS(Events!$A$6:$A$4467,$A10) -> 197 | D10: =COUNTIFS(Events!$A$6:$A$4467,$A10,Events!$L$6:$L$4467,"After close") -> 101 | E10: =COUNTIFS(Events!$A$6:$A$4467,$A10,Events!$L$6:$L$4467,"During market") -> 69 | F10: =COUNTIFS(Events!$A$6:$A$4467,$A10,Events!$L$6:$L$4467,"Non-trading day") -> 27 | G10: =IFERROR(AVERAGEIFS(Events!$U$6:$U$4467,Events!$A$6:$A$4467,$A10),"") -> 0.0059134515 | H10: =IFERROR(COUNTIFS(Events!$A$6:$A$4467,$A10,Events!$U$6:$U$4467,">0")/COUNTIFS(Events!$A$6:$A$4467,$A10,Events!$U$6:$U$4467,"<>"),"") -> 0.52284264 | I10: =IFERROR(AVERAGEIFS(Events!$X$6:$X$4467,Events!$A$6:$A$4467,$A10),"") -> -0.0034610825 | J10: =IFERROR(AVERAGEIFS(Events!$AD$6:$AD$4467,Events!$A$6:$A$4467,$A10),"") -> 0.027237163 | K10: =IFERROR(COUNTIFS(Events!$A$6:$A$4467,$A10,Events!$AV$6:$AV$4467,">0")/COUNTIFS(Events!$A$6:$A$4467,$A10,Events!$AV$6:$AV$4467,"<>"),"") -> 0.89142857 | L10: =IFERROR(COUNTIFS(Events!$A$6:$A$4467,$A10,Events!$BB$6:$BB$4467,">0")/COUNTIFS(Events!$A$6:$A$4467,$A10,Events!$BB$6:$BB$4467,"<>"),"") -> 0.62111801 | M10: =IFERROR(AVERAGEIFS(Events!$AZ$6:$AZ$4467,Events!$A$6:$A$4467,$A10),"") -> -0.17847309 | N10: =IFERROR(AVERAGEIFS(Events!$CK$6:$CK$4467,Events!$A$6:$A$4467,$A10),"") -> 0.060571876 | O10: =IFERROR(AVERAGEIFS(Events!$CL$6:$CL$4467,Events!$A$6:$A$4467,$A10),"") -> 0.47580877 | P10: =IFERROR(AVERAGEIFS(Events!$CJ$6:$CJ$4467,Events!$A$6:$A$4467,$A10),"") -> -0.10255836 | Q10: =COUNTIFS(Events!$A$6:$A$4467,$A10,Events!$CN$6:$CN$4467,"Yes",Events!$CM$6:$CM$4467,"<>") -> 94 | R10: =IFERROR(AVERAGEIFS(Events!$CM$6:$CM$4467,Events!$A$6:$A$4467,$A10,Events!$CN$6:$CN$4467,"Yes"),"") -> -0.074778859 | S10: =IFERROR(COUNTIFS(Events!$A$6:$A$4467,$A10,Events!$CM$6:$CM$4467,">0",Events!$CN$6:$CN$4467,"Yes")/COUNTIFS(Events!$A$6:$A$4467,$A10,Events!$CM$6:$CM$4467,"<>",Events!$CN$6:$CN$4467,"Yes"),"") -> 0.21276596
A11: Q3 FY23 | B11: Oct-Dec 2022 | C11: =COUNTIFS(Events!$A$6:$A$4467,$A11) -> 199 | D11: =COUNTIFS(Events!$A$6:$A$4467,$A11,Events!$L$6:$L$4467,"After close") -> 123 | E11: =COUNTIFS(Events!$A$6:$A$4467,$A11,Events!$L$6:$L$4467,"During market") -> 64 | F11: =COUNTIFS(Events!$A$6:$A$4467,$A11,Events!$L$6:$L$4467,"Non-trading day") -> 11 | G11: =IFERROR(AVERAGEIFS(Events!$U$6:$U$4467,Events!$A$6:$A$4467,$A11),"") -> -0.00015474327 | H11: =IFERROR(COUNTIFS(Events!$A$6:$A$4467,$A11,Events!$U$6:$U$4467,">0")/COUNTIFS(Events!$A$6:$A$4467,$A11,Events!$U$6:$U$4467,"<>"),"") -> 0.46733668 | I11: =IFERROR(AVERAGEIFS(Events!$X$6:$X$4467,Events!$A$6:$A$4467,$A11),"") -> 0.00046620672 | J11: =IFERROR(AVERAGEIFS(Events!$AD$6:$AD$4467,Events!$A$6:$A$4467,$A11),"") -> 0.027399293 | K11: =IFERROR(COUNTIFS(Events!$A$6:$A$4467,$A11,Events!$AV$6:$AV$4467,">0")/COUNTIFS(Events!$A$6:$A$4467,$A11,Events!$AV$6:$AV$4467,"<>"),"") -> 0.85795455 | L11: =IFERROR(COUNTIFS(Events!$A$6:$A$4467,$A11,Events!$BB$6:$BB$4467,">0")/COUNTIFS(Events!$A$6:$A$4467,$A11,Events!$BB$6:$BB$4467,"<>"),"") -> 0.6686747 | M11: =IFERROR(AVERAGEIFS(Events!$AZ$6:$AZ$4467,Events!$A$6:$A$4467,$A11),"") -> -0.061465212 | N11: =IFERROR(AVERAGEIFS(Events!$CK$6:$CK$4467,Events!$A$6:$A$4467,$A11),"") -> 0.063115118 | O11: =IFERROR(AVERAGEIFS(Events!$CL$6:$CL$4467,Events!$A$6:$A$4467,$A11),"") -> 0.45728979 | P11: =IFERROR(AVERAGEIFS(Events!$CJ$6:$CJ$4467,Events!$A$6:$A$4467,$A11),"") -> -0.097020331 | Q11: =COUNTIFS(Events!$A$6:$A$4467,$A11,Events!$CN$6:$CN$4467,"Yes",Events!$CM$6:$CM$4467,"<>") -> 66 | R11: =IFERROR(AVERAGEIFS(Events!$CM$6:$CM$4467,Events!$A$6:$A$4467,$A11,Events!$CN$6:$CN$4467,"Yes"),"") -> -0.082838321 | S11: =IFERROR(COUNTIFS(Events!$A$6:$A$4467,$A11,Events!$CM$6:$CM$4467,">0",Events!$CN$6:$CN$4467,"Yes")/COUNTIFS(Events!$A$6:$A$4467,$A11,Events!$CM$6:$CM$4467,"<>",Events!$CN$6:$CN$4467,"Yes"),"") -> 0.28787879
A12: Q4 FY23 | B12: Jan-Mar 2023 | C12: =COUNTIFS(Events!$A$6:$A$4467,$A12) -> 200 | D12: =COUNTIFS(Events!$A$6:$A$4467,$A12,Events!$L$6:$L$4467,"After close") -> 120 | E12: =COUNTIFS(Events!$A$6:$A$4467,$A12,Events!$L$6:$L$4467,"During market") -> 57 | F12: =COUNTIFS(Events!$A$6:$A$4467,$A12,Events!$L$6:$L$4467,"Non-trading day") -> 21 | G12: =IFERROR(AVERAGEIFS(Events!$U$6:$U$4467,Events!$A$6:$A$4467,$A12),"") -> 0.0060714588 | H12: =IFERROR(COUNTIFS(Events!$A$6:$A$4467,$A12,Events!$U$6:$U$4467,">0")/COUNTIFS(Events!$A$6:$A$4467,$A12,Events!$U$6:$U$4467,"<>"),"") -> 0.55 | I12: =IFERROR(AVERAGEIFS(Events!$X$6:$X$4467,Events!$A$6:$A$4467,$A12),"") -> 7.5573827e-05 | J12: =IFERROR(AVERAGEIFS(Events!$AD$6:$AD$4467,Events!$A$6:$A$4467,$A12),"") -> 0.02852567 | K12: =IFERROR(COUNTIFS(Events!$A$6:$A$4467,$A12,Events!$AV$6:$AV$4467,">0")/COUNTIFS(Events!$A$6:$A$4467,$A12,Events!$AV$6:$AV$4467,"<>"),"") -> 0.86170213 | L12: =IFERROR(COUNTIFS(Events!$A$6:$A$4467,$A12,Events!$BB$6:$BB$4467,">0")/COUNTIFS(Events!$A$6:$A$4467,$A12,Events!$BB$6:$BB$4467,"<>"),"") -> 0.67630058 | M12: =IFERROR(AVERAGEIFS(Events!$AZ$6:$AZ$4467,Events!$A$6:$A$4467,$A12),"") -> 0.010168081 | N12: =IFERROR(AVERAGEIFS(Events!$CK$6:$CK$4467,Events!$A$6:$A$4467,$A12),"") -> 0.057593671 | O12: =IFERROR(AVERAGEIFS(Events!$CL$6:$CL$4467,Events!$A$6:$A$4467,$A12),"") -> 0.48159234 | P12: =IFERROR(AVERAGEIFS(Events!$CJ$6:$CJ$4467,Events!$A$6:$A$4467,$A12),"") -> -0.16593494 | Q12: =COUNTIFS(Events!$A$6:$A$4467,$A12,Events!$CN$6:$CN$4467,"Yes",Events!$CM$6:$CM$4467,"<>") -> 62 | R12: =IFERROR(AVERAGEIFS(Events!$CM$6:$CM$4467,Events!$A$6:$A$4467,$A12,Events!$CN$6:$CN$4467,"Yes"),"") -> 0.043146095 | S12: =IFERROR(COUNTIFS(Events!$A$6:$A$4467,$A12,Events!$CM$6:$CM$4467,">0",Events!$CN$6:$CN$4467,"Yes")/COUNTIFS(Events!$A$6:$A$4467,$A12,Events!$CM$6:$CM$4467,"<>",Events!$CN$6:$CN$4467,"Yes"),"") -> 0.51612903
A13: Q1 FY24 | B13: Apr-Jun 2023 | C13: =COUNTIFS(Events!$A$6:$A$4467,$A13) -> 200 | D13: =COUNTIFS(Events!$A$6:$A$4467,$A13,Events!$L$6:$L$4467,"After close") -> 112 | E13: =COUNTIFS(Events!$A$6:$A$4467,$A13,Events!$L$6:$L$4467,"During market") -> 72 | F13: =COUNTIFS(Events!$A$6:$A$4467,$A13,Events!$L$6:$L$4467,"Non-trading day") -> 15 | G13: =IFERROR(AVERAGEIFS(Events!$U$6:$U$4467,Events!$A$6:$A$4467,$A13),"") -> 0.00070859285 | H13: =IFERROR(COUNTIFS(Events!$A$6:$A$4467,$A13,Events!$U$6:$U$4467,">0")/COUNTIFS(Events!$A$6:$A$4467,$A13,Events!$U$6:$U$4467,"<>"),"") -> 0.48241206 | I13: =IFERROR(AVERAGEIFS(Events!$X$6:$X$4467,Events!$A$6:$A$4467,$A13),"") -> 0.0031089281 | J13: =IFERROR(AVERAGEIFS(Events!$AD$6:$AD$4467,Events!$A$6:$A$4467,$A13),"") -> 0.025281975 | K13: =IFERROR(COUNTIFS(Events!$A$6:$A$4467,$A13,Events!$AV$6:$AV$4467,">0")/COUNTIFS(Events!$A$6:$A$4467,$A13,Events!$AV$6:$AV$4467,"<>"),"") -> 0.81456954 | L13: =IFERROR(COUNTIFS(Events!$A$6:$A$4467,$A13,Events!$BB$6:$BB$4467,">0")/COUNTIFS(Events!$A$6:$A$4467,$A13,Events!$BB$6:$BB$4467,"<>"),"") -> 0.75539568 | M13: =IFERROR(AVERAGEIFS(Events!$AZ$6:$AZ$4467,Events!$A$6:$A$4467,$A13),"") -> 0.024801064 | N13: =IFERROR(AVERAGEIFS(Events!$CK$6:$CK$4467,Events!$A$6:$A$4467,$A13),"") -> 0.063094073 | O13: =IFERROR(AVERAGEIFS(Events!$CL$6:$CL$4467,Events!$A$6:$A$4467,$A13),"") -> 0.39778691 | P13: =IFERROR(AVERAGEIFS(Events!$CJ$6:$CJ$4467,Events!$A$6:$A$4467,$A13),"") -> -0.12208439 | Q13: =COUNTIFS(Events!$A$6:$A$4467,$A13,Events!$CN$6:$CN$4467,"Yes",Events!$CM$6:$CM$4467,"<>") -> 57 | R13: =IFERROR(AVERAGEIFS(Events!$CM$6:$CM$4467,Events!$A$6:$A$4467,$A13,Events!$CN$6:$CN$4467,"Yes"),"") -> 0.06443682 | S13: =IFERROR(COUNTIFS(Events!$A$6:$A$4467,$A13,Events!$CM$6:$CM$4467,">0",Events!$CN$6:$CN$4467,"Yes")/COUNTIFS(Events!$A$6:$A$4467,$A13,Events!$CM$6:$CM$4467,"<>",Events!$CN$6:$CN$4467,"Yes"),"") -> 0.31578947
A14: Q2 FY24 | B14: Jul-Sep 2023 | C14: =COUNTIFS(Events!$A$6:$A$4467,$A14) -> 202 | D14: =COUNTIFS(Events!$A$6:$A$4467,$A14,Events!$L$6:$L$4467,"After close") -> 109 | E14: =COUNTIFS(Events!$A$6:$A$4467,$A14,Events!$L$6:$L$4467,"During market") -> 71 | F14: =COUNTIFS(Events!$A$6:$A$4467,$A14,Events!$L$6:$L$4467,"Non-trading day") -> 20 | G14: =IFERROR(AVERAGEIFS(Events!$U$6:$U$4467,Events!$A$6:$A$4467,$A14),"") -> 0.0093807369 | H14: =IFERROR(COUNTIFS(Events!$A$6:$A$4467,$A14,Events!$U$6:$U$4467,">0")/COUNTIFS(Events!$A$6:$A$4467,$A14,Events!$U$6:$U$4467,"<>"),"") -> 0.55940594 | I14: =IFERROR(AVERAGEIFS(Events!$X$6:$X$4467,Events!$A$6:$A$4467,$A14),"") -> 0.0085039222 | J14: =IFERROR(AVERAGEIFS(Events!$AD$6:$AD$4467,Events!$A$6:$A$4467,$A14),"") -> 0.023915659 | K14: =IFERROR(COUNTIFS(Events!$A$6:$A$4467,$A14,Events!$AV$6:$AV$4467,">0")/COUNTIFS(Events!$A$6:$A$4467,$A14,Events!$AV$6:$AV$4467,"<>"),"") -> 0.81967213 | L14: =IFERROR(COUNTIFS(Events!$A$6:$A$4467,$A14,Events!$BB$6:$BB$4467,">0")/COUNTIFS(Events!$A$6:$A$4467,$A14,Events!$BB$6:$BB$4467,"<>"),"") -> 0.80952381 | M14: =IFERROR(AVERAGEIFS(Events!$AZ$6:$AZ$4467,Events!$A$6:$A$4467,$A14),"") -> 0.03496705 | N14: =IFERROR(AVERAGEIFS(Events!$CK$6:$CK$4467,Events!$A$6:$A$4467,$A14),"") -> 0.054551271 | O14: =IFERROR(AVERAGEIFS(Events!$CL$6:$CL$4467,Events!$A$6:$A$4467,$A14),"") -> 0.45015937 | P14: =IFERROR(AVERAGEIFS(Events!$CJ$6:$CJ$4467,Events!$A$6:$A$4467,$A14),"") -> -0.10259982 | Q14: =COUNTIFS(Events!$A$6:$A$4467,$A14,Events!$CN$6:$CN$4467,"Yes",Events!$CM$6:$CM$4467,"<>") -> 40 | R14: =IFERROR(AVERAGEIFS(Events!$CM$6:$CM$4467,Events!$A$6:$A$4467,$A14,Events!$CN$6:$CN$4467,"Yes"),"") -> -0.015778531 | S14: =IFERROR(COUNTIFS(Events!$A$6:$A$4467,$A14,Events!$CM$6:$CM$4467,">0",Events!$CN$6:$CN$4467,"Yes")/COUNTIFS(Events!$A$6:$A$4467,$A14,Events!$CM$6:$CM$4467,"<>",Events!$CN$6:$CN$4467,"Yes"),"") -> 0.325
A15: Q3 FY24 | B15: Oct-Dec 2023 | C15: =COUNTIFS(Events!$A$6:$A$4467,$A15) -> 203 | D15: =COUNTIFS(Events!$A$6:$A$4467,$A15,Events!$L$6:$L$4467,"After close") -> 115 | E15: =COUNTIFS(Events!$A$6:$A$4467,$A15,Events!$L$6:$L$4467,"During market") -> 74 | F15: =COUNTIFS(Events!$A$6:$A$4467,$A15,Events!$L$6:$L$4467,"Non-trading day") -> 14 | G15: =IFERROR(AVERAGEIFS(Events!$U$6:$U$4467,Events!$A$6:$A$4467,$A15),"") -> 0.0017522894 | H15: =IFERROR(COUNTIFS(Events!$A$6:$A$4467,$A15,Events!$U$6:$U$4467,">0")/COUNTIFS(Events!$A$6:$A$4467,$A15,Events!$U$6:$U$4467,"<>"),"") -> 0.51231527 | I15: =IFERROR(AVERAGEIFS(Events!$X$6:$X$4467,Events!$A$6:$A$4467,$A15),"") -> 0.00037605658 | J15: =IFERROR(AVERAGEIFS(Events!$AD$6:$AD$4467,Events!$A$6:$A$4467,$A15),"") -> 0.038196439 | K15: =IFERROR(COUNTIFS(Events!$A$6:$A$4467,$A15,Events!$AV$6:$AV$4467,">0")/COUNTIFS(Events!$A$6:$A$4467,$A15,Events!$AV$6:$AV$4467,"<>"),"") -> 0.84375 | L15: =IFERROR(COUNTIFS(Events!$A$6:$A$4467,$A15,Events!$BB$6:$BB$4467,">0")/COUNTIFS(Events!$A$6:$A$4467,$A15,Events!$BB$6:$BB$4467,"<>"),"") -> 0.80110497 | M15: =IFERROR(AVERAGEIFS(Events!$AZ$6:$AZ$4467,Events!$A$6:$A$4467,$A15),"") -> 0.028238754 | N15: =IFERROR(AVERAGEIFS(Events!$CK$6:$CK$4467,Events!$A$6:$A$4467,$A15),"") -> 0.078875288 | O15: =IFERROR(AVERAGEIFS(Events!$CL$6:$CL$4467,Events!$A$6:$A$4467,$A15),"") -> 0.49375029 | P15: =IFERROR(AVERAGEIFS(Events!$CJ$6:$CJ$4467,Events!$A$6:$A$4467,$A15),"") -> -0.10010828 | Q15: =COUNTIFS(Events!$A$6:$A$4467,$A15,Events!$CN$6:$CN$4467,"Yes",Events!$CM$6:$CM$4467,"<>") -> 44 | R15: =IFERROR(AVERAGEIFS(Events!$CM$6:$CM$4467,Events!$A$6:$A$4467,$A15,Events!$CN$6:$CN$4467,"Yes"),"") -> 0.19417718 | S15: =IFERROR(COUNTIFS(Events!$A$6:$A$4467,$A15,Events!$CM$6:$CM$4467,">0",Events!$CN$6:$CN$4467,"Yes")/COUNTIFS(Events!$A$6:$A$4467,$A15,Events!$CM$6:$CM$4467,"<>",Events!$CN$6:$CN$4467,"Yes"),"") -> 0.77272727
... A25: Q1 FY27 | B25: Apr-Jun 2026 | C25: =COUNTIFS(Events!$A$6:$A$4467,$A25) -> 212 | D25: =COUNTIFS(Events!$A$6:$A$4467,$A25,Events!$L$6:$L$4467,"After close") -> 114 | E25: =COUNTIFS(Events!$A$6:$A$4467,$A25,Events!$L$6:$L$4467,"During market") -> 80 | F25: =COUNTIFS(Events!$A$6:$A$4467,$A25,Events!$L$6:$L$4467,"Non-trading day") -> 16 | G25: =IFERROR(AVERAGEIFS(Events!$U$6:$U$4467,Events!$A$6:$A$4467,$A25),"") -> 0.0035881287 | H25: =IFERROR(COUNTIFS(Events!$A$6:$A$4467,$A25,Events!$U$6:$U$4467,">0")/COUNTIFS(Events!$A$6:$A$4467,$A25,Events!$U$6:$U$4467,"<>"),"") -> 0.51415094 | I25: =IFERROR(AVERAGEIFS(Events!$X$6:$X$4467,Events!$A$6:$A$4467,$A25),"") -> 0.0011012401 | J25: =IFERROR(AVERAGEIFS(Events!$AD$6:$AD$4467,Events!$A$6:$A$4467,$A25),"") -> 0.030007701 | K25: =IFERROR(COUNTIFS(Events!$A$6:$A$4467,$A25,Events!$AV$6:$AV$4467,">0")/COUNTIFS(Events!$A$6:$A$4467,$A25,Events!$AV$6:$AV$4467,"<>"),"") -> 0.92270531 | L25: =IFERROR(COUNTIFS(Events!$A$6:$A$4467,$A25,Events!$BB$6:$BB$4467,">0")/COUNTIFS(Events!$A$6:$A$4467,$A25,Events!$BB$6:$BB$4467,"<>"),"") -> 0.78606965 | M25: =IFERROR(AVERAGEIFS(Events!$AZ$6:$AZ$4467,Events!$A$6:$A$4467,$A25),"") -> 0.004594922 | N25: =IFERROR(AVERAGEIFS(Events!$CK$6:$CK$4467,Events!$A$6:$A$4467,$A25),"") -> 0.064907961 | O25: =IFERROR(AVERAGEIFS(Events!$CL$6:$CL$4467,Events!$A$6:$A$4467,$A25),"") -> 0.46502498 | P25: =IFERROR(AVERAGEIFS(Events!$CJ$6:$CJ$4467,Events!$A$6:$A$4467,$A25),"") -> -0.14724885 | Q25: =COUNTIFS(Events!$A$6:$A$4467,$A25,Events!$CN$6:$CN$4467,"Yes",Events!$CM$6:$CM$4467,"<>") -> 111 | R25: =IFERROR(AVERAGEIFS(Events!$CM$6:$CM$4467,Events!$A$6:$A$4467,$A25,Events!$CN$6:$CN$4467,"Yes"),"") -> -0.0061018844 | S25: =IFERROR(COUNTIFS(Events!$A$6:$A$4467,$A25,Events!$CM$6:$CM$4467,">0",Events!$CN$6:$CN$4467,"Yes")/COUNTIFS(Events!$A$6:$A$4467,$A25,Events!$CM$6:$CM$4467,"<>",Events!$CN$6:$CN$4467,"Yes"),"") -> 0.33333333
A26: All quarters | C26: =COUNTIFS(Events!$A$6:$A$4467,"<>") -> 4462 | D26: =COUNTIFS(Events!$A$6:$A$4467,"<>",Events!$L$6:$L$4467,"After close") -> 2623 | E26: =COUNTIFS(Events!$A$6:$A$4467,"<>",Events!$L$6:$L$4467,"During market") -> 1419 | F26: =COUNTIFS(Events!$A$6:$A$4467,"<>",Events!$L$6:$L$4467,"Non-trading day") -> 393 | G26: =IFERROR(AVERAGEIFS(Events!$U$6:$U$4467,Events!$A$6:$A$4467,"<>"),"") -> 0.0028108158 | H26: =IFERROR(COUNTIFS(Events!$A$6:$A$4467,"<>",Events!$U$6:$U$4467,">0")/COUNTIFS(Events!$A$6:$A$4467,"<>",Events!$U$6:$U$4467,"<>"),"") -> 0.50381166 | I26: =IFERROR(AVERAGEIFS(Events!$X$6:$X$4467,Events!$A$6:$A$4467,"<>"),"") -> 0.0016344564 | J26: =IFERROR(AVERAGEIFS(Events!$AD$6:$AD$4467,Events!$A$6:$A$4467,"<>"),"") -> 0.030647861 | K26: =IFERROR(COUNTIFS(Events!$A$6:$A$4467,"<>",Events!$AV$6:$AV$4467,">0")/COUNTIFS(Events!$A$6:$A$4467,"<>",Events!$AV$6:$AV$4467,"<>"),"") -> 0.86166299 | L26: =IFERROR(COUNTIFS(Events!$A$6:$A$4467,"<>",Events!$BB$6:$BB$4467,">0")/COUNTIFS(Events!$A$6:$A$4467,"<>",Events!$BB$6:$BB$4467,"<>"),"") -> 0.72437418 | M26: =IFERROR(AVERAGEIFS(Events!$AZ$6:$AZ$4467,Events!$A$6:$A$4467,"<>"),"") -> 0.014142264 | N26: =IFERROR(AVERAGEIFS(Events!$CK$6:$CK$4467,Events!$A$6:$A$4467,"<>"),"") -> 0.067968055 | O26: =IFERROR(AVERAGEIFS(Events!$CL$6:$CL$4467,Events!$A$6:$A$4467,"<>"),"") -> 0.4615053 | P26: =IFERROR(AVERAGEIFS(Events!$CJ$6:$CJ$4467,Events!$A$6:$A$4467,"<>"),"") -> -0.11842411 | Q26: =COUNTIFS(Events!$A$6:$A$4467,"<>",Events!$CN$6:$CN$4467,"Yes",Events!$CM$6:$CM$4467,"<>") -> 1685 | R26: =IFERROR(AVERAGEIFS(Events!$CM$6:$CM$4467,Events!$A$6:$A$4467,"<>",Events!$CN$6:$CN$4467,"Yes"),"") -> 0.018684818 | S26: =IFERROR(COUNTIFS(Events!$A$6:$A$4467,"<>",Events!$CM$6:$CM$4467,">0",Events!$CN$6:$CN$4467,"Yes")/COUNTIFS(Events!$A$6:$A$4467,"<>",Events!$CM$6:$CM$4467,"<>",Events!$CN$6:$CN$4467,"Yes"),"") -> 0.39762611

Sheet By industry
A1: By industry (NSE industry labels)
A2: Formulas over the Events sheet, all 22 quarters.
A3: Industry | B3: Results events | C3: After close | D3: During market | E3: Weekend / holiday | F3: Avg three-day sum % | G3: % three-day positive | H3: Avg excess vs Nifty % | I3: Avg size of reaction move % | J3: % sales up YoY | K3: % profit up YoY | L3: Avg EBITDA margin chg YoY (pts) | M3: Avg expected move % (options) | N3: Avg actual / expected move (x) | O3: Avg IV drop % | P3: Run-up trades (rule pass) | Q3: Run-up avg return % (rule pass) | R3: Run-up win rate (rule pass)
A4: Banks | B4: =COUNTIFS(Events!$F$6:$F$4467,$A4) -> 440 | C4: =COUNTIFS(Events!$F$6:$F$4467,$A4,Events!$L$6:$L$4467,"After close") -> 137 | D4: =COUNTIFS(Events!$F$6:$F$4467,$A4,Events!$L$6:$L$4467,"During market") -> 163 | E4: =COUNTIFS(Events!$F$6:$F$4467,$A4,Events!$L$6:$L$4467,"Non-trading day") -> 140 | F4: =IFERROR(AVERAGEIFS(Events!$U$6:$U$4467,Events!$F$6:$F$4467,$A4),"") -> 0.00090985432 | G4: =IFERROR(COUNTIFS(Events!$F$6:$F$4467,$A4,Events!$U$6:$U$4467,">0")/COUNTIFS(Events!$F$6:$F$4467,$A4,Events!$U$6:$U$4467,"<>"),"") -> 0.49318182 | H4: =IFERROR(AVERAGEIFS(Events!$X$6:$X$4467,Events!$F$6:$F$4467,$A4),"") -> 0.0019649222 | I4: =IFERROR(AVERAGEIFS(Events!$AD$6:$AD$4467,Events!$F$6:$F$4467,$A4),"") -> 0.033672508 | J4: =IFERROR(COUNTIFS(Events!$F$6:$F$4467,$A4,Events!$AV$6:$AV$4467,">0")/COUNTIFS(Events!$F$6:$F$4467,$A4,Events!$AV$6:$AV$4467,"<>"),"") -> 0.85866667 | K4: =IFERROR(COUNTIFS(Events!$F$6:$F$4467,$A4,Events!$BB$6:$BB$4467,">0")/COUNTIFS(Events!$F$6:$F$4467,$A4,Events!$BB$6:$BB$4467,"<>"),"") -> 0.8021978 | L4: =IFERROR(AVERAGEIFS(Events!$AZ$6:$AZ$4467,Events!$F$6:$F$4467,$A4),"") | M4: =IFERROR(AVERAGEIFS(Events!$CK$6:$CK$4467,Events!$F$6:$F$4467,$A4),"") -> 0.069221866 | N4: =IFERROR(AVERAGEIFS(Events!$CL$6:$CL$4467,Events!$F$6:$F$4467,$A4),"") -> 0.53476369 | O4: =IFERROR(AVERAGEIFS(Events!$CJ$6:$CJ$4467,Events!$F$6:$F$4467,$A4),"") -> -0.14621293 | P4: =COUNTIFS(Events!$F$6:$F$4467,$A4,Events!$CN$6:$CN$4467,"Yes",Events!$CM$6:$CM$4467,"<>") -> 167 | Q4: =IFERROR(AVERAGEIFS(Events!$CM$6:$CM$4467,Events!$F$6:$F$4467,$A4,Events!$CN$6:$CN$4467,"Yes"),"") -> 0.065146288 | R4: =IFERROR(COUNTIFS(Events!$F$6:$F$4467,$A4,Events!$CM$6:$CM$4467,">0",Events!$CN$6:$CN$4467,"Yes")/COUNTIFS(Events!$F$6:$F$4467,$A4,Events!$CM$6:$CM$4467,"<>",Events!$CN$6:$CN$4467,"Yes"),"") -> 0.4251497
A5: Computers - Software | B5: =COUNTIFS(Events!$F$6:$F$4467,$A5) -> 294 | C5: =COUNTIFS(Events!$F$6:$F$4467,$A5,Events!$L$6:$L$4467,"After close") -> 226 | D5: =COUNTIFS(Events!$F$6:$F$4467,$A5,Events!$L$6:$L$4467,"During market") -> 43 | E5: =COUNTIFS(Events!$F$6:$F$4467,$A5,Events!$L$6:$L$4467,"Non-trading day") -> 11 | F5: =IFERROR(AVERAGEIFS(Events!$U$6:$U$4467,Events!$F$6:$F$4467,$A5),"") -> 0.0071002116 | G5: =IFERROR(COUNTIFS(Events!$F$6:$F$4467,$A5,Events!$U$6:$U$4467,">0")/COUNTIFS(Events!$F$6:$F$4467,$A5,Events!$U$6:$U$4467,"<>"),"") -> 0.53061224 | H5: =IFERROR(AVERAGEIFS(Events!$X$6:$X$4467,Events!$F$6:$F$4467,$A5),"") -> 0.0052043494 | I5: =IFERROR(AVERAGEIFS(Events!$AD$6:$AD$4467,Events!$F$6:$F$4467,$A5),"") -> 0.036030915 | J5: =IFERROR(COUNTIFS(Events!$F$6:$F$4467,$A5,Events!$AV$6:$AV$4467,">0")/COUNTIFS(Events!$F$6:$F$4467,$A5,Events!$AV$6:$AV$4467,"<>"),"") -> 0.9352518 | K5: =IFERROR(COUNTIFS(Events!$F$6:$F$4467,$A5,Events!$BB$6:$BB$4467,">0")/COUNTIFS(Events!$F$6:$F$4467,$A5,Events!$BB$6:$BB$4467,"<>"),"") -> 0.78623188 | L5: =IFERROR(AVERAGEIFS(Events!$AZ$6:$AZ$4467,Events!$F$6:$F$4467,$A5),"") -> -0.016846436 | M5: =IFERROR(AVERAGEIFS(Events!$CK$6:$CK$4467,Events!$F$6:$F$4467,$A5),"") -> 0.066751726 | N5: =IFERROR(AVERAGEIFS(Events!$CL$6:$CL$4467,Events!$F$6:$F$4467,$A5),"") -> 0.56583902 | O5: =IFERROR(AVERAGEIFS(Events!$CJ$6:$CJ$4467,Events!$F$6:$F$4467,$A5),"") -> -0.19711359 | P5: =COUNTIFS(Events!$F$6:$F$4467,$A5,Events!$CN$6:$CN$4467,"Yes",Events!$CM$6:$CM$4467,"<>") -> 159 | Q5: =IFERROR(AVERAGEIFS(Events!$CM$6:$CM$4467,Events!$F$6:$F$4467,$A5,Events!$CN$6:$CN$4467,"Yes"),"") -> 0.039035197 | R5: =IFERROR(COUNTIFS(Events!$F$6:$F$4467,$A5,Events!$CM$6:$CM$4467,">0",Events!$CN$6:$CN$4467,"Yes")/COUNTIFS(Events!$F$6:$F$4467,$A5,Events!$CM$6:$CM$4467,"<>",Events!$CN$6:$CN$4467,"Yes"),"") -> 0.45283019
A6: Pharmaceuticals | B6: =COUNTIFS(Events!$F$6:$F$4467,$A6) -> 278 | C6: =COUNTIFS(Events!$F$6:$F$4467,$A6,Events!$L$6:$L$4467,"After close") -> 138 | D6: =COUNTIFS(Events!$F$6:$F$4467,$A6,Events!$L$6:$L$4467,"During market") -> 114 | E6: =COUNTIFS(Events!$F$6:$F$4467,$A6,Events!$L$6:$L$4467,"Non-trading day") -> 25 | F6: =IFERROR(AVERAGEIFS(Events!$U$6:$U$4467,Events!$F$6:$F$4467,$A6),"") -> 0.00090850504 | G6: =IFERROR(COUNTIFS(Events!$F$6:$F$4467,$A6,Events!$U$6:$U$4467,">0")/COUNTIFS(Events!$F$6:$F$4467,$A6,Events!$U$6:$U$4467,"<>"),"") -> 0.48561151 | H6: =IFERROR(AVERAGEIFS(Events!$X$6:$X$4467,Events!$F$6:$F$4467,$A6),"") -> -6.0053869e-05 | I6: =IFERROR(AVERAGEIFS(Events!$AD$6:$AD$4467,Events!$F$6:$F$4467,$A6),"") -> 0.026632639 | J6: =IFERROR(COUNTIFS(Events!$F$6:$F$4467,$A6,Events!$AV$6:$AV$4467,">0")/COUNTIFS(Events!$F$6:$F$4467,$A6,Events!$AV$6:$AV$4467,"<>"),"") -> 0.875 | K6: =IFERROR(COUNTIFS(Events!$F$6:$F$4467,$A6,Events!$BB$6:$BB$4467,">0")/COUNTIFS(Events!$F$6:$F$4467,$A6,Events!$BB$6:$BB$4467,"<>"),"") -> 0.65 | L6: =IFERROR(AVERAGEIFS(Events!$AZ$6:$AZ$4467,Events!$F$6:$F$4467,$A6),"") -> 0.00036369514 | M6: =IFERROR(AVERAGEIFS(Events!$CK$6:$CK$4467,Events!$F$6:$F$4467,$A6),"") -> 0.065561806 | N6: =IFERROR(AVERAGEIFS(Events!$CL$6:$CL$4467,Events!$F$6:$F$4467,$A6),"") -> 0.42726417 | O6: =IFERROR(AVERAGEIFS(Events!$CJ$6:$CJ$4467,Events!$F$6:$F$4467,$A6),"") -> -0.10448922 | P6: =COUNTIFS(Events!$F$6:$F$4467,$A6,Events!$CN$6:$CN$4467,"Yes",Events!$CM$6:$CM$4467,"<>") -> 135 | Q6: =IFERROR(AVERAGEIFS(Events!$CM$6:$CM$4467,Events!$F$6:$F$4467,$A6,Events!$CN$6:$CN$4467,"Yes"),"") -> -0.00061289839 | R6: =IFERROR(COUNTIFS(Events!$F$6:$F$4467,$A6,Events!$CM$6:$CM$4467,">0",Events!$CN$6:$CN$4467,"Yes")/COUNTIFS(Events!$F$6:$F$4467,$A6,Events!$CM$6:$CM$4467,"<>",Events!$CN$6:$CN$4467,"Yes"),"") -> 0.35555556
A7: Finance | B7: =COUNTIFS(Events!$F$6:$F$4467,$A7) -> 254 | C7: =COUNTIFS(Events!$F$6:$F$4467,$A7,Events!$L$6:$L$4467,"After close") -> 164 | D7: =COUNTIFS(Events!$F$6:$F$4467,$A7,Events!$L$6:$L$4467,"During market") -> 79 | E7: =COUNTIFS(Events!$F$6:$F$4467,$A7,Events!$L$6:$L$4467,"Non-trading day") -> 9 | F7: =IFERROR(AVERAGEIFS(Events!$U$6:$U$4467,Events!$F$6:$F$4467,$A7),"") -> -0.0025566199 | G7: =IFERROR(COUNTIFS(Events!$F$6:$F$4467,$A7,Events!$U$6:$U$4467,">0")/COUNTIFS(Events!$F$6:$F$4467,$A7,Events!$U$6:$U$4467,"<>"),"") -> 0.44488189 | H7: =IFERROR(AVERAGEIFS(Events!$X$6:$X$4467,Events!$F$6:$F$4467,$A7),"") -> -0.0054202227 | I7: =IFERROR(AVERAGEIFS(Events!$AD$6:$AD$4467,Events!$F$6:$F$4467,$A7),"") -> 0.031920099 | J7: =IFERROR(COUNTIFS(Events!$F$6:$F$4467,$A7,Events!$AV$6:$AV$4467,">0")/COUNTIFS(Events!$F$6:$F$4467,$A7,Events!$AV$6:$AV$4467,"<>"),"") -> 0.86585366 | K7: =IFERROR(COUNTIFS(Events!$F$6:$F$4467,$A7,Events!$BB$6:$BB$4467,">0")/COUNTIFS(Events!$F$6:$F$4467,$A7,Events!$BB$6:$BB$4467,"<>"),"") -> 0.78423237 | L7: =IFERROR(AVERAGEIFS(Events!$AZ$6:$AZ$4467,Events!$F$6:$F$4467,$A7),"") -> 0.011105987 | M7: =IFERROR(AVERAGEIFS(Events!$CK$6:$CK$4467,Events!$F$6:$F$4467,$A7),"") -> 0.074041519 | N7: =IFERROR(AVERAGEIFS(Events!$CL$6:$CL$4467,Events!$F$6:$F$4467,$A7),"") -> 0.46707607 | O7: =IFERROR(AVERAGEIFS(Events!$CJ$6:$CJ$4467,Events!$F$6:$F$4467,$A7),"") -> -0.097511957 | P7: =COUNTIFS(Events!$F$6:$F$4467,$A7,Events!$CN$6:$CN$4467,"Yes",Events!$CM$6:$CM$4467,"<>") -> 79 | Q7: =IFERROR(AVERAGEIFS(Events!$CM$6:$CM$4467,Events!$F$6:$F$4467,$A7,Events!$CN$6:$CN$4467,"Yes"),"") -> -0.0068793716 | R7: =IFERROR(COUNTIFS(Events!$F$6:$F$4467,$A7,Events!$CM$6:$CM$4467,">0",Events!$CN$6:$CN$4467,"Yes")/COUNTIFS(Events!$F$6:$F$4467,$A7,Events!$CM$6:$CM$4467,"<>",Events!$CN$6:$CN$4467,"Yes"),"") -> 0.40506329
A8: Electrical Equipment | B8: =COUNTIFS(Events!$F$6:$F$4467,$A8) -> 242 | C8: =COUNTIFS(Events!$F$6:$F$4467,$A8,Events!$L$6:$L$4467,"After close") -> 157 | D8: =COUNTIFS(Events!$F$6:$F$4467,$A8,Events!$L$6:$L$4467,"During market") -> 75 | E8: =COUNTIFS(Events!$F$6:$F$4467,$A8,Events!$L$6:$L$4467,"Non-trading day") -> 10 | F8: =IFERROR(AVERAGEIFS(Events!$U$6:$U$4467,Events!$F$6:$F$4467,$A8),"") -> 0.006105328 | G8: =IFERROR(COUNTIFS(Events!$F$6:$F$4467,$A8,Events!$U$6:$U$4467,">0")/COUNTIFS(Events!$F$6:$F$4467,$A8,Events!$U$6:$U$4467,"<>"),"") -> 0.53305785 | H8: =IFERROR(AVERAGEIFS(Events!$X$6:$X$4467,Events!$F$6:$F$4467,$A8),"") -> 0.0040622124 | I8: =IFERROR(AVERAGEIFS(Events!$AD$6:$AD$4467,Events!$F$6:$F$4467,$A8),"") -> 0.037754795 | J8: =IFERROR(COUNTIFS(Events!$F$6:$F$4467,$A8,Events!$AV$6:$AV$4467,">0")/COUNTIFS(Events!$F$6:$F$4467,$A8,Events!$AV$6:$AV$4467,"<>"),"") -> 0.88940092 | K8: =IFERROR(COUNTIFS(Events!$F$6:$F$4467,$A8,Events!$BB$6:$BB$4467,">0")/COUNTIFS(Events!$F$6:$F$4467,$A8,Events!$BB$6:$BB$4467,"<>"),"") -> 0.76023392 | L8: =IFERROR(AVERAGEIFS(Events!$AZ$6:$AZ$4467,Events!$F$6:$F$4467,$A8),"") -> 0.035037571 | M8: =IFERROR(AVERAGEIFS(Events!$CK$6:$CK$4467,Events!$F$6:$F$4467,$A8),"") -> 0.075419324 | N8: =IFERROR(AVERAGEIFS(Events!$CL$6:$CL$4467,Events!$F$6:$F$4467,$A8),"") -> 0.48971367 | O8: =IFERROR(AVERAGEIFS(Events!$CJ$6:$CJ$4467,Events!$F$6:$F$4467,$A8),"") -> -0.14088574 | P8: =COUNTIFS(Events!$F$6:$F$4467,$A8,Events!$CN$6:$CN$4467,"Yes",Events!$CM$6:$CM$4467,"<>") -> 82 | Q8: =IFERROR(AVERAGEIFS(Events!$CM$6:$CM$4467,Events!$F$6:$F$4467,$A8,Events!$CN$6:$CN$4467,"Yes"),"") -> 0.061848599 | R8: =IFERROR(COUNTIFS(Events!$F$6:$F$4467,$A8,Events!$CM$6:$CM$4467,">0",Events!$CN$6:$CN$4467,"Yes")/COUNTIFS(Events!$F$6:$F$4467,$A8,Events!$CM$6:$CM$4467,"<>",Events!$CN$6:$CN$4467,"Yes"),"") -> 0.46341463
A9: Capital Markets | B9: =COUNTIFS(Events!$F$6:$F$4467,$A9) -> 210 | C9: =COUNTIFS(Events!$F$6:$F$4467,$A9,Events!$L$6:$L$4467,"After close") -> 136 | D9: =COUNTIFS(Events!$F$6:$F$4467,$A9,Events!$L$6:$L$4467,"During market") -> 45 | E9: =COUNTIFS(Events!$F$6:$F$4467,$A9,Events!$L$6:$L$4467,"Non-trading day") -> 28 | F9: =IFERROR(AVERAGEIFS(Events!$U$6:$U$4467,Events!$F$6:$F$4467,$A9),"") -> 0.0050144602 | G9: =IFERROR(COUNTIFS(Events!$F$6:$F$4467,$A9,Events!$U$6:$U$4467,">0")/COUNTIFS(Events!$F$6:$F$4467,$A9,Events!$U$6:$U$4467,"<>"),"") -> 0.52857143 | H9: =IFERROR(AVERAGEIFS(Events!$X$6:$X$4467,Events!$F$6:$F$4467,$A9),"") -> 0.0036161339 | I9: =IFERROR(AVERAGEIFS(Events!$AD$6:$AD$4467,Events!$F$6:$F$4467,$A9),"") -> 0.032579734 | J9: =IFERROR(COUNTIFS(Events!$F$6:$F$4467,$A9,Events!$AV$6:$AV$4467,">0")/COUNTIFS(Events!$F$6:$F$4467,$A9,Events!$AV$6:$AV$4467,"<>"),"") -> 0.93048128 | K9: =IFERROR(COUNTIFS(Events!$F$6:$F$4467,$A9,Events!$BB$6:$BB$4467,">0")/COUNTIFS(Events!$F$6:$F$4467,$A9,Events!$BB$6:$BB$4467,"<>"),"") -> 0.83243243 | L9: =IFERROR(AVERAGEIFS(Events!$AZ$6:$AZ$4467,Events!$F$6:$F$4467,$A9),"") -> 0.022268676 | M9: =IFERROR(AVERAGEIFS(Events!$CK$6:$CK$4467,Events!$F$6:$F$4467,$A9),"") -> 0.074476857 | N9: =IFERROR(AVERAGEIFS(Events!$CL$6:$CL$4467,Events!$F$6:$F$4467,$A9),"") -> 0.42838692 | O9: =IFERROR(AVERAGEIFS(Events!$CJ$6:$CJ$4467,Events!$F$6:$F$4467,$A9),"") -> -0.090326304 | P9: =COUNTIFS(Events!$F$6:$F$4467,$A9,Events!$CN$6:$CN$4467,"Yes",Events!$CM$6:$CM$4467,"<>") -> 45 | Q9: =IFERROR(AVERAGEIFS(Events!$CM$6:$CM$4467,Events!$F$6:$F$4467,$A9,Events!$CN$6:$CN$4467,"Yes"),"") -> 0.17714685 | R9: =IFERROR(COUNTIFS(Events!$F$6:$F$4467,$A9,Events!$CM$6:$CM$4467,">0",Events!$CN$6:$CN$4467,"Yes")/COUNTIFS(Events!$F$6:$F$4467,$A9,Events!$CM$6:$CM$4467,"<>",Events!$CN$6:$CN$4467,"Yes"),"") -> 0.48888889
A10: Construction | B10: =COUNTIFS(Events!$F$6:$F$4467,$A10) -> 176 | C10: =COUNTIFS(Events!$F$6:$F$4467,$A10,Events!$L$6:$L$4467,"After close") -> 134 | D10: =COUNTIFS(Events!$F$6:$F$4467,$A10,Events!$L$6:$L$4467,"During market") -> 32 | E10: =COUNTIFS(Events!$F$6:$F$4467,$A10,Events!$L$6:$L$4467,"Non-trading day") -> 10 | F10: =IFERROR(AVERAGEIFS(Events!$U$6:$U$4467,Events!$F$6:$F$4467,$A10),"") -> -0.0073478961 | G10: =IFERROR(COUNTIFS(Events!$F$6:$F$4467,$A10,Events!$U$6:$U$4467,">0")/COUNTIFS(Events!$F$6:$F$4467,$A10,Events!$U$6:$U$4467,"<>"),"") -> 0.42045455 | H10: =IFERROR(AVERAGEIFS(Events!$X$6:$X$4467,Events!$F$6:$F$4467,$A10),"") -> -0.008931228 | I10: =IFERROR(AVERAGEIFS(Events!$AD$6:$AD$4467,Events!$F$6:$F$4467,$A10),"") -> 0.026135308 | J10: =IFERROR(COUNTIFS(Events!$F$6:$F$4467,$A10,Events!$AV$6:$AV$4467,">0")/COUNTIFS(Events!$F$6:$F$4467,$A10,Events!$AV$6:$AV$4467,"<>"),"") -> 0.71856287 | K10: =IFERROR(COUNTIFS(Events!$F$6:$F$4467,$A10,Events!$BB$6:$BB$4467,">0")/COUNTIFS(Events!$F$6:$F$4467,$A10,Events!$BB$6:$BB$4467,"<>"),"") -> 0.73584906 | L10: =IFERROR(AVERAGEIFS(Events!$AZ$6:$AZ$4467,Events!$F$6:$F$4467,$A10),"") -> 0.0080839402 | M10: =IFERROR(AVERAGEIFS(Events!$CK$6:$CK$4467,Events!$F$6:$F$4467,$A10),"") -> 0.077784044 | N10: =IFERROR(AVERAGEIFS(Events!$CL$6:$CL$4467,Events!$F$6:$F$4467,$A10),"") -> 0.38304596 | O10: =IFERROR(AVERAGEIFS(Events!$CJ$6:$CJ$4467,Events!$F$6:$F$4467,$A10),"") -> -0.11011185 | P10: =COUNTIFS(Events!$F$6:$F$4467,$A10,Events!$CN$6:$CN$4467,"Yes",Events!$CM$6:$CM$4467,"<>") -> 38 | Q10: =IFERROR(AVERAGEIFS(Events!$CM$6:$CM$4467,Events!$F$6:$F$4467,$A10,Events!$CN$6:$CN$4467,"Yes"),"") -> 0.087890514 | R10: =IFERROR(COUNTIFS(Events!$F$6:$F$4467,$A10,Events!$CM$6:$CM$4467,">0",Events!$CN$6:$CN$4467,"Yes")/COUNTIFS(Events!$F$6:$F$4467,$A10,Events!$CM$6:$CM$4467,"<>",Events!$CN$6:$CN$4467,"Yes"),"") -> 0.42105263
A11: Power | B11: =COUNTIFS(Events!$F$6:$F$4467,$A11) -> 176 | C11: =COUNTIFS(Events!$F$6:$F$4467,$A11,Events!$L$6:$L$4467,"After close") -> 111 | D11: =COUNTIFS(Events!$F$6:$F$4467,$A11,Events!$L$6:$L$4467,"During market") -> 47 | E11: =COUNTIFS(Events!$F$6:$F$4467,$A11,Events!$L$6:$L$4467,"Non-trading day") -> 18 | F11: =IFERROR(AVERAGEIFS(Events!$U$6:$U$4467,Events!$F$6:$F$4467,$A11),"") -> -0.008446011 | G11: =IFERROR(COUNTIFS(Events!$F$6:$F$4467,$A11,Events!$U$6:$U$4467,">0")/COUNTIFS(Events!$F$6:$F$4467,$A11,Events!$U$6:$U$4467,"<>"),"") -> 0.44318182 | H11: =IFERROR(AVERAGEIFS(Events!$X$6:$X$4467,Events!$F$6:$F$4467,$A11),"") -> -0.0092370897 | I11: =IFERROR(AVERAGEIFS(Events!$AD$6:$AD$4467,Events!$F$6:$F$4467,$A11),"") -> 0.023050454 | J11: =IFERROR(COUNTIFS(Events!$F$6:$F$4467,$A11,Events!$AV$6:$AV$4467,">0")/COUNTIFS(Events!$F$6:$F$4467,$A11,Events!$AV$6:$AV$4467,"<>"),"") -> 0.77906977 | K11: =IFERROR(COUNTIFS(Events!$F$6:$F$4467,$A11,Events!$BB$6:$BB$4467,">0")/COUNTIFS(Events!$F$6:$F$4467,$A11,Events!$BB$6:$BB$4467,"<>"),"") -> 0.65060241 | L11: =IFERROR(AVERAGEIFS(Events!$AZ$6:$AZ$4467,Events!$F$6:$F$4467,$A11),"") -> 0.0065885768 | M11: =IFERROR(AVERAGEIFS(Events!$CK$6:$CK$4467,Events!$F$6:$F$4467,$A11),"") -> 0.064375127 | N11: =IFERROR(AVERAGEIFS(Events!$CL$6:$CL$4467,Events!$F$6:$F$4467,$A11),"") -> 0.36100018 | O11: =IFERROR(AVERAGEIFS(Events!$CJ$6:$CJ$4467,Events!$F$6:$F$4467,$A11),"") -> -0.10175107 | P11: =COUNTIFS(Events!$F$6:$F$4467,$A11,Events!$CN$6:$CN$4467,"Yes",Events!$CM$6:$CM$4467,"<>") -> 45 | Q11: =IFERROR(AVERAGEIFS(Events!$CM$6:$CM$4467,Events!$F$6:$F$4467,$A11,Events!$CN$6:$CN$4467,"Yes"),"") -> -0.064932197 | R11: =IFERROR(COUNTIFS(Events!$F$6:$F$4467,$A11,Events!$CM$6:$CM$4467,">0",Events!$CN$6:$CN$4467,"Yes")/COUNTIFS(Events!$F$6:$F$4467,$A11,Events!$CM$6:$CM$4467,"<>",Events!$CN$6:$CN$4467,"Yes"),"") -> 0.31111111
A12: Insurance | B12: =COUNTIFS(Events!$F$6:$F$4467,$A12) -> 128 | C12: =COUNTIFS(Events!$F$6:$F$4467,$A12,Events!$L$6:$L$4467,"After close") -> 89 | D12: =COUNTIFS(Events!$F$6:$F$4467,$A12,Events!$L$6:$L$4467,"During market") -> 31 | E12: =COUNTIFS(Events!$F$6:$F$4467,$A12,Events!$L$6:$L$4467,"Non-trading day") -> 8 | F12: =IFERROR(AVERAGEIFS(Events!$U$6:$U$4467,Events!$F$6:$F$4467,$A12),"") -> 0.0056480383 | G12: =IFERROR(COUNTIFS(Events!$F$6:$F$4467,$A12,Events!$U$6:$U$4467,">0")/COUNTIFS(Events!$F$6:$F$4467,$A12,Events!$U$6:$U$4467,"<>"),"") -> 0.53125 | H12: =IFERROR(AVERAGEIFS(Events!$X$6:$X$4467,Events!$F$6:$F$4467,$A12),"") -> 0.0051971859 | I12: =IFERROR(AVERAGEIFS(Events!$AD$6:$AD$4467,Events!$F$6:$F$4467,$A12),"") -> 0.027146426 | J12: =IFERROR(COUNTIFS(Events!$F$6:$F$4467,$A12,Events!$AV$6:$AV$4467,">0")/COUNTIFS(Events!$F$6:$F$4467,$A12,Events!$AV$6:$AV$4467,"<>"),"") -> 0.66666667 | K12: =IFERROR(COUNTIFS(Events!$F$6:$F$4467,$A12,Events!$BB$6:$BB$4467,">0")/COUNTIFS(Events!$F$6:$F$4467,$A12,Events!$BB$6:$BB$4467,"<>"),"") -> 0.25 | L12: =IFERROR(AVERAGEIFS(Events!$AZ$6:$AZ$4467,Events!$F$6:$F$4467,$A12),"") | M12: =IFERROR(AVERAGEIFS(Events!$CK$6:$CK$4467,Events!$F$6:$F$4467,$A12),"") -> 0.054830466 | N12: =IFERROR(AVERAGEIFS(Events!$CL$6:$CL$4467,Events!$F$6:$F$4467,$A12),"") -> 0.52077536 | O12: =IFERROR(AVERAGEIFS(Events!$CJ$6:$CJ$4467,Events!$F$6:$F$4467,$A12),"") -> -0.13086352 | P12: =COUNTIFS(Events!$F$6:$F$4467,$A12,Events!$CN$6:$CN$4467,"Yes",Events!$CM$6:$CM$4467,"<>") -> 81 | Q12: =IFERROR(AVERAGEIFS(Events!$CM$6:$CM$4467,Events!$F$6:$F$4467,$A12,Events!$CN$6:$CN$4467,"Yes"),"") -> -0.0085236312 | R12: =IFERROR(COUNTIFS(Events!$F$6:$F$4467,$A12,Events!$CM$6:$CM$4467,">0",Events!$CN$6:$CN$4467,"Yes")/COUNTIFS(Events!$F$6:$F$4467,$A12,Events!$CM$6:$CM$4467,"<>",Events!$CN$6:$CN$4467,"Yes"),"") -> 0.41975309
A13: Automobiles - 4 Wheelers | B13: =COUNTIFS(Events!$F$6:$F$4467,$A13) -> 128 | C13: =COUNTIFS(Events!$F$6:$F$4467,$A13,Events!$L$6:$L$4467,"After close") -> 63 | D13: =COUNTIFS(Events!$F$6:$F$4467,$A13,Events!$L$6:$L$4467,"During market") -> 62 | E13: =COUNTIFS(Events!$F$6:$F$4467,$A13,Events!$L$6:$L$4467,"Non-trading day") -> 3 | F13: =IFERROR(AVERAGEIFS(Events!$U$6:$U$4467,Events!$F$6:$F$4467,$A13),"") -> 0.017023852 | G13: =IFERROR(COUNTIFS(Events!$F$6:$F$4467,$A13,Events!$U$6:$U$4467,">0")/COUNTIFS(Events!$F$6:$F$4467,$A13,Events!$U$6:$U$4467,"<>"),"") -> 0.625 | H13: =IFERROR(AVERAGEIFS(Events!$X$6:$X$4467,Events!$F$6:$F$4467,$A13),"") -> 0.013774852 | I13: =IFERROR(AVERAGEIFS(Events!$AD$6:$AD$4467,Events!$F$6:$F$4467,$A13),"") -> 0.027633885 | J13: =IFERROR(COUNTIFS(Events!$F$6:$F$4467,$A13,Events!$AV$6:$AV$4467,">0")/COUNTIFS(Events!$F$6:$F$4467,$A13,Events!$AV$6:$AV$4467,"<>"),"") -> 0.88695652 | K13: =IFERROR(COUNTIFS(Events!$F$6:$F$4467,$A13,Events!$BB$6:$BB$4467,">0")/COUNTIFS(Events!$F$6:$F$4467,$A13,Events!$BB$6:$BB$4467,"<>"),"") -> 0.74489796 | L13: =IFERROR(AVERAGEIFS(Events!$AZ$6:$AZ$4467,Events!$F$6:$F$4467,$A13),"") -> 0.0088972097 | M13: =IFERROR(AVERAGEIFS(Events!$CK$6:$CK$4467,Events!$F$6:$F$4467,$A13),"") -> 0.066550007 | N13: =IFERROR(AVERAGEIFS(Events!$CL$6:$CL$4467,Events!$F$6:$F$4467,$A13),"") -> 0.40131556 | O13: =IFERROR(AVERAGEIFS(Events!$CJ$6:$CJ$4467,Events!$F$6:$F$4467,$A13),"") -> -0.11234639 | P13: =COUNTIFS(Events!$F$6:$F$4467,$A13,Events!$CN$6:$CN$4467,"Yes",Events!$CM$6:$CM$4467,"<>") -> 52 | Q13: =IFERROR(AVERAGEIFS(Events!$CM$6:$CM$4467,Events!$F$6:$F$4467,$A13,Events!$CN$6:$CN$4467,"Yes"),"") -> -0.025384798 | R13: =IFERROR(COUNTIFS(Events!$F$6:$F$4467,$A13,Events!$CM$6:$CM$4467,">0",Events!$CN$6:$CN$4467,"Yes")/COUNTIFS(Events!$F$6:$F$4467,$A13,Events!$CM$6:$CM$4467,"<>",Events!$CN$6:$CN$4467,"Yes"),"") -> 0.38461538
A14: Food And Food Processing | B14: =COUNTIFS(Events!$F$6:$F$4467,$A14) -> 122 | C14: =COUNTIFS(Events!$F$6:$F$4467,$A14,Events!$L$6:$L$4467,"After close") -> 67 | D14: =COUNTIFS(Events!$F$6:$F$4467,$A14,Events!$L$6:$L$4467,"During market") -> 47 | E14: =COUNTIFS(Events!$F$6:$F$4467,$A14,Events!$L$6:$L$4467,"Non-trading day") -> 8 | F14: =IFERROR(AVERAGEIFS(Events!$U$6:$U$4467,Events!$F$6:$F$4467,$A14),"") -> 0.0056010326 | G14: =IFERROR(COUNTIFS(Events!$F$6:$F$4467,$A14,Events!$U$6:$U$4467,">0")/COUNTIFS(Events!$F$6:$F$4467,$A14,Events!$U$6:$U$4467,"<>"),"") -> 0.52459016 | H14: =IFERROR(AVERAGEIFS(Events!$X$6:$X$4467,Events!$F$6:$F$4467,$A14),"") -> 0.0044538192 | I14: =IFERROR(AVERAGEIFS(Events!$AD$6:$AD$4467,Events!$F$6:$F$4467,$A14),"") -> 0.03162427 | J14: =IFERROR(COUNTIFS(Events!$F$6:$F$4467,$A14,Events!$AV$6:$AV$4467,">0")/COUNTIFS(Events!$F$6:$F$4467,$A14,Events!$AV$6:$AV$4467,"<>"),"") -> 0.95762712 | K14: =IFERROR(COUNTIFS(Events!$F$6:$F$4467,$A14,Events!$BB$6:$BB$4467,">0")/COUNTIFS(Events!$F$6:$F$4467,$A14,Events!$BB$6:$BB$4467,"<>"),"") -> 0.72807018 | L14: =IFERROR(AVERAGEIFS(Events!$AZ$6:$AZ$4467,Events!$F$6:$F$4467,$A14),"") -> 0.0019971448 | M14: =IFERROR(AVERAGEIFS(Events!$CK$6:$CK$4467,Events!$F$6:$F$4467,$A14),"") -> 0.061219948 | N14: =IFERROR(AVERAGEIFS(Events!$CL$6:$CL$4467,Events!$F$6:$F$4467,$A14),"") -> 0.57343076 | O14: =IFERROR(AVERAGEIFS(Events!$CJ$6:$CJ$4467,Events!$F$6:$F$4467,$A14),"") -> -0.1308149 | P14: =COUNTIFS(Events!$F$6:$F$4467,$A14,Events!$CN$6:$CN$4467,"Yes",Events!$CM$6:$CM$4467,"<>") -> 41 | Q14: =IFERROR(AVERAGEIFS(Events!$CM$6:$CM$4467,Events!$F$6:$F$4467,$A14,Events!$CN$6:$CN$4467,"Yes"),"") -> -0.012842883 | R14: =IFERROR(COUNTIFS(Events!$F$6:$F$4467,$A14,Events!$CM$6:$CM$4467,">0",Events!$CN$6:$CN$4467,"Yes")/COUNTIFS(Events!$F$6:$F$4467,$A14,Events!$CM$6:$CM$4467,"<>",Events!$CN$6:$CN$4467,"Yes"),"") -> 0.34146341
A15: Miscellaneous | B15: =COUNTIFS(Events!$F$6:$F$4467,$A15) -> 110 | C15: =COUNTIFS(Events!$F$6:$F$4467,$A15,Events!$L$6:$L$4467,"After close") -> 76 | D15: =COUNTIFS(Events!$F$6:$F$4467,$A15,Events!$L$6:$L$4467,"During market") -> 30 | E15: =COUNTIFS(Events!$F$6:$F$4467,$A15,Events!$L$6:$L$4467,"Non-trading day") -> 4 | F15: =IFERROR(AVERAGEIFS(Events!$U$6:$U$4467,Events!$F$6:$F$4467,$A15),"") -> 0.012454502 | G15: =IFERROR(COUNTIFS(Events!$F$6:$F$4467,$A15,Events!$U$6:$U$4467,">0")/COUNTIFS(Events!$F$6:$F$4467,$A15,Events!$U$6:$U$4467,"<>"),"") -> 0.55454545 | H15: =IFERROR(AVERAGEIFS(Events!$X$6:$X$4467,Events!$F$6:$F$4467,$A15),"") -> 0.010943248 | I15: =IFERROR(AVERAGEIFS(Events!$AD$6:$AD$4467,Events!$F$6:$F$4467,$A15),"") -> 0.032079051 | J15: =IFERROR(COUNTIFS(Events!$F$6:$F$4467,$A15,Events!$AV$6:$AV$4467,">0")/COUNTIFS(Events!$F$6:$F$4467,$A15,Events!$AV$6:$AV$4467,"<>"),"") -> 0.97222222 | K15: =IFERROR(COUNTIFS(Events!$F$6:$F$4467,$A15,Events!$BB$6:$BB$4467,">0")/COUNTIFS(Events!$F$6:$F$4467,$A15,Events!$BB$6:$BB$4467,"<>"),"") -> 0.84 | L15: =IFERROR(AVERAGEIFS(Events!$AZ$6:$AZ$4467,Events!$F$6:$F$4467,$A15),"") -> 0.018598858 | M15: =IFERROR(AVERAGEIFS(Events!$CK$6:$CK$4467,Events!$F$6:$F$4467,$A15),"") -> 0.071302869 | N15: =IFERROR(AVERAGEIFS(Events!$CL$6:$CL$4467,Events!$F$6:$F$4467,$A15),"") -> 0.52670961 | O15: =IFERROR(AVERAGEIFS(Events!$CJ$6:$CJ$4467,Events!$F$6:$F$4467,$A15),"") -> -0.13632786 | P15: =COUNTIFS(Events!$F$6:$F$4467,$A15,Events!$CN$6:$CN$4467,"Yes",Events!$CM$6:$CM$4467,"<>") -> 39 | Q15: =IFERROR(AVERAGEIFS(Events!$CM$6:$CM$4467,Events!$F$6:$F$4467,$A15,Events!$CN$6:$CN$4467,"Yes"),"") -> -0.00028071286 | R15: =IFERROR(COUNTIFS(Events!$F$6:$F$4467,$A15,Events!$CM$6:$CM$4467,">0",Events!$CN$6:$CN$4467,"Yes")/COUNTIFS(Events!$F$6:$F$4467,$A15,Events!$CM$6:$CM$4467,"<>",Events!$CN$6:$CN$4467,"Yes"),"") -> 0.35897436
... A52: Electronics - Industrial | B52: =COUNTIFS(Events!$F$6:$F$4467,$A52) -> 22 | C52: =COUNTIFS(Events!$F$6:$F$4467,$A52,Events!$L$6:$L$4467,"After close") -> 8 | D52: =COUNTIFS(Events!$F$6:$F$4467,$A52,Events!$L$6:$L$4467,"During market") -> 9 | E52: =COUNTIFS(Events!$F$6:$F$4467,$A52,Events!$L$6:$L$4467,"Non-trading day") -> 5 | F52: =IFERROR(AVERAGEIFS(Events!$U$6:$U$4467,Events!$F$6:$F$4467,$A52),"") -> 0.028458548 | G52: =IFERROR(COUNTIFS(Events!$F$6:$F$4467,$A52,Events!$U$6:$U$4467,">0")/COUNTIFS(Events!$F$6:$F$4467,$A52,Events!$U$6:$U$4467,"<>"),"") -> 0.68181818 | H52: =IFERROR(AVERAGEIFS(Events!$X$6:$X$4467,Events!$F$6:$F$4467,$A52),"") -> 0.024893692 | I52: =IFERROR(AVERAGEIFS(Events!$AD$6:$AD$4467,Events!$F$6:$F$4467,$A52),"") -> 0.031555097 | J52: =IFERROR(COUNTIFS(Events!$F$6:$F$4467,$A52,Events!$AV$6:$AV$4467,">0")/COUNTIFS(Events!$F$6:$F$4467,$A52,Events!$AV$6:$AV$4467,"<>"),"") -> 0.90909091 | K52: =IFERROR(COUNTIFS(Events!$F$6:$F$4467,$A52,Events!$BB$6:$BB$4467,">0")/COUNTIFS(Events!$F$6:$F$4467,$A52,Events!$BB$6:$BB$4467,"<>"),"") -> 0.86363636 | L52: =IFERROR(AVERAGEIFS(Events!$AZ$6:$AZ$4467,Events!$F$6:$F$4467,$A52),"") -> 0.018008865 | M52: =IFERROR(AVERAGEIFS(Events!$CK$6:$CK$4467,Events!$F$6:$F$4467,$A52),"") -> 0.076136924 | N52: =IFERROR(AVERAGEIFS(Events!$CL$6:$CL$4467,Events!$F$6:$F$4467,$A52),"") -> 0.38292172 | O52: =IFERROR(AVERAGEIFS(Events!$CJ$6:$CJ$4467,Events!$F$6:$F$4467,$A52),"") -> -0.058656332 | P52: =COUNTIFS(Events!$F$6:$F$4467,$A52,Events!$CN$6:$CN$4467,"Yes",Events!$CM$6:$CM$4467,"<>") -> 7 | Q52: =IFERROR(AVERAGEIFS(Events!$CM$6:$CM$4467,Events!$F$6:$F$4467,$A52,Events!$CN$6:$CN$4467,"Yes"),"") -> 0.21042063 | R52: =IFERROR(COUNTIFS(Events!$F$6:$F$4467,$A52,Events!$CM$6:$CM$4467,">0",Events!$CN$6:$CN$4467,"Yes")/COUNTIFS(Events!$F$6:$F$4467,$A52,Events!$CM$6:$CM$4467,"<>",Events!$CN$6:$CN$4467,"Yes"),"") -> 0.42857143
A53: All industries | B53: =COUNTIFS(Events!$F$6:$F$4467,"<>") -> 4462 | C53: =COUNTIFS(Events!$F$6:$F$4467,"<>",Events!$L$6:$L$4467,"After close") -> 2623 | D53: =COUNTIFS(Events!$F$6:$F$4467,"<>",Events!$L$6:$L$4467,"During market") -> 1419 | E53: =COUNTIFS(Events!$F$6:$F$4467,"<>",Events!$L$6:$L$4467,"Non-trading day") -> 393 | F53: =IFERROR(AVERAGEIFS(Events!$U$6:$U$4467,Events!$F$6:$F$4467,"<>"),"") -> 0.0028108158 | G53: =IFERROR(COUNTIFS(Events!$F$6:$F$4467,"<>",Events!$U$6:$U$4467,">0")/COUNTIFS(Events!$F$6:$F$4467,"<>",Events!$U$6:$U$4467,"<>"),"") -> 0.50381166 | H53: =IFERROR(AVERAGEIFS(Events!$X$6:$X$4467,Events!$F$6:$F$4467,"<>"),"") -> 0.0016344564 | I53: =IFERROR(AVERAGEIFS(Events!$AD$6:$AD$4467,Events!$F$6:$F$4467,"<>"),"") -> 0.030647861 | J53: =IFERROR(COUNTIFS(Events!$F$6:$F$4467,"<>",Events!$AV$6:$AV$4467,">0")/COUNTIFS(Events!$F$6:$F$4467,"<>",Events!$AV$6:$AV$4467,"<>"),"") -> 0.86166299 | K53: =IFERROR(COUNTIFS(Events!$F$6:$F$4467,"<>",Events!$BB$6:$BB$4467,">0")/COUNTIFS(Events!$F$6:$F$4467,"<>",Events!$BB$6:$BB$4467,"<>"),"") -> 0.72437418 | L53: =IFERROR(AVERAGEIFS(Events!$AZ$6:$AZ$4467,Events!$F$6:$F$4467,"<>"),"") -> 0.014142264 | M53: =IFERROR(AVERAGEIFS(Events!$CK$6:$CK$4467,Events!$F$6:$F$4467,"<>"),"") -> 0.067968055 | N53: =IFERROR(AVERAGEIFS(Events!$CL$6:$CL$4467,Events!$F$6:$F$4467,"<>"),"") -> 0.4615053 | O53: =IFERROR(AVERAGEIFS(Events!$CJ$6:$CJ$4467,Events!$F$6:$F$4467,"<>"),"") -> -0.11842411 | P53: =COUNTIFS(Events!$F$6:$F$4467,"<>",Events!$CN$6:$CN$4467,"Yes",Events!$CM$6:$CM$4467,"<>") -> 1685 | Q53: =IFERROR(AVERAGEIFS(Events!$CM$6:$CM$4467,Events!$F$6:$F$4467,"<>",Events!$CN$6:$CN$4467,"Yes"),"") -> 0.018684818 | R53: =IFERROR(COUNTIFS(Events!$F$6:$F$4467,"<>",Events!$CM$6:$CM$4467,">0",Events!$CN$6:$CN$4467,"Yes")/COUNTIFS(Events!$F$6:$F$4467,"<>",Events!$CM$6:$CM$4467,"<>",Events!$CN$6:$CN$4467,"Yes"),"") -> 0.39762611

Sheet By stock
A1: By stock
A2: Formulas over the Events sheet, all 22 quarters.
A3: Symbol | B3: Company | C3: Industry | D3: Results events | E3: After close | F3: Avg three-day sum % | G3: % three-day positive | H3: Avg excess vs Nifty % | I3: Avg size of reaction move % | J3: % sales up YoY | K3: % profit up YoY | L3: Avg EBITDA margin chg YoY (pts) | M3: Avg expected move % (options) | N3: Avg actual / expected move (x) | O3: Avg IV drop % | P3: Run-up trades (rule pass) | Q3: Run-up avg return % (rule pass) | R3: Run-up win rate (rule pass)
A4: 360ONE | B4: =INDEX(Events!$E$6:$E$4467,MATCH($A4,Events!$D$6:$D$4467,0)) -> 360 ONE WAM LIMITED | C4: =INDEX(Events!$F$6:$F$4467,MATCH($A4,Events!$D$6:$D$4467,0))&"" -> Capital Markets | D4: =COUNTIFS(Events!$D$6:$D$4467,$A4) -> 22 | E4: =COUNTIFS(Events!$D$6:$D$4467,$A4,Events!$L$6:$L$4467,"After close") -> 18 | F4: =IFERROR(AVERAGEIFS(Events!$U$6:$U$4467,Events!$D$6:$D$4467,$A4),"") -> 0.0090797633 | G4: =IFERROR(COUNTIFS(Events!$D$6:$D$4467,$A4,Events!$U$6:$U$4467,">0")/COUNTIFS(Events!$D$6:$D$4467,$A4,Events!$U$6:$U$4467,"<>"),"") -> 0.68181818 | H4: =IFERROR(AVERAGEIFS(Events!$X$6:$X$4467,Events!$D$6:$D$4467,$A4),"") -> 0.0087506089 | I4: =IFERROR(AVERAGEIFS(Events!$AD$6:$AD$4467,Events!$D$6:$D$4467,$A4),"") -> 0.035290339 | J4: =IFERROR(COUNTIFS(Events!$D$6:$D$4467,$A4,Events!$AV$6:$AV$4467,">0")/COUNTIFS(Events!$D$6:$D$4467,$A4,Events!$AV$6:$AV$4467,"<>"),"") -> 0.9 | K4: =IFERROR(COUNTIFS(Events!$D$6:$D$4467,$A4,Events!$BB$6:$BB$4467,">0")/COUNTIFS(Events!$D$6:$D$4467,$A4,Events!$BB$6:$BB$4467,"<>"),"") -> 0.94736842 | L4: =IFERROR(AVERAGEIFS(Events!$AZ$6:$AZ$4467,Events!$D$6:$D$4467,$A4),"") -> 0.016615718 | M4: =IFERROR(AVERAGEIFS(Events!$CK$6:$CK$4467,Events!$D$6:$D$4467,$A4),"") -> 0.058463763 | N4: =IFERROR(AVERAGEIFS(Events!$CL$6:$CL$4467,Events!$D$6:$D$4467,$A4),"") -> 0.44387782 | O4: =IFERROR(AVERAGEIFS(Events!$CJ$6:$CJ$4467,Events!$D$6:$D$4467,$A4),"") -> -0.15649243 | P4: =COUNTIFS(Events!$D$6:$D$4467,$A4,Events!$CN$6:$CN$4467,"Yes",Events!$CM$6:$CM$4467,"<>") -> 5 | Q4: =IFERROR(AVERAGEIFS(Events!$CM$6:$CM$4467,Events!$D$6:$D$4467,$A4,Events!$CN$6:$CN$4467,"Yes"),"") -> 0.069709918 | R4: =IFERROR(COUNTIFS(Events!$D$6:$D$4467,$A4,Events!$CM$6:$CM$4467,">0",Events!$CN$6:$CN$4467,"Yes")/COUNTIFS(Events!$D$6:$D$4467,$A4,Events!$CM$6:$CM$4467,"<>",Events!$CN$6:$CN$4467,"Yes"),"") -> 0.4
A5: ABB | B5: =INDEX(Events!$E$6:$E$4467,MATCH($A5,Events!$D$6:$D$4467,0)) -> ABB India Limited | C5: =INDEX(Events!$F$6:$F$4467,MATCH($A5,Events!$D$6:$D$4467,0))&"" -> Electrical Equipment | D5: =COUNTIFS(Events!$D$6:$D$4467,$A5) -> 22 | E5: =COUNTIFS(Events!$D$6:$D$4467,$A5,Events!$L$6:$L$4467,"After close") -> 18 | F5: =IFERROR(AVERAGEIFS(Events!$U$6:$U$4467,Events!$D$6:$D$4467,$A5),"") -> 0.0055872373 | G5: =IFERROR(COUNTIFS(Events!$D$6:$D$4467,$A5,Events!$U$6:$U$4467,">0")/COUNTIFS(Events!$D$6:$D$4467,$A5,Events!$U$6:$U$4467,"<>"),"") -> 0.54545455 | H5: =IFERROR(AVERAGEIFS(Events!$X$6:$X$4467,Events!$D$6:$D$4467,$A5),"") -> 0.0035192286 | I5: =IFERROR(AVERAGEIFS(Events!$AD$6:$AD$4467,Events!$D$6:$D$4467,$A5),"") -> 0.040461622 | J5: =IFERROR(COUNTIFS(Events!$D$6:$D$4467,$A5,Events!$AV$6:$AV$4467,">0")/COUNTIFS(Events!$D$6:$D$4467,$A5,Events!$AV$6:$AV$4467,"<>"),"") -> 1 | K5: =IFERROR(COUNTIFS(Events!$D$6:$D$4467,$A5,Events!$BB$6:$BB$4467,">0")/COUNTIFS(Events!$D$6:$D$4467,$A5,Events!$BB$6:$BB$4467,"<>"),"") -> 0.81818182 | L5: =IFERROR(AVERAGEIFS(Events!$AZ$6:$AZ$4467,Events!$D$6:$D$4467,$A5),"") -> 0.015923713 | M5: =IFERROR(AVERAGEIFS(Events!$CK$6:$CK$4467,Events!$D$6:$D$4467,$A5),"") -> 0.072857118 | N5: =IFERROR(AVERAGEIFS(Events!$CL$6:$CL$4467,Events!$D$6:$D$4467,$A5),"") -> 0.61289742 | O5: =IFERROR(AVERAGEIFS(Events!$CJ$6:$CJ$4467,Events!$D$6:$D$4467,$A5),"") -> -0.13833043 | P5: =COUNTIFS(Events!$D$6:$D$4467,$A5,Events!$CN$6:$CN$4467,"Yes",Events!$CM$6:$CM$4467,"<>") -> 10 | Q5: =IFERROR(AVERAGEIFS(Events!$CM$6:$CM$4467,Events!$D$6:$D$4467,$A5,Events!$CN$6:$CN$4467,"Yes"),"") -> 0.1083875 | R5: =IFERROR(COUNTIFS(Events!$D$6:$D$4467,$A5,Events!$CM$6:$CM$4467,">0",Events!$CN$6:$CN$4467,"Yes")/COUNTIFS(Events!$D$6:$D$4467,$A5,Events!$CM$6:$CM$4467,"<>",Events!$CN$6:$CN$4467,"Yes"),"") -> 0.6
A6: ABCAPITAL | B6: =INDEX(Events!$E$6:$E$4467,MATCH($A6,Events!$D$6:$D$4467,0)) -> Aditya Birla Capital Limited | C6: =INDEX(Events!$F$6:$F$4467,MATCH($A6,Events!$D$6:$D$4467,0))&"" -> Finance | D6: =COUNTIFS(Events!$D$6:$D$4467,$A6) -> 22 | E6: =COUNTIFS(Events!$D$6:$D$4467,$A6,Events!$L$6:$L$4467,"After close") -> 7 | F6: =IFERROR(AVERAGEIFS(Events!$U$6:$U$4467,Events!$D$6:$D$4467,$A6),"") -> 0.026211941 | G6: =IFERROR(COUNTIFS(Events!$D$6:$D$4467,$A6,Events!$U$6:$U$4467,">0")/COUNTIFS(Events!$D$6:$D$4467,$A6,Events!$U$6:$U$4467,"<>"),"") -> 0.72727273 | H6: =IFERROR(AVERAGEIFS(Events!$X$6:$X$4467,Events!$D$6:$D$4467,$A6),"") -> 0.021366968 | I6: =IFERROR(AVERAGEIFS(Events!$AD$6:$AD$4467,Events!$D$6:$D$4467,$A6),"") -> 0.027840454 | J6: =IFERROR(COUNTIFS(Events!$D$6:$D$4467,$A6,Events!$AV$6:$AV$4467,">0")/COUNTIFS(Events!$D$6:$D$4467,$A6,Events!$AV$6:$AV$4467,"<>"),"") -> 1 | K6: =IFERROR(COUNTIFS(Events!$D$6:$D$4467,$A6,Events!$BB$6:$BB$4467,">0")/COUNTIFS(Events!$D$6:$D$4467,$A6,Events!$BB$6:$BB$4467,"<>"),"") -> 0.8 | L6: =IFERROR(AVERAGEIFS(Events!$AZ$6:$AZ$4467,Events!$D$6:$D$4467,$A6),"") | M6: =IFERROR(AVERAGEIFS(Events!$CK$6:$CK$4467,Events!$D$6:$D$4467,$A6),"") -> 0.076935985 | N6: =IFERROR(AVERAGEIFS(Events!$CL$6:$CL$4467,Events!$D$6:$D$4467,$A6),"") -> 0.34060094 | O6: =IFERROR(AVERAGEIFS(Events!$CJ$6:$CJ$4467,Events!$D$6:$D$4467,$A6),"") -> -0.068224079 | P6: =COUNTIFS(Events!$D$6:$D$4467,$A6,Events!$CN$6:$CN$4467,"Yes",Events!$CM$6:$CM$4467,"<>") -> 5 | Q6: =IFERROR(AVERAGEIFS(Events!$CM$6:$CM$4467,Events!$D$6:$D$4467,$A6,Events!$CN$6:$CN$4467,"Yes"),"") -> 0.099351373 | R6: =IFERROR(COUNTIFS(Events!$D$6:$D$4467,$A6,Events!$CM$6:$CM$4467,">0",Events!$CN$6:$CN$4467,"Yes")/COUNTIFS(Events!$D$6:$D$4467,$A6,Events!$CM$6:$CM$4467,"<>",Events!$CN$6:$CN$4467,"Yes"),"") -> 0.6
