Workbook

Sheet Summary
A1: Summary by quarter
A2: Every number is a formula over the Events sheet. 'Rule pass' = front expiry within 14 sessions of the last close before results (the playbook's run-up rule).
A3: Quarter | B3: Period | C3: Results events | D3: After close | E3: During market | F3: Weekend / holiday | G3: Avg three-day sum % | H3: % three-day positive | I3: Avg excess vs Nifty % | J3: Avg size of reaction move % | K3: % sales up YoY | L3: % profit up YoY | M3: Avg EBITDA margin chg YoY (pts) | N3: Avg expected move % (options) | O3: Avg actual / expected move (x) | P3: Avg IV drop % | Q3: Run-up trades (rule pass) | R3: Run-up avg return % (rule pass) | S3: Run-up win rate (rule pass)
A4: Q3 FY23 | B4: Oct-Dec 2022 | C4: =COUNTIFS(Events!$A$6:$A$3108,$A4) -> 199 | D4: =COUNTIFS(Events!$A$6:$A$3108,$A4,Events!$K$6:$K$3108,"After close") -> 124 | E4: =COUNTIFS(Events!$A$6:$A$3108,$A4,Events!$K$6:$K$3108,"During market") -> 63 | F4: =COUNTIFS(Events!$A$6:$A$3108,$A4,Events!$K$6:$K$3108,"Non-trading day") -> 11 | G4: =IFERROR(AVERAGEIFS(Events!$T$6:$T$3108,Events!$A$6:$A$3108,$A4),"") -> -0.00078411029 | H4: =IFERROR(COUNTIFS(Events!$A$6:$A$3108,$A4,Events!$T$6:$T$3108,">0")/COUNTIFS(Events!$A$6:$A$3108,$A4,Events!$T$6:$T$3108,"<>"),"") -> 0.46031746 | I4: =IFERROR(AVERAGEIFS(Events!$W$6:$W$3108,Events!$A$6:$A$3108,$A4),"") -> -0.00035966502 | J4: =IFERROR(AVERAGEIFS(Events!$AC$6:$AC$3108,Events!$A$6:$A$3108,$A4),"") -> 0.027299043 | K4: =IFERROR(COUNTIFS(Events!$A$6:$A$3108,$A4,Events!$AU$6:$AU$3108,">0")/COUNTIFS(Events!$A$6:$A$3108,$A4,Events!$AU$6:$AU$3108,"<>"),"") -> 0.85795455 | L4: =IFERROR(COUNTIFS(Events!$A$6:$A$3108,$A4,Events!$BA$6:$BA$3108,">0")/COUNTIFS(Events!$A$6:$A$3108,$A4,Events!$BA$6:$BA$3108,"<>"),"") -> 0.64189189 | M4: =IFERROR(AVERAGEIFS(Events!$AY$6:$AY$3108,Events!$A$6:$A$3108,$A4),"") -> -0.062371061 | N4: =IFERROR(AVERAGEIFS(Events!$CJ$6:$CJ$3108,Events!$A$6:$A$3108,$A4),"") -> 0.063015114 | O4: =IFERROR(AVERAGEIFS(Events!$CK$6:$CK$3108,Events!$A$6:$A$3108,$A4),"") -> 0.45236005 | P4: =IFERROR(AVERAGEIFS(Events!$CI$6:$CI$3108,Events!$A$6:$A$3108,$A4),"") -> -0.098235077 | Q4: =COUNTIFS(Events!$A$6:$A$3108,$A4,Events!$CM$6:$CM$3108,"Yes",Events!$CL$6:$CL$3108,"<>") -> 65 | R4: =IFERROR(AVERAGEIFS(Events!$CL$6:$CL$3108,Events!$A$6:$A$3108,$A4,Events!$CM$6:$CM$3108,"Yes"),"") -> -0.080738606 | S4: =IFERROR(COUNTIFS(Events!$A$6:$A$3108,$A4,Events!$CL$6:$CL$3108,">0",Events!$CM$6:$CM$3108,"Yes")/COUNTIFS(Events!$A$6:$A$3108,$A4,Events!$CL$6:$CL$3108,"<>",Events!$CM$6:$CM$3108,"Yes"),"") -> 0.29230769
A5: Q4 FY23 | B5: Jan-Mar 2023 | C5: =COUNTIFS(Events!$A$6:$A$3108,$A5) -> 200 | D5: =COUNTIFS(Events!$A$6:$A$3108,$A5,Events!$K$6:$K$3108,"After close") -> 120 | E5: =COUNTIFS(Events!$A$6:$A$3108,$A5,Events!$K$6:$K$3108,"During market") -> 57 | F5: =COUNTIFS(Events!$A$6:$A$3108,$A5,Events!$K$6:$K$3108,"Non-trading day") -> 21 | G5: =IFERROR(AVERAGEIFS(Events!$T$6:$T$3108,Events!$A$6:$A$3108,$A5),"") -> 0.0073437312 | H5: =IFERROR(COUNTIFS(Events!$A$6:$A$3108,$A5,Events!$T$6:$T$3108,">0")/COUNTIFS(Events!$A$6:$A$3108,$A5,Events!$T$6:$T$3108,"<>"),"") -> 0.54450262 | I5: =IFERROR(AVERAGEIFS(Events!$W$6:$W$3108,Events!$A$6:$A$3108,$A5),"") -> 0.0014996983 | J5: =IFERROR(AVERAGEIFS(Events!$AC$6:$AC$3108,Events!$A$6:$A$3108,$A5),"") -> 0.028292562 | K5: =IFERROR(COUNTIFS(Events!$A$6:$A$3108,$A5,Events!$AU$6:$AU$3108,">0")/COUNTIFS(Events!$A$6:$A$3108,$A5,Events!$AU$6:$AU$3108,"<>"),"") -> 0.86170213 | L5: =IFERROR(COUNTIFS(Events!$A$6:$A$3108,$A5,Events!$BA$6:$BA$3108,">0")/COUNTIFS(Events!$A$6:$A$3108,$A5,Events!$BA$6:$BA$3108,"<>"),"") -> 0.63975155 | M5: =IFERROR(AVERAGEIFS(Events!$AY$6:$AY$3108,Events!$A$6:$A$3108,$A5),"") -> 0.010637263 | N5: =IFERROR(AVERAGEIFS(Events!$CJ$6:$CJ$3108,Events!$A$6:$A$3108,$A5),"") -> 0.057414456 | O5: =IFERROR(AVERAGEIFS(Events!$CK$6:$CK$3108,Events!$A$6:$A$3108,$A5),"") -> 0.47796664 | P5: =IFERROR(AVERAGEIFS(Events!$CI$6:$CI$3108,Events!$A$6:$A$3108,$A5),"") -> -0.16351047 | Q5: =COUNTIFS(Events!$A$6:$A$3108,$A5,Events!$CM$6:$CM$3108,"Yes",Events!$CL$6:$CL$3108,"<>") -> 61 | R5: =IFERROR(AVERAGEIFS(Events!$CL$6:$CL$3108,Events!$A$6:$A$3108,$A5,Events!$CM$6:$CM$3108,"Yes"),"") -> 0.045490892 | S5: =IFERROR(COUNTIFS(Events!$A$6:$A$3108,$A5,Events!$CL$6:$CL$3108,">0",Events!$CM$6:$CM$3108,"Yes")/COUNTIFS(Events!$A$6:$A$3108,$A5,Events!$CL$6:$CL$3108,"<>",Events!$CM$6:$CM$3108,"Yes"),"") -> 0.52459016
A6: Q1 FY24 | B6: Apr-Jun 2023 | C6: =COUNTIFS(Events!$A$6:$A$3108,$A6) -> 200 | D6: =COUNTIFS(Events!$A$6:$A$3108,$A6,Events!$K$6:$K$3108,"After close") -> 112 | E6: =COUNTIFS(Events!$A$6:$A$3108,$A6,Events!$K$6:$K$3108,"During market") -> 72 | F6: =COUNTIFS(Events!$A$6:$A$3108,$A6,Events!$K$6:$K$3108,"Non-trading day") -> 15 | G6: =IFERROR(AVERAGEIFS(Events!$T$6:$T$3108,Events!$A$6:$A$3108,$A6),"") -> -0.00067566989 | H6: =IFERROR(COUNTIFS(Events!$A$6:$A$3108,$A6,Events!$T$6:$T$3108,">0")/COUNTIFS(Events!$A$6:$A$3108,$A6,Events!$T$6:$T$3108,"<>"),"") -> 0.47894737 | I6: =IFERROR(AVERAGEIFS(Events!$W$6:$W$3108,Events!$A$6:$A$3108,$A6),"") -> 0.0019276615 | J6: =IFERROR(AVERAGEIFS(Events!$AC$6:$AC$3108,Events!$A$6:$A$3108,$A6),"") -> 0.025350293 | K6: =IFERROR(COUNTIFS(Events!$A$6:$A$3108,$A6,Events!$AU$6:$AU$3108,">0")/COUNTIFS(Events!$A$6:$A$3108,$A6,Events!$AU$6:$AU$3108,"<>"),"") -> 0.81456954 | L6: =IFERROR(COUNTIFS(Events!$A$6:$A$3108,$A6,Events!$BA$6:$BA$3108,">0")/COUNTIFS(Events!$A$6:$A$3108,$A6,Events!$BA$6:$BA$3108,"<>"),"") -> 0.72519084 | M6: =IFERROR(AVERAGEIFS(Events!$AY$6:$AY$3108,Events!$A$6:$A$3108,$A6),"") -> 0.025583819 | N6: =IFERROR(AVERAGEIFS(Events!$CJ$6:$CJ$3108,Events!$A$6:$A$3108,$A6),"") -> 0.063118768 | O6: =IFERROR(AVERAGEIFS(Events!$CK$6:$CK$3108,Events!$A$6:$A$3108,$A6),"") -> 0.39623744 | P6: =IFERROR(AVERAGEIFS(Events!$CI$6:$CI$3108,Events!$A$6:$A$3108,$A6),"") -> -0.12198804 | Q6: =COUNTIFS(Events!$A$6:$A$3108,$A6,Events!$CM$6:$CM$3108,"Yes",Events!$CL$6:$CL$3108,"<>") -> 53 | R6: =IFERROR(AVERAGEIFS(Events!$CL$6:$CL$3108,Events!$A$6:$A$3108,$A6,Events!$CM$6:$CM$3108,"Yes"),"") -> 0.070544851 | S6: =IFERROR(COUNTIFS(Events!$A$6:$A$3108,$A6,Events!$CL$6:$CL$3108,">0",Events!$CM$6:$CM$3108,"Yes")/COUNTIFS(Events!$A$6:$A$3108,$A6,Events!$CL$6:$CL$3108,"<>",Events!$CM$6:$CM$3108,"Yes"),"") -> 0.30188679
A7: Q2 FY24 | B7: Jul-Sep 2023 | C7: =COUNTIFS(Events!$A$6:$A$3108,$A7) -> 202 | D7: =COUNTIFS(Events!$A$6:$A$3108,$A7,Events!$K$6:$K$3108,"After close") -> 109 | E7: =COUNTIFS(Events!$A$6:$A$3108,$A7,Events!$K$6:$K$3108,"During market") -> 71 | F7: =COUNTIFS(Events!$A$6:$A$3108,$A7,Events!$K$6:$K$3108,"Non-trading day") -> 20 | G7: =IFERROR(AVERAGEIFS(Events!$T$6:$T$3108,Events!$A$6:$A$3108,$A7),"") -> 0.0075002949 | H7: =IFERROR(COUNTIFS(Events!$A$6:$A$3108,$A7,Events!$T$6:$T$3108,">0")/COUNTIFS(Events!$A$6:$A$3108,$A7,Events!$T$6:$T$3108,"<>"),"") -> 0.54123711 | I7: =IFERROR(AVERAGEIFS(Events!$W$6:$W$3108,Events!$A$6:$A$3108,$A7),"") -> 0.0068971445 | J7: =IFERROR(AVERAGEIFS(Events!$AC$6:$AC$3108,Events!$A$6:$A$3108,$A7),"") -> 0.024232827 | K7: =IFERROR(COUNTIFS(Events!$A$6:$A$3108,$A7,Events!$AU$6:$AU$3108,">0")/COUNTIFS(Events!$A$6:$A$3108,$A7,Events!$AU$6:$AU$3108,"<>"),"") -> 0.81967213 | L7: =IFERROR(COUNTIFS(Events!$A$6:$A$3108,$A7,Events!$BA$6:$BA$3108,">0")/COUNTIFS(Events!$A$6:$A$3108,$A7,Events!$BA$6:$BA$3108,"<>"),"") -> 0.78064516 | M7: =IFERROR(AVERAGEIFS(Events!$AY$6:$AY$3108,Events!$A$6:$A$3108,$A7),"") -> 0.036674867 | N7: =IFERROR(AVERAGEIFS(Events!$CJ$6:$CJ$3108,Events!$A$6:$A$3108,$A7),"") -> 0.054308871 | O7: =IFERROR(AVERAGEIFS(Events!$CK$6:$CK$3108,Events!$A$6:$A$3108,$A7),"") -> 0.45796686 | P7: =IFERROR(AVERAGEIFS(Events!$CI$6:$CI$3108,Events!$A$6:$A$3108,$A7),"") -> -0.099620677 | Q7: =COUNTIFS(Events!$A$6:$A$3108,$A7,Events!$CM$6:$CM$3108,"Yes",Events!$CL$6:$CL$3108,"<>") -> 54 | R7: =IFERROR(AVERAGEIFS(Events!$CL$6:$CL$3108,Events!$A$6:$A$3108,$A7,Events!$CM$6:$CM$3108,"Yes"),"") -> 0.051597608 | S7: =IFERROR(COUNTIFS(Events!$A$6:$A$3108,$A7,Events!$CL$6:$CL$3108,">0",Events!$CM$6:$CM$3108,"Yes")/COUNTIFS(Events!$A$6:$A$3108,$A7,Events!$CL$6:$CL$3108,"<>",Events!$CM$6:$CM$3108,"Yes"),"") -> 0.48148148
A8: Q3 FY24 | B8: Oct-Dec 2023 | C8: =COUNTIFS(Events!$A$6:$A$3108,$A8) -> 203 | D8: =COUNTIFS(Events!$A$6:$A$3108,$A8,Events!$K$6:$K$3108,"After close") -> 112 | E8: =COUNTIFS(Events!$A$6:$A$3108,$A8,Events!$K$6:$K$3108,"During market") -> 71 | F8: =COUNTIFS(Events!$A$6:$A$3108,$A8,Events!$K$6:$K$3108,"Non-trading day") -> 20 | G8: =IFERROR(AVERAGEIFS(Events!$T$6:$T$3108,Events!$A$6:$A$3108,$A8),"") -> 0.00071947546 | H8: =IFERROR(COUNTIFS(Events!$A$6:$A$3108,$A8,Events!$T$6:$T$3108,">0")/COUNTIFS(Events!$A$6:$A$3108,$A8,Events!$T$6:$T$3108,"<>"),"") -> 0.5025641 | I8: =IFERROR(AVERAGEIFS(Events!$W$6:$W$3108,Events!$A$6:$A$3108,$A8),"") -> -0.00096846979 | J8: =IFERROR(AVERAGEIFS(Events!$AC$6:$AC$3108,Events!$A$6:$A$3108,$A8),"") -> 0.037795429 | K8: =IFERROR(COUNTIFS(Events!$A$6:$A$3108,$A8,Events!$AU$6:$AU$3108,">0")/COUNTIFS(Events!$A$6:$A$3108,$A8,Events!$AU$6:$AU$3108,"<>"),"") -> 0.84375 | L8: =IFERROR(COUNTIFS(Events!$A$6:$A$3108,$A8,Events!$BA$6:$BA$3108,">0")/COUNTIFS(Events!$A$6:$A$3108,$A8,Events!$BA$6:$BA$3108,"<>"),"") -> 0.77108434 | M8: =IFERROR(AVERAGEIFS(Events!$AY$6:$AY$3108,Events!$A$6:$A$3108,$A8),"") -> 0.028679025 | N8: =IFERROR(AVERAGEIFS(Events!$CJ$6:$CJ$3108,Events!$A$6:$A$3108,$A8),"") -> 0.0790595 | O8: =IFERROR(AVERAGEIFS(Events!$CK$6:$CK$3108,Events!$A$6:$A$3108,$A8),"") -> 0.48901211 | P8: =IFERROR(AVERAGEIFS(Events!$CI$6:$CI$3108,Events!$A$6:$A$3108,$A8),"") -> -0.089277249 | Q8: =COUNTIFS(Events!$A$6:$A$3108,$A8,Events!$CM$6:$CM$3108,"Yes",Events!$CL$6:$CL$3108,"<>") -> 41 | R8: =IFERROR(AVERAGEIFS(Events!$CL$6:$CL$3108,Events!$A$6:$A$3108,$A8,Events!$CM$6:$CM$3108,"Yes"),"") -> 0.19111234 | S8: =IFERROR(COUNTIFS(Events!$A$6:$A$3108,$A8,Events!$CL$6:$CL$3108,">0",Events!$CM$6:$CM$3108,"Yes")/COUNTIFS(Events!$A$6:$A$3108,$A8,Events!$CL$6:$CL$3108,"<>",Events!$CM$6:$CM$3108,"Yes"),"") -> 0.75609756
A9: Q4 FY24 | B9: Jan-Mar 2024 | C9: =COUNTIFS(Events!$A$6:$A$3108,$A9) -> 204 | D9: =COUNTIFS(Events!$A$6:$A$3108,$A9,Events!$K$6:$K$3108,"After close") -> 113 | E9: =COUNTIFS(Events!$A$6:$A$3108,$A9,Events!$K$6:$K$3108,"During market") -> 64 | F9: =COUNTIFS(Events!$A$6:$A$3108,$A9,Events!$K$6:$K$3108,"Non-trading day") -> 26 | G9: =IFERROR(AVERAGEIFS(Events!$T$6:$T$3108,Events!$A$6:$A$3108,$A9),"") -> 0.012048187 | H9: =IFERROR(COUNTIFS(Events!$A$6:$A$3108,$A9,Events!$T$6:$T$3108,">0")/COUNTIFS(Events!$A$6:$A$3108,$A9,Events!$T$6:$T$3108,"<>"),"") -> 0.56852792 | I9: =IFERROR(AVERAGEIFS(Events!$W$6:$W$3108,Events!$A$6:$A$3108,$A9),"") -> 0.0092775438 | J9: =IFERROR(AVERAGEIFS(Events!$AC$6:$AC$3108,Events!$A$6:$A$3108,$A9),"") -> 0.033517389 | K9: =IFERROR(COUNTIFS(Events!$A$6:$A$3108,$A9,Events!$AU$6:$AU$3108,">0")/COUNTIFS(Events!$A$6:$A$3108,$A9,Events!$AU$6:$AU$3108,"<>"),"") -> 0.85492228 | L9: =IFERROR(COUNTIFS(Events!$A$6:$A$3108,$A9,Events!$BA$6:$BA$3108,">0")/COUNTIFS(Events!$A$6:$A$3108,$A9,Events!$BA$6:$BA$3108,"<>"),"") -> 0.68047337 | M9: =IFERROR(AVERAGEIFS(Events!$AY$6:$AY$3108,Events!$A$6:$A$3108,$A9),"") -> 0.01608179 | N9: =IFERROR(AVERAGEIFS(Events!$CJ$6:$CJ$3108,Events!$A$6:$A$3108,$A9),"") -> 0.072850131 | O9: =IFERROR(AVERAGEIFS(Events!$CK$6:$CK$3108,Events!$A$6:$A$3108,$A9),"") -> 0.45750506 | P9: =IFERROR(AVERAGEIFS(Events!$CI$6:$CI$3108,Events!$A$6:$A$3108,$A9),"") -> -0.12888722 | Q9: =COUNTIFS(Events!$A$6:$A$3108,$A9,Events!$CM$6:$CM$3108,"Yes",Events!$CL$6:$CL$3108,"<>") -> 61 | R9: =IFERROR(AVERAGEIFS(Events!$CL$6:$CL$3108,Events!$A$6:$A$3108,$A9,Events!$CM$6:$CM$3108,"Yes"),"") -> 0.054352723 | S9: =IFERROR(COUNTIFS(Events!$A$6:$A$3108,$A9,Events!$CL$6:$CL$3108,">0",Events!$CM$6:$CM$3108,"Yes")/COUNTIFS(Events!$A$6:$A$3108,$A9,Events!$CL$6:$CL$3108,"<>",Events!$CM$6:$CM$3108,"Yes"),"") -> 0.57377049
A10: Q1 FY25 | B10: Apr-Jun 2024 | C10: =COUNTIFS(Events!$A$6:$A$3108,$A10) -> 204 | D10: =COUNTIFS(Events!$A$6:$A$3108,$A10,Events!$K$6:$K$3108,"After close") -> 110 | E10: =COUNTIFS(Events!$A$6:$A$3108,$A10,Events!$K$6:$K$3108,"During market") -> 74 | F10: =COUNTIFS(Events!$A$6:$A$3108,$A10,Events!$K$6:$K$3108,"Non-trading day") -> 19 | G10: =IFERROR(AVERAGEIFS(Events!$T$6:$T$3108,Events!$A$6:$A$3108,$A10),"") -> 0.0077113233 | H10: =IFERROR(COUNTIFS(Events!$A$6:$A$3108,$A10,Events!$T$6:$T$3108,">0")/COUNTIFS(Events!$A$6:$A$3108,$A10,Events!$T$6:$T$3108,"<>"),"") -> 0.53266332 | I10: =IFERROR(AVERAGEIFS(Events!$W$6:$W$3108,Events!$A$6:$A$3108,$A10),"") -> 0.007911735 | J10: =IFERROR(AVERAGEIFS(Events!$AC$6:$AC$3108,Events!$A$6:$A$3108,$A10),"") -> 0.02777609 | K10: =IFERROR(COUNTIFS(Events!$A$6:$A$3108,$A10,Events!$AU$6:$AU$3108,">0")/COUNTIFS(Events!$A$6:$A$3108,$A10,Events!$AU$6:$AU$3108,"<>"),"") -> 0.89005236 | L10: =IFERROR(COUNTIFS(Events!$A$6:$A$3108,$A10,Events!$BA$6:$BA$3108,">0")/COUNTIFS(Events!$A$6:$A$3108,$A10,Events!$BA$6:$BA$3108,"<>"),"") -> 0.77058824 | M10: =IFERROR(AVERAGEIFS(Events!$AY$6:$AY$3108,Events!$A$6:$A$3108,$A10),"") -> -0.0021506247 | N10: =IFERROR(AVERAGEIFS(Events!$CJ$6:$CJ$3108,Events!$A$6:$A$3108,$A10),"") -> 0.068774092 | O10: =IFERROR(AVERAGEIFS(Events!$CK$6:$CK$3108,Events!$A$6:$A$3108,$A10),"") -> 0.40736744 | P10: =IFERROR(AVERAGEIFS(Events!$CI$6:$CI$3108,Events!$A$6:$A$3108,$A10),"") -> -0.12603567 | Q10: =COUNTIFS(Events!$A$6:$A$3108,$A10,Events!$CM$6:$CM$3108,"Yes",Events!$CL$6:$CL$3108,"<>") -> 49 | R10: =IFERROR(AVERAGEIFS(Events!$CL$6:$CL$3108,Events!$A$6:$A$3108,$A10,Events!$CM$6:$CM$3108,"Yes"),"") -> 0.0081885479 | S10: =IFERROR(COUNTIFS(Events!$A$6:$A$3108,$A10,Events!$CL$6:$CL$3108,">0",Events!$CM$6:$CM$3108,"Yes")/COUNTIFS(Events!$A$6:$A$3108,$A10,Events!$CL$6:$CL$3108,"<>",Events!$CM$6:$CM$3108,"Yes"),"") -> 0.3877551
A11: Q2 FY25 | B11: Jul-Sep 2024 | C11: =COUNTIFS(Events!$A$6:$A$3108,$A11) -> 209 | D11: =COUNTIFS(Events!$A$6:$A$3108,$A11,Events!$K$6:$K$3108,"After close") -> 126 | E11: =COUNTIFS(Events!$A$6:$A$3108,$A11,Events!$K$6:$K$3108,"During market") -> 69 | F11: =COUNTIFS(Events!$A$6:$A$3108,$A11,Events!$K$6:$K$3108,"Non-trading day") -> 13 | G11: =IFERROR(AVERAGEIFS(Events!$T$6:$T$3108,Events!$A$6:$A$3108,$A11),"") -> -0.0061816112 | H11: =IFERROR(COUNTIFS(Events!$A$6:$A$3108,$A11,Events!$T$6:$T$3108,">0")/COUNTIFS(Events!$A$6:$A$3108,$A11,Events!$T$6:$T$3108,"<>"),"") -> 0.42857143 | I11: =IFERROR(AVERAGEIFS(Events!$W$6:$W$3108,Events!$A$6:$A$3108,$A11),"") -> 0.00070968564 | J11: =IFERROR(AVERAGEIFS(Events!$AC$6:$AC$3108,Events!$A$6:$A$3108,$A11),"") -> 0.037371603 | K11: =IFERROR(COUNTIFS(Events!$A$6:$A$3108,$A11,Events!$AU$6:$AU$3108,">0")/COUNTIFS(Events!$A$6:$A$3108,$A11,Events!$AU$6:$AU$3108,"<>"),"") -> 0.87309645 | L11: =IFERROR(COUNTIFS(Events!$A$6:$A$3108,$A11,Events!$BA$6:$BA$3108,">0")/COUNTIFS(Events!$A$6:$A$3108,$A11,Events!$BA$6:$BA$3108,"<>"),"") -> 0.69822485 | M11: =IFERROR(AVERAGEIFS(Events!$AY$6:$AY$3108,Events!$A$6:$A$3108,$A11),"") -> 0.015624645 | N11: =IFERROR(AVERAGEIFS(Events!$CJ$6:$CJ$3108,Events!$A$6:$A$3108,$A11),"") -> 0.058222861 | O11: =IFERROR(AVERAGEIFS(Events!$CK$6:$CK$3108,Events!$A$6:$A$3108,$A11),"") -> 0.65267496 | P11: =IFERROR(AVERAGEIFS(Events!$CI$6:$CI$3108,Events!$A$6:$A$3108,$A11),"") -> -0.16461315 | Q11: =COUNTIFS(Events!$A$6:$A$3108,$A11,Events!$CM$6:$CM$3108,"Yes",Events!$CL$6:$CL$3108,"<>") -> 109 | R11: =IFERROR(AVERAGEIFS(Events!$CL$6:$CL$3108,Events!$A$6:$A$3108,$A11,Events!$CM$6:$CM$3108,"Yes"),"") -> 0.19278184 | S11: =IFERROR(COUNTIFS(Events!$A$6:$A$3108,$A11,Events!$CL$6:$CL$3108,">0",Events!$CM$6:$CM$3108,"Yes")/COUNTIFS(Events!$A$6:$A$3108,$A11,Events!$CL$6:$CL$3108,"<>",Events!$CM$6:$CM$3108,"Yes"),"") -> 0.56880734
A12: Q3 FY25 | B12: Oct-Dec 2024 | C12: =COUNTIFS(Events!$A$6:$A$3108,$A12) -> 210 | D12: =COUNTIFS(Events!$A$6:$A$3108,$A12,Events!$K$6:$K$3108,"After close") -> 129 | E12: =COUNTIFS(Events!$A$6:$A$3108,$A12,Events!$K$6:$K$3108,"During market") -> 70 | F12: =COUNTIFS(Events!$A$6:$A$3108,$A12,Events!$K$6:$K$3108,"Non-trading day") -> 9 | G12: =IFERROR(AVERAGEIFS(Events!$T$6:$T$3108,Events!$A$6:$A$3108,$A12),"") -> -0.0053164652 | H12: =IFERROR(COUNTIFS(Events!$A$6:$A$3108,$A12,Events!$T$6:$T$3108,">0")/COUNTIFS(Events!$A$6:$A$3108,$A12,Events!$T$6:$T$3108,"<>"),"") -> 0.46601942 | I12: =IFERROR(AVERAGEIFS(Events!$W$6:$W$3108,Events!$A$6:$A$3108,$A12),"") -> -0.0054772659 | J12: =IFERROR(AVERAGEIFS(Events!$AC$6:$AC$3108,Events!$A$6:$A$3108,$A12),"") -> 0.03529863 | K12: =IFERROR(COUNTIFS(Events!$A$6:$A$3108,$A12,Events!$AU$6:$AU$3108,">0")/COUNTIFS(Events!$A$6:$A$3108,$A12,Events!$AU$6:$AU$3108,"<>"),"") -> 0.88383838 | L12: =IFERROR(COUNTIFS(Events!$A$6:$A$3108,$A12,Events!$BA$6:$BA$3108,">0")/COUNTIFS(Events!$A$6:$A$3108,$A12,Events!$BA$6:$BA$3108,"<>"),"") -> 0.64772727 | M12: =IFERROR(AVERAGEIFS(Events!$AY$6:$AY$3108,Events!$A$6:$A$3108,$A12),"") -> 0.011927833 | N12: =IFERROR(AVERAGEIFS(Events!$CJ$6:$CJ$3108,Events!$A$6:$A$3108,$A12),"") -> 0.074843855 | O12: =IFERROR(AVERAGEIFS(Events!$CK$6:$CK$3108,Events!$A$6:$A$3108,$A12),"") -> 0.48273734 | P12: =IFERROR(AVERAGEIFS(Events!$CI$6:$CI$3108,Events!$A$6:$A$3108,$A12),"") -> -0.16406961 | Q12: =COUNTIFS(Events!$A$6:$A$3108,$A12,Events!$CM$6:$CM$3108,"Yes",Events!$CL$6:$CL$3108,"<>") -> 97 | R12: =IFERROR(AVERAGEIFS(Events!$CL$6:$CL$3108,Events!$A$6:$A$3108,$A12,Events!$CM$6:$CM$3108,"Yes"),"") -> 0.010531451 | S12: =IFERROR(COUNTIFS(Events!$A$6:$A$3108,$A12,Events!$CL$6:$CL$3108,">0",Events!$CM$6:$CM$3108,"Yes")/COUNTIFS(Events!$A$6:$A$3108,$A12,Events!$CL$6:$CL$3108,"<>",Events!$CM$6:$CM$3108,"Yes"),"") -> 0.4742268
A13: Q4 FY25 | B13: Jan-Mar 2025 | C13: =COUNTIFS(Events!$A$6:$A$3108,$A13) -> 212 | D13: =COUNTIFS(Events!$A$6:$A$3108,$A13,Events!$K$6:$K$3108,"After close") -> 160 | E13: =COUNTIFS(Events!$A$6:$A$3108,$A13,Events!$K$6:$K$3108,"During market") -> 31 | F13: =COUNTIFS(Events!$A$6:$A$3108,$A13,Events!$K$6:$K$3108,"Non-trading day") -> 17 | G13: =IFERROR(AVERAGEIFS(Events!$T$6:$T$3108,Events!$A$6:$A$3108,$A13),"") -> 0.010293256 | H13: =IFERROR(COUNTIFS(Events!$A$6:$A$3108,$A13,Events!$T$6:$T$3108,">0")/COUNTIFS(Events!$A$6:$A$3108,$A13,Events!$T$6:$T$3108,"<>"),"") -> 0.52380952 | I13: =IFERROR(AVERAGEIFS(Events!$W$6:$W$3108,Events!$A$6:$A$3108,$A13),"") -> 0.0059475698 | J13: =IFERROR(AVERAGEIFS(Events!$AC$6:$AC$3108,Events!$A$6:$A$3108,$A13),"") -> 0.027829355 | K13: =IFERROR(COUNTIFS(Events!$A$6:$A$3108,$A13,Events!$AU$6:$AU$3108,">0")/COUNTIFS(Events!$A$6:$A$3108,$A13,Events!$AU$6:$AU$3108,"<>"),"") -> 0.85427136 | L13: =IFERROR(COUNTIFS(Events!$A$6:$A$3108,$A13,Events!$BA$6:$BA$3108,">0")/COUNTIFS(Events!$A$6:$A$3108,$A13,Events!$BA$6:$BA$3108,"<>"),"") -> 0.66666667 | M13: =IFERROR(AVERAGEIFS(Events!$AY$6:$AY$3108,Events!$A$6:$A$3108,$A13),"") -> 0.006597987 | N13: =IFERROR(AVERAGEIFS(Events!$CJ$6:$CJ$3108,Events!$A$6:$A$3108,$A13),"") -> 0.072933463 | O13: =IFERROR(AVERAGEIFS(Events!$CK$6:$CK$3108,Events!$A$6:$A$3108,$A13),"") -> 0.36940703 | P13: =IFERROR(AVERAGEIFS(Events!$CI$6:$CI$3108,Events!$A$6:$A$3108,$A13),"") -> -0.11633419 | Q13: =COUNTIFS(Events!$A$6:$A$3108,$A13,Events!$CM$6:$CM$3108,"Yes",Events!$CL$6:$CL$3108,"<>") -> 74 | R13: =IFERROR(AVERAGEIFS(Events!$CL$6:$CL$3108,Events!$A$6:$A$3108,$A13,Events!$CM$6:$CM$3108,"Yes"),"") -> -0.038828429 | S13: =IFERROR(COUNTIFS(Events!$A$6:$A$3108,$A13,Events!$CL$6:$CL$3108,">0",Events!$CM$6:$CM$3108,"Yes")/COUNTIFS(Events!$A$6:$A$3108,$A13,Events!$CL$6:$CL$3108,"<>",Events!$CM$6:$CM$3108,"Yes"),"") -> 0.32432432
A14: Q1 FY26 | B14: Apr-Jun 2025 | C14: =COUNTIFS(Events!$A$6:$A$3108,$A14) -> 212 | D14: =COUNTIFS(Events!$A$6:$A$3108,$A14,Events!$K$6:$K$3108,"After close") -> 128 | E14: =COUNTIFS(Events!$A$6:$A$3108,$A14,Events!$K$6:$K$3108,"During market") -> 70 | F14: =COUNTIFS(Events!$A$6:$A$3108,$A14,Events!$K$6:$K$3108,"Non-trading day") -> 13 | G14: =IFERROR(AVERAGEIFS(Events!$T$6:$T$3108,Events!$A$6:$A$3108,$A14),"") -> -0.0024914309 | H14: =IFERROR(COUNTIFS(Events!$A$6:$A$3108,$A14,Events!$T$6:$T$3108,">0")/COUNTIFS(Events!$A$6:$A$3108,$A14,Events!$T$6:$T$3108,"<>"),"") -> 0.47142857 | I14: =IFERROR(AVERAGEIFS(Events!$W$6:$W$3108,Events!$A$6:$A$3108,$A14),"") -> 0.0010809227 | J14: =IFERROR(AVERAGEIFS(Events!$AC$6:$AC$3108,Events!$A$6:$A$3108,$A14),"") -> 0.027183741 | K14: =IFERROR(COUNTIFS(Events!$A$6:$A$3108,$A14,Events!$AU$6:$AU$3108,">0")/COUNTIFS(Events!$A$6:$A$3108,$A14,Events!$AU$6:$AU$3108,"<>"),"") -> 0.8241206 | L14: =IFERROR(COUNTIFS(Events!$A$6:$A$3108,$A14,Events!$BA$6:$BA$3108,">0")/COUNTIFS(Events!$A$6:$A$3108,$A14,Events!$BA$6:$BA$3108,"<>"),"") -> 0.68333333 | M14: =IFERROR(AVERAGEIFS(Events!$AY$6:$AY$3108,Events!$A$6:$A$3108,$A14),"") -> 0.0033443195 | N14: =IFERROR(AVERAGEIFS(Events!$CJ$6:$CJ$3108,Events!$A$6:$A$3108,$A14),"") -> 0.057104604 | O14: =IFERROR(AVERAGEIFS(Events!$CK$6:$CK$3108,Events!$A$6:$A$3108,$A14),"") -> 0.45429194 | P14: =IFERROR(AVERAGEIFS(Events!$CI$6:$CI$3108,Events!$A$6:$A$3108,$A14),"") -> -0.11774236 | Q14: =COUNTIFS(Events!$A$6:$A$3108,$A14,Events!$CM$6:$CM$3108,"Yes",Events!$CL$6:$CL$3108,"<>") -> 122 | R14: =IFERROR(AVERAGEIFS(Events!$CL$6:$CL$3108,Events!$A$6:$A$3108,$A14,Events!$CM$6:$CM$3108,"Yes"),"") -> 0.0092613044 | S14: =IFERROR(COUNTIFS(Events!$A$6:$A$3108,$A14,Events!$CL$6:$CL$3108,">0",Events!$CM$6:$CM$3108,"Yes")/COUNTIFS(Events!$A$6:$A$3108,$A14,Events!$CL$6:$CL$3108,"<>",Events!$CM$6:$CM$3108,"Yes"),"") -> 0.28688525
A15: Q2 FY26 | B15: Jul-Sep 2025 | C15: =COUNTIFS(Events!$A$6:$A$3108,$A15) -> 212 | D15: =COUNTIFS(Events!$A$6:$A$3108,$A15,Events!$K$6:$K$3108,"After close") -> 131 | E15: =COUNTIFS(Events!$A$6:$A$3108,$A15,Events!$K$6:$K$3108,"During market") -> 60 | F15: =COUNTIFS(Events!$A$6:$A$3108,$A15,Events!$K$6:$K$3108,"Non-trading day") -> 20 | G15: =IFERROR(AVERAGEIFS(Events!$T$6:$T$3108,Events!$A$6:$A$3108,$A15),"") -> 0.0066284719 | H15: =IFERROR(COUNTIFS(Events!$A$6:$A$3108,$A15,Events!$T$6:$T$3108,">0")/COUNTIFS(Events!$A$6:$A$3108,$A15,Events!$T$6:$T$3108,"<>"),"") -> 0.53554502 | I15: =IFERROR(AVERAGEIFS(Events!$W$6:$W$3108,Events!$A$6:$A$3108,$A15),"") -> 0.0044425224 | J15: =IFERROR(AVERAGEIFS(Events!$AC$6:$AC$3108,Events!$A$6:$A$3108,$A15),"") -> 0.02942194 | K15: =IFERROR(COUNTIFS(Events!$A$6:$A$3108,$A15,Events!$AU$6:$AU$3108,">0")/COUNTIFS(Events!$A$6:$A$3108,$A15,Events!$AU$6:$AU$3108,"<>"),"") -> 0.8627451 | L15: =IFERROR(COUNTIFS(Events!$A$6:$A$3108,$A15,Events!$BA$6:$BA$3108,">0")/COUNTIFS(Events!$A$6:$A$3108,$A15,Events!$BA$6:$BA$3108,"<>"),"") -> 0.67955801 | M15: =IFERROR(AVERAGEIFS(Events!$AY$6:$AY$3108,Events!$A$6:$A$3108,$A15),"") -> -0.0033096847 | N15: =IFERROR(AVERAGEIFS(Events!$CJ$6:$CJ$3108,Events!$A$6:$A$3108,$A15),"") -> 0.055983082 | O15: =IFERROR(AVERAGEIFS(Events!$CK$6:$CK$3108,Events!$A$6:$A$3108,$A15),"") -> 0.53291966 | P15: =IFERROR(AVERAGEIFS(Events!$CI$6:$CI$3108,Events!$A$6:$A$3108,$A15),"") -> -0.13620364 | Q15: =COUNTIFS(Events!$A$6:$A$3108,$A15,Events!$CM$6:$CM$3108,"Yes",Events!$CL$6:$CL$3108,"<>") -> 122 | R15: =IFERROR(AVERAGEIFS(Events!$CL$6:$CL$3108,Events!$A$6:$A$3108,$A15,Events!$CM$6:$CM$3108,"Yes"),"") -> -0.015100843 | S15: =IFERROR(COUNTIFS(Events!$A$6:$A$3108,$A15,Events!$CL$6:$CL$3108,">0",Events!$CM$6:$CM$3108,"Yes")/COUNTIFS(Events!$A$6:$A$3108,$A15,Events!$CL$6:$CL$3108,"<>",Events!$CM$6:$CM$3108,"Yes"),"") -> 0.37704918
... A18: Q1 FY27 | B18: Apr-Jun 2026 | C18: =COUNTIFS(Events!$A$6:$A$3108,$A18) -> 212 | D18: =COUNTIFS(Events!$A$6:$A$3108,$A18,Events!$K$6:$K$3108,"After close") -> 114 | E18: =COUNTIFS(Events!$A$6:$A$3108,$A18,Events!$K$6:$K$3108,"During market") -> 80 | F18: =COUNTIFS(Events!$A$6:$A$3108,$A18,Events!$K$6:$K$3108,"Non-trading day") -> 16 | G18: =IFERROR(AVERAGEIFS(Events!$T$6:$T$3108,Events!$A$6:$A$3108,$A18),"") -> 0.0035881287 | H18: =IFERROR(COUNTIFS(Events!$A$6:$A$3108,$A18,Events!$T$6:$T$3108,">0")/COUNTIFS(Events!$A$6:$A$3108,$A18,Events!$T$6:$T$3108,"<>"),"") -> 0.51415094 | I18: =IFERROR(AVERAGEIFS(Events!$W$6:$W$3108,Events!$A$6:$A$3108,$A18),"") -> 0.0011012401 | J18: =IFERROR(AVERAGEIFS(Events!$AC$6:$AC$3108,Events!$A$6:$A$3108,$A18),"") -> 0.030007701 | K18: =IFERROR(COUNTIFS(Events!$A$6:$A$3108,$A18,Events!$AU$6:$AU$3108,">0")/COUNTIFS(Events!$A$6:$A$3108,$A18,Events!$AU$6:$AU$3108,"<>"),"") -> 0.92270531 | L18: =IFERROR(COUNTIFS(Events!$A$6:$A$3108,$A18,Events!$BA$6:$BA$3108,">0")/COUNTIFS(Events!$A$6:$A$3108,$A18,Events!$BA$6:$BA$3108,"<>"),"") -> 0.75647668 | M18: =IFERROR(AVERAGEIFS(Events!$AY$6:$AY$3108,Events!$A$6:$A$3108,$A18),"") -> 0.0044008573 | N18: =IFERROR(AVERAGEIFS(Events!$CJ$6:$CJ$3108,Events!$A$6:$A$3108,$A18),"") -> 0.064907961 | O18: =IFERROR(AVERAGEIFS(Events!$CK$6:$CK$3108,Events!$A$6:$A$3108,$A18),"") -> 0.46502498 | P18: =IFERROR(AVERAGEIFS(Events!$CI$6:$CI$3108,Events!$A$6:$A$3108,$A18),"") -> -0.14724885 | Q18: =COUNTIFS(Events!$A$6:$A$3108,$A18,Events!$CM$6:$CM$3108,"Yes",Events!$CL$6:$CL$3108,"<>") -> 111 | R18: =IFERROR(AVERAGEIFS(Events!$CL$6:$CL$3108,Events!$A$6:$A$3108,$A18,Events!$CM$6:$CM$3108,"Yes"),"") -> -0.0061018844 | S18: =IFERROR(COUNTIFS(Events!$A$6:$A$3108,$A18,Events!$CL$6:$CL$3108,">0",Events!$CM$6:$CM$3108,"Yes")/COUNTIFS(Events!$A$6:$A$3108,$A18,Events!$CL$6:$CL$3108,"<>",Events!$CM$6:$CM$3108,"Yes"),"") -> 0.33333333
A19: All quarters | C19: =COUNTIFS(Events!$A$6:$A$3108,"<>") -> 3103 | D19: =COUNTIFS(Events!$A$6:$A$3108,"<>",Events!$K$6:$K$3108,"After close") -> 1841 | E19: =COUNTIFS(Events!$A$6:$A$3108,"<>",Events!$K$6:$K$3108,"During market") -> 982 | F19: =COUNTIFS(Events!$A$6:$A$3108,"<>",Events!$K$6:$K$3108,"Non-trading day") -> 260 | G19: =IFERROR(AVERAGEIFS(Events!$T$6:$T$3108,Events!$A$6:$A$3108,"<>"),"") -> 0.0032559418 | H19: =IFERROR(COUNTIFS(Events!$A$6:$A$3108,"<>",Events!$T$6:$T$3108,">0")/COUNTIFS(Events!$A$6:$A$3108,"<>",Events!$T$6:$T$3108,"<>"),"") -> 0.50445692 | I19: =IFERROR(AVERAGEIFS(Events!$W$6:$W$3108,Events!$A$6:$A$3108,"<>"),"") -> 0.0029667542 | J19: =IFERROR(AVERAGEIFS(Events!$AC$6:$AC$3108,Events!$A$6:$A$3108,"<>"),"") -> 0.030677338 | K19: =IFERROR(COUNTIFS(Events!$A$6:$A$3108,"<>",Events!$AU$6:$AU$3108,">0")/COUNTIFS(Events!$A$6:$A$3108,"<>",Events!$AU$6:$AU$3108,"<>"),"") -> 0.86401384 | L19: =IFERROR(COUNTIFS(Events!$A$6:$A$3108,"<>",Events!$BA$6:$BA$3108,">0")/COUNTIFS(Events!$A$6:$A$3108,"<>",Events!$BA$6:$BA$3108,"<>"),"") -> 0.70227808 | M19: =IFERROR(AVERAGEIFS(Events!$AY$6:$AY$3108,Events!$A$6:$A$3108,"<>"),"") -> 0.0075195822 | N19: =IFERROR(AVERAGEIFS(Events!$CJ$6:$CJ$3108,Events!$A$6:$A$3108,"<>"),"") -> 0.065824381 | O19: =IFERROR(AVERAGEIFS(Events!$CK$6:$CK$3108,Events!$A$6:$A$3108,"<>"),"") -> 0.47374933 | P19: =IFERROR(AVERAGEIFS(Events!$CI$6:$CI$3108,Events!$A$6:$A$3108,"<>"),"") -> -0.12756074 | Q19: =COUNTIFS(Events!$A$6:$A$3108,"<>",Events!$CM$6:$CM$3108,"Yes",Events!$CL$6:$CL$3108,"<>") -> 1220 | R19: =IFERROR(AVERAGEIFS(Events!$CL$6:$CL$3108,Events!$A$6:$A$3108,"<>",Events!$CM$6:$CM$3108,"Yes"),"") -> 0.038055532 | S19: =IFERROR(COUNTIFS(Events!$A$6:$A$3108,"<>",Events!$CL$6:$CL$3108,">0",Events!$CM$6:$CM$3108,"Yes")/COUNTIFS(Events!$A$6:$A$3108,"<>",Events!$CL$6:$CL$3108,"<>",Events!$CM$6:$CM$3108,"Yes"),"") -> 0.43360656

Sheet By industry
A1: By industry (NSE industry classification)
A2: Formulas over the Events sheet, all 15 quarters.
A3: Industry | B3: Results events | C3: After close | D3: During market | E3: Weekend / holiday | F3: Avg three-day sum % | G3: % three-day positive | H3: Avg excess vs Nifty % | I3: Avg size of reaction move % | J3: % sales up YoY | K3: % profit up YoY | L3: Avg EBITDA margin chg YoY (pts) | M3: Avg expected move % (options) | N3: Avg actual / expected move (x) | O3: Avg IV drop % | P3: Run-up trades (rule pass) | Q3: Run-up avg return % (rule pass) | R3: Run-up win rate (rule pass)
A4: Banks | B4: =COUNTIFS(Events!$F$6:$F$3108,$A4) -> 225 | C4: =COUNTIFS(Events!$F$6:$F$3108,$A4,Events!$K$6:$K$3108,"After close") -> 60 | D4: =COUNTIFS(Events!$F$6:$F$3108,$A4,Events!$K$6:$K$3108,"During market") -> 88 | E4: =COUNTIFS(Events!$F$6:$F$3108,$A4,Events!$K$6:$K$3108,"Non-trading day") -> 77 | F4: =IFERROR(AVERAGEIFS(Events!$T$6:$T$3108,Events!$F$6:$F$3108,$A4),"") -> 0.0010748307 | G4: =IFERROR(COUNTIFS(Events!$F$6:$F$3108,$A4,Events!$T$6:$T$3108,">0")/COUNTIFS(Events!$F$6:$F$3108,$A4,Events!$T$6:$T$3108,"<>"),"") -> 0.54222222 | H4: =IFERROR(AVERAGEIFS(Events!$W$6:$W$3108,Events!$F$6:$F$3108,$A4),"") -> 0.0022603272 | I4: =IFERROR(AVERAGEIFS(Events!$AC$6:$AC$3108,Events!$F$6:$F$3108,$A4),"") -> 0.030514663 | J4: =IFERROR(COUNTIFS(Events!$F$6:$F$3108,$A4,Events!$AU$6:$AU$3108,">0")/COUNTIFS(Events!$F$6:$F$3108,$A4,Events!$AU$6:$AU$3108,"<>"),"") -> 0.93809524 | K4: =IFERROR(COUNTIFS(Events!$F$6:$F$3108,$A4,Events!$BA$6:$BA$3108,">0")/COUNTIFS(Events!$F$6:$F$3108,$A4,Events!$BA$6:$BA$3108,"<>"),"") -> 0.85576923 | L4: =IFERROR(AVERAGEIFS(Events!$AY$6:$AY$3108,Events!$F$6:$F$3108,$A4),"") | M4: =IFERROR(AVERAGEIFS(Events!$CJ$6:$CJ$3108,Events!$F$6:$F$3108,$A4),"") -> 0.060028872 | N4: =IFERROR(AVERAGEIFS(Events!$CK$6:$CK$3108,Events!$F$6:$F$3108,$A4),"") -> 0.54404705 | O4: =IFERROR(AVERAGEIFS(Events!$CI$6:$CI$3108,Events!$F$6:$F$3108,$A4),"") -> -0.16681027 | P4: =COUNTIFS(Events!$F$6:$F$3108,$A4,Events!$CM$6:$CM$3108,"Yes",Events!$CL$6:$CL$3108,"<>") -> 92 | Q4: =IFERROR(AVERAGEIFS(Events!$CL$6:$CL$3108,Events!$F$6:$F$3108,$A4,Events!$CM$6:$CM$3108,"Yes"),"") -> 0.046335422 | R4: =IFERROR(COUNTIFS(Events!$F$6:$F$3108,$A4,Events!$CL$6:$CL$3108,">0",Events!$CM$6:$CM$3108,"Yes")/COUNTIFS(Events!$F$6:$F$3108,$A4,Events!$CL$6:$CL$3108,"<>",Events!$CM$6:$CM$3108,"Yes"),"") -> 0.40217391
A5: Computers - Software | B5: =COUNTIFS(Events!$F$6:$F$3108,$A5) -> 150 | C5: =COUNTIFS(Events!$F$6:$F$3108,$A5,Events!$K$6:$K$3108,"After close") -> 125 | D5: =COUNTIFS(Events!$F$6:$F$3108,$A5,Events!$K$6:$K$3108,"During market") -> 16 | E5: =COUNTIFS(Events!$F$6:$F$3108,$A5,Events!$K$6:$K$3108,"Non-trading day") -> 4 | F5: =IFERROR(AVERAGEIFS(Events!$T$6:$T$3108,Events!$F$6:$F$3108,$A5),"") -> 5.821061e-05 | G5: =IFERROR(COUNTIFS(Events!$F$6:$F$3108,$A5,Events!$T$6:$T$3108,">0")/COUNTIFS(Events!$F$6:$F$3108,$A5,Events!$T$6:$T$3108,"<>"),"") -> 0.48 | H5: =IFERROR(AVERAGEIFS(Events!$W$6:$W$3108,Events!$F$6:$F$3108,$A5),"") -> -0.0012781954 | I5: =IFERROR(AVERAGEIFS(Events!$AC$6:$AC$3108,Events!$F$6:$F$3108,$A5),"") -> 0.035128955 | J5: =IFERROR(COUNTIFS(Events!$F$6:$F$3108,$A5,Events!$AU$6:$AU$3108,">0")/COUNTIFS(Events!$F$6:$F$3108,$A5,Events!$AU$6:$AU$3108,"<>"),"") -> 0.90344828 | K5: =IFERROR(COUNTIFS(Events!$F$6:$F$3108,$A5,Events!$BA$6:$BA$3108,">0")/COUNTIFS(Events!$F$6:$F$3108,$A5,Events!$BA$6:$BA$3108,"<>"),"") -> 0.69503546 | L5: =IFERROR(AVERAGEIFS(Events!$AY$6:$AY$3108,Events!$F$6:$F$3108,$A5),"") -> -0.041522736 | M5: =IFERROR(AVERAGEIFS(Events!$CJ$6:$CJ$3108,Events!$F$6:$F$3108,$A5),"") -> 0.062748578 | N5: =IFERROR(AVERAGEIFS(Events!$CK$6:$CK$3108,Events!$F$6:$F$3108,$A5),"") -> 0.61009208 | O5: =IFERROR(AVERAGEIFS(Events!$CI$6:$CI$3108,Events!$F$6:$F$3108,$A5),"") -> -0.22089315 | P5: =COUNTIFS(Events!$F$6:$F$3108,$A5,Events!$CM$6:$CM$3108,"Yes",Events!$CL$6:$CL$3108,"<>") -> 98 | Q5: =IFERROR(AVERAGEIFS(Events!$CL$6:$CL$3108,Events!$F$6:$F$3108,$A5,Events!$CM$6:$CM$3108,"Yes"),"") -> 0.07663019 | R5: =IFERROR(COUNTIFS(Events!$F$6:$F$3108,$A5,Events!$CL$6:$CL$3108,">0",Events!$CM$6:$CM$3108,"Yes")/COUNTIFS(Events!$F$6:$F$3108,$A5,Events!$CL$6:$CL$3108,"<>",Events!$CM$6:$CM$3108,"Yes"),"") -> 0.5
A6: Pharmaceuticals | B6: =COUNTIFS(Events!$F$6:$F$3108,$A6) -> 135 | C6: =COUNTIFS(Events!$F$6:$F$3108,$A6,Events!$K$6:$K$3108,"After close") -> 81 | D6: =COUNTIFS(Events!$F$6:$F$3108,$A6,Events!$K$6:$K$3108,"During market") -> 34 | E6: =COUNTIFS(Events!$F$6:$F$3108,$A6,Events!$K$6:$K$3108,"Non-trading day") -> 19 | F6: =IFERROR(AVERAGEIFS(Events!$T$6:$T$3108,Events!$F$6:$F$3108,$A6),"") -> 0.0039927517 | G6: =IFERROR(COUNTIFS(Events!$F$6:$F$3108,$A6,Events!$T$6:$T$3108,">0")/COUNTIFS(Events!$F$6:$F$3108,$A6,Events!$T$6:$T$3108,"<>"),"") -> 0.52592593 | H6: =IFERROR(AVERAGEIFS(Events!$W$6:$W$3108,Events!$F$6:$F$3108,$A6),"") -> 0.0043645434 | I6: =IFERROR(AVERAGEIFS(Events!$AC$6:$AC$3108,Events!$F$6:$F$3108,$A6),"") -> 0.025530363 | J6: =IFERROR(COUNTIFS(Events!$F$6:$F$3108,$A6,Events!$AU$6:$AU$3108,">0")/COUNTIFS(Events!$F$6:$F$3108,$A6,Events!$AU$6:$AU$3108,"<>"),"") -> 0.91791045 | K6: =IFERROR(COUNTIFS(Events!$F$6:$F$3108,$A6,Events!$BA$6:$BA$3108,">0")/COUNTIFS(Events!$F$6:$F$3108,$A6,Events!$BA$6:$BA$3108,"<>"),"") -> 0.68965517 | L6: =IFERROR(AVERAGEIFS(Events!$AY$6:$AY$3108,Events!$F$6:$F$3108,$A6),"") -> 0.0095460651 | M6: =IFERROR(AVERAGEIFS(Events!$CJ$6:$CJ$3108,Events!$F$6:$F$3108,$A6),"") -> 0.061953526 | N6: =IFERROR(AVERAGEIFS(Events!$CK$6:$CK$3108,Events!$F$6:$F$3108,$A6),"") -> 0.4347267 | O6: =IFERROR(AVERAGEIFS(Events!$CI$6:$CI$3108,Events!$F$6:$F$3108,$A6),"") -> -0.15108079 | P6: =COUNTIFS(Events!$F$6:$F$3108,$A6,Events!$CM$6:$CM$3108,"Yes",Events!$CL$6:$CL$3108,"<>") -> 73 | Q6: =IFERROR(AVERAGEIFS(Events!$CL$6:$CL$3108,Events!$F$6:$F$3108,$A6,Events!$CM$6:$CM$3108,"Yes"),"") -> 0.010807613 | R6: =IFERROR(COUNTIFS(Events!$F$6:$F$3108,$A6,Events!$CL$6:$CL$3108,">0",Events!$CM$6:$CM$3108,"Yes")/COUNTIFS(Events!$F$6:$F$3108,$A6,Events!$CL$6:$CL$3108,"<>",Events!$CM$6:$CM$3108,"Yes"),"") -> 0.38356164
A7: Finance | B7: =COUNTIFS(Events!$F$6:$F$3108,$A7) -> 105 | C7: =COUNTIFS(Events!$F$6:$F$3108,$A7,Events!$K$6:$K$3108,"After close") -> 67 | D7: =COUNTIFS(Events!$F$6:$F$3108,$A7,Events!$K$6:$K$3108,"During market") -> 34 | E7: =COUNTIFS(Events!$F$6:$F$3108,$A7,Events!$K$6:$K$3108,"Non-trading day") -> 3 | F7: =IFERROR(AVERAGEIFS(Events!$T$6:$T$3108,Events!$F$6:$F$3108,$A7),"") -> -0.00018276707 | G7: =IFERROR(COUNTIFS(Events!$F$6:$F$3108,$A7,Events!$T$6:$T$3108,">0")/COUNTIFS(Events!$F$6:$F$3108,$A7,Events!$T$6:$T$3108,"<>"),"") -> 0.45714286 | H7: =IFERROR(AVERAGEIFS(Events!$W$6:$W$3108,Events!$F$6:$F$3108,$A7),"") -> -0.0026512148 | I7: =IFERROR(AVERAGEIFS(Events!$AC$6:$AC$3108,Events!$F$6:$F$3108,$A7),"") -> 0.030784593 | J7: =IFERROR(COUNTIFS(Events!$F$6:$F$3108,$A7,Events!$AU$6:$AU$3108,">0")/COUNTIFS(Events!$F$6:$F$3108,$A7,Events!$AU$6:$AU$3108,"<>"),"") -> 0.8952381 | K7: =IFERROR(COUNTIFS(Events!$F$6:$F$3108,$A7,Events!$BA$6:$BA$3108,">0")/COUNTIFS(Events!$F$6:$F$3108,$A7,Events!$BA$6:$BA$3108,"<>"),"") -> 0.81818182 | L7: =IFERROR(AVERAGEIFS(Events!$AY$6:$AY$3108,Events!$F$6:$F$3108,$A7),"") -> -0.0072170239 | M7: =IFERROR(AVERAGEIFS(Events!$CJ$6:$CJ$3108,Events!$F$6:$F$3108,$A7),"") -> 0.069483033 | N7: =IFERROR(AVERAGEIFS(Events!$CK$6:$CK$3108,Events!$F$6:$F$3108,$A7),"") -> 0.49405314 | O7: =IFERROR(AVERAGEIFS(Events!$CI$6:$CI$3108,Events!$F$6:$F$3108,$A7),"") -> -0.10161122 | P7: =COUNTIFS(Events!$F$6:$F$3108,$A7,Events!$CM$6:$CM$3108,"Yes",Events!$CL$6:$CL$3108,"<>") -> 33 | Q7: =IFERROR(AVERAGEIFS(Events!$CL$6:$CL$3108,Events!$F$6:$F$3108,$A7,Events!$CM$6:$CM$3108,"Yes"),"") -> 0.021363641 | R7: =IFERROR(COUNTIFS(Events!$F$6:$F$3108,$A7,Events!$CL$6:$CL$3108,">0",Events!$CM$6:$CM$3108,"Yes")/COUNTIFS(Events!$F$6:$F$3108,$A7,Events!$CL$6:$CL$3108,"<>",Events!$CM$6:$CM$3108,"Yes"),"") -> 0.48484848
A8: Power | B8: =COUNTIFS(Events!$F$6:$F$3108,$A8) -> 90 | C8: =COUNTIFS(Events!$F$6:$F$3108,$A8,Events!$K$6:$K$3108,"After close") -> 69 | D8: =COUNTIFS(Events!$F$6:$F$3108,$A8,Events!$K$6:$K$3108,"During market") -> 12 | E8: =COUNTIFS(Events!$F$6:$F$3108,$A8,Events!$K$6:$K$3108,"Non-trading day") -> 9 | F8: =IFERROR(AVERAGEIFS(Events!$T$6:$T$3108,Events!$F$6:$F$3108,$A8),"") -> -0.0098163744 | G8: =IFERROR(COUNTIFS(Events!$F$6:$F$3108,$A8,Events!$T$6:$T$3108,">0")/COUNTIFS(Events!$F$6:$F$3108,$A8,Events!$T$6:$T$3108,"<>"),"") -> 0.43820225 | H8: =IFERROR(AVERAGEIFS(Events!$W$6:$W$3108,Events!$F$6:$F$3108,$A8),"") -> -0.010493536 | I8: =IFERROR(AVERAGEIFS(Events!$AC$6:$AC$3108,Events!$F$6:$F$3108,$A8),"") -> 0.023062848 | J8: =IFERROR(COUNTIFS(Events!$F$6:$F$3108,$A8,Events!$AU$6:$AU$3108,">0")/COUNTIFS(Events!$F$6:$F$3108,$A8,Events!$AU$6:$AU$3108,"<>"),"") -> 0.69318182 | K8: =IFERROR(COUNTIFS(Events!$F$6:$F$3108,$A8,Events!$BA$6:$BA$3108,">0")/COUNTIFS(Events!$F$6:$F$3108,$A8,Events!$BA$6:$BA$3108,"<>"),"") -> 0.59090909 | L8: =IFERROR(AVERAGEIFS(Events!$AY$6:$AY$3108,Events!$F$6:$F$3108,$A8),"") -> 0.0027631351 | M8: =IFERROR(AVERAGEIFS(Events!$CJ$6:$CJ$3108,Events!$F$6:$F$3108,$A8),"") -> 0.057949907 | N8: =IFERROR(AVERAGEIFS(Events!$CK$6:$CK$3108,Events!$F$6:$F$3108,$A8),"") -> 0.37433348 | O8: =IFERROR(AVERAGEIFS(Events!$CI$6:$CI$3108,Events!$F$6:$F$3108,$A8),"") -> -0.12626492 | P8: =COUNTIFS(Events!$F$6:$F$3108,$A8,Events!$CM$6:$CM$3108,"Yes",Events!$CL$6:$CL$3108,"<>") -> 29 | Q8: =IFERROR(AVERAGEIFS(Events!$CL$6:$CL$3108,Events!$F$6:$F$3108,$A8,Events!$CM$6:$CM$3108,"Yes"),"") -> -0.03199456 | R8: =IFERROR(COUNTIFS(Events!$F$6:$F$3108,$A8,Events!$CL$6:$CL$3108,">0",Events!$CM$6:$CM$3108,"Yes")/COUNTIFS(Events!$F$6:$F$3108,$A8,Events!$CL$6:$CL$3108,"<>",Events!$CM$6:$CM$3108,"Yes"),"") -> 0.44827586
A9: Construction | B9: =COUNTIFS(Events!$F$6:$F$3108,$A9) -> 90 | C9: =COUNTIFS(Events!$F$6:$F$3108,$A9,Events!$K$6:$K$3108,"After close") -> 70 | D9: =COUNTIFS(Events!$F$6:$F$3108,$A9,Events!$K$6:$K$3108,"During market") -> 19 | E9: =COUNTIFS(Events!$F$6:$F$3108,$A9,Events!$K$6:$K$3108,"Non-trading day") -> 1 | F9: =IFERROR(AVERAGEIFS(Events!$T$6:$T$3108,Events!$F$6:$F$3108,$A9),"") -> -0.0083017495 | G9: =IFERROR(COUNTIFS(Events!$F$6:$F$3108,$A9,Events!$T$6:$T$3108,">0")/COUNTIFS(Events!$F$6:$F$3108,$A9,Events!$T$6:$T$3108,"<>"),"") -> 0.38888889 | H9: =IFERROR(AVERAGEIFS(Events!$W$6:$W$3108,Events!$F$6:$F$3108,$A9),"") -> -0.0084033433 | I9: =IFERROR(AVERAGEIFS(Events!$AC$6:$AC$3108,Events!$F$6:$F$3108,$A9),"") -> 0.026495641 | J9: =IFERROR(COUNTIFS(Events!$F$6:$F$3108,$A9,Events!$AU$6:$AU$3108,">0")/COUNTIFS(Events!$F$6:$F$3108,$A9,Events!$AU$6:$AU$3108,"<>"),"") -> 0.71590909 | K9: =IFERROR(COUNTIFS(Events!$F$6:$F$3108,$A9,Events!$BA$6:$BA$3108,">0")/COUNTIFS(Events!$F$6:$F$3108,$A9,Events!$BA$6:$BA$3108,"<>"),"") -> 0.73255814 | L9: =IFERROR(AVERAGEIFS(Events!$AY$6:$AY$3108,Events!$F$6:$F$3108,$A9),"") -> -0.02148609 | M9: =IFERROR(AVERAGEIFS(Events!$CJ$6:$CJ$3108,Events!$F$6:$F$3108,$A9),"") -> 0.072964196 | N9: =IFERROR(AVERAGEIFS(Events!$CK$6:$CK$3108,Events!$F$6:$F$3108,$A9),"") -> 0.41901313 | O9: =IFERROR(AVERAGEIFS(Events!$CI$6:$CI$3108,Events!$F$6:$F$3108,$A9),"") -> -0.11828236 | P9: =COUNTIFS(Events!$F$6:$F$3108,$A9,Events!$CM$6:$CM$3108,"Yes",Events!$CL$6:$CL$3108,"<>") -> 28 | Q9: =IFERROR(AVERAGEIFS(Events!$CL$6:$CL$3108,Events!$F$6:$F$3108,$A9,Events!$CM$6:$CM$3108,"Yes"),"") -> 0.089089993 | R9: =IFERROR(COUNTIFS(Events!$F$6:$F$3108,$A9,Events!$CL$6:$CL$3108,">0",Events!$CM$6:$CM$3108,"Yes")/COUNTIFS(Events!$F$6:$F$3108,$A9,Events!$CL$6:$CL$3108,"<>",Events!$CM$6:$CM$3108,"Yes"),"") -> 0.39285714
A10: Electrical Equipment | B10: =COUNTIFS(Events!$F$6:$F$3108,$A10) -> 75 | C10: =COUNTIFS(Events!$F$6:$F$3108,$A10,Events!$K$6:$K$3108,"After close") -> 48 | D10: =COUNTIFS(Events!$F$6:$F$3108,$A10,Events!$K$6:$K$3108,"During market") -> 26 | E10: =COUNTIFS(Events!$F$6:$F$3108,$A10,Events!$K$6:$K$3108,"Non-trading day") -> 1 | F10: =IFERROR(AVERAGEIFS(Events!$T$6:$T$3108,Events!$F$6:$F$3108,$A10),"") -> 0.0041226543 | G10: =IFERROR(COUNTIFS(Events!$F$6:$F$3108,$A10,Events!$T$6:$T$3108,">0")/COUNTIFS(Events!$F$6:$F$3108,$A10,Events!$T$6:$T$3108,"<>"),"") -> 0.54794521 | H10: =IFERROR(AVERAGEIFS(Events!$W$6:$W$3108,Events!$F$6:$F$3108,$A10),"") -> 0.0021143318 | I10: =IFERROR(AVERAGEIFS(Events!$AC$6:$AC$3108,Events!$F$6:$F$3108,$A10),"") -> 0.03518668 | J10: =IFERROR(COUNTIFS(Events!$F$6:$F$3108,$A10,Events!$AU$6:$AU$3108,">0")/COUNTIFS(Events!$F$6:$F$3108,$A10,Events!$AU$6:$AU$3108,"<>"),"") -> 0.8630137 | K10: =IFERROR(COUNTIFS(Events!$F$6:$F$3108,$A10,Events!$BA$6:$BA$3108,">0")/COUNTIFS(Events!$F$6:$F$3108,$A10,Events!$BA$6:$BA$3108,"<>"),"") -> 0.6557377 | L10: =IFERROR(AVERAGEIFS(Events!$AY$6:$AY$3108,Events!$F$6:$F$3108,$A10),"") -> -0.01799247 | M10: =IFERROR(AVERAGEIFS(Events!$CJ$6:$CJ$3108,Events!$F$6:$F$3108,$A10),"") -> 0.071717235 | N10: =IFERROR(AVERAGEIFS(Events!$CK$6:$CK$3108,Events!$F$6:$F$3108,$A10),"") -> 0.4875787 | O10: =IFERROR(AVERAGEIFS(Events!$CI$6:$CI$3108,Events!$F$6:$F$3108,$A10),"") -> -0.13895853 | P10: =COUNTIFS(Events!$F$6:$F$3108,$A10,Events!$CM$6:$CM$3108,"Yes",Events!$CL$6:$CL$3108,"<>") -> 43 | Q10: =IFERROR(AVERAGEIFS(Events!$CL$6:$CL$3108,Events!$F$6:$F$3108,$A10,Events!$CM$6:$CM$3108,"Yes"),"") -> 0.077711918 | R10: =IFERROR(COUNTIFS(Events!$F$6:$F$3108,$A10,Events!$CL$6:$CL$3108,">0",Events!$CM$6:$CM$3108,"Yes")/COUNTIFS(Events!$F$6:$F$3108,$A10,Events!$CL$6:$CL$3108,"<>",Events!$CM$6:$CM$3108,"Yes"),"") -> 0.46511628
A11: Steel And Steel Products | B11: =COUNTIFS(Events!$F$6:$F$3108,$A11) -> 75 | C11: =COUNTIFS(Events!$F$6:$F$3108,$A11,Events!$K$6:$K$3108,"After close") -> 53 | D11: =COUNTIFS(Events!$F$6:$F$3108,$A11,Events!$K$6:$K$3108,"During market") -> 14 | E11: =COUNTIFS(Events!$F$6:$F$3108,$A11,Events!$K$6:$K$3108,"Non-trading day") -> 8 | F11: =IFERROR(AVERAGEIFS(Events!$T$6:$T$3108,Events!$F$6:$F$3108,$A11),"") -> -0.0029565431 | G11: =IFERROR(COUNTIFS(Events!$F$6:$F$3108,$A11,Events!$T$6:$T$3108,">0")/COUNTIFS(Events!$F$6:$F$3108,$A11,Events!$T$6:$T$3108,"<>"),"") -> 0.52 | H11: =IFERROR(AVERAGEIFS(Events!$W$6:$W$3108,Events!$F$6:$F$3108,$A11),"") -> -0.0043688085 | I11: =IFERROR(AVERAGEIFS(Events!$AC$6:$AC$3108,Events!$F$6:$F$3108,$A11),"") -> 0.02344528 | J11: =IFERROR(COUNTIFS(Events!$F$6:$F$3108,$A11,Events!$AU$6:$AU$3108,">0")/COUNTIFS(Events!$F$6:$F$3108,$A11,Events!$AU$6:$AU$3108,"<>"),"") -> 0.61643836 | K11: =IFERROR(COUNTIFS(Events!$F$6:$F$3108,$A11,Events!$BA$6:$BA$3108,">0")/COUNTIFS(Events!$F$6:$F$3108,$A11,Events!$BA$6:$BA$3108,"<>"),"") -> 0.48148148 | L11: =IFERROR(AVERAGEIFS(Events!$AY$6:$AY$3108,Events!$F$6:$F$3108,$A11),"") -> 0.0023587355 | M11: =IFERROR(AVERAGEIFS(Events!$CJ$6:$CJ$3108,Events!$F$6:$F$3108,$A11),"") -> 0.063199981 | N11: =IFERROR(AVERAGEIFS(Events!$CK$6:$CK$3108,Events!$F$6:$F$3108,$A11),"") -> 0.37954278 | O11: =IFERROR(AVERAGEIFS(Events!$CI$6:$CI$3108,Events!$F$6:$F$3108,$A11),"") -> -0.09757952 | P11: =COUNTIFS(Events!$F$6:$F$3108,$A11,Events!$CM$6:$CM$3108,"Yes",Events!$CL$6:$CL$3108,"<>") -> 35 | Q11: =IFERROR(AVERAGEIFS(Events!$CL$6:$CL$3108,Events!$F$6:$F$3108,$A11,Events!$CM$6:$CM$3108,"Yes"),"") -> -0.0114517 | R11: =IFERROR(COUNTIFS(Events!$F$6:$F$3108,$A11,Events!$CL$6:$CL$3108,">0",Events!$CM$6:$CM$3108,"Yes")/COUNTIFS(Events!$F$6:$F$3108,$A11,Events!$CL$6:$CL$3108,"<>",Events!$CM$6:$CM$3108,"Yes"),"") -> 0.4
A12: Refineries | B12: =COUNTIFS(Events!$F$6:$F$3108,$A12) -> 60 | C12: =COUNTIFS(Events!$F$6:$F$3108,$A12,Events!$K$6:$K$3108,"After close") -> 40 | D12: =COUNTIFS(Events!$F$6:$F$3108,$A12,Events!$K$6:$K$3108,"During market") -> 20 | E12: =COUNTIFS(Events!$F$6:$F$3108,$A12,Events!$K$6:$K$3108,"Non-trading day") -> 0 | F12: =IFERROR(AVERAGEIFS(Events!$T$6:$T$3108,Events!$F$6:$F$3108,$A12),"") -> 0.003830512 | G12: =IFERROR(COUNTIFS(Events!$F$6:$F$3108,$A12,Events!$T$6:$T$3108,">0")/COUNTIFS(Events!$F$6:$F$3108,$A12,Events!$T$6:$T$3108,"<>"),"") -> 0.54237288 | H12: =IFERROR(AVERAGEIFS(Events!$W$6:$W$3108,Events!$F$6:$F$3108,$A12),"") -> 0.0039693205 | I12: =IFERROR(AVERAGEIFS(Events!$AC$6:$AC$3108,Events!$F$6:$F$3108,$A12),"") -> 0.0251297 | J12: =IFERROR(COUNTIFS(Events!$F$6:$F$3108,$A12,Events!$AU$6:$AU$3108,">0")/COUNTIFS(Events!$F$6:$F$3108,$A12,Events!$AU$6:$AU$3108,"<>"),"") -> 0.68965517 | K12: =IFERROR(COUNTIFS(Events!$F$6:$F$3108,$A12,Events!$BA$6:$BA$3108,">0")/COUNTIFS(Events!$F$6:$F$3108,$A12,Events!$BA$6:$BA$3108,"<>"),"") -> 0.5 | L12: =IFERROR(AVERAGEIFS(Events!$AY$6:$AY$3108,Events!$F$6:$F$3108,$A12),"") -> 0.0048226473 | M12: =IFERROR(AVERAGEIFS(Events!$CJ$6:$CJ$3108,Events!$F$6:$F$3108,$A12),"") -> 0.05645762 | N12: =IFERROR(AVERAGEIFS(Events!$CK$6:$CK$3108,Events!$F$6:$F$3108,$A12),"") -> 0.48543483 | O12: =IFERROR(AVERAGEIFS(Events!$CI$6:$CI$3108,Events!$F$6:$F$3108,$A12),"") -> -0.087111459 | P12: =COUNTIFS(Events!$F$6:$F$3108,$A12,Events!$CM$6:$CM$3108,"Yes",Events!$CL$6:$CL$3108,"<>") -> 29 | Q12: =IFERROR(AVERAGEIFS(Events!$CL$6:$CL$3108,Events!$F$6:$F$3108,$A12,Events!$CM$6:$CM$3108,"Yes"),"") -> 0.11897505 | R12: =IFERROR(COUNTIFS(Events!$F$6:$F$3108,$A12,Events!$CL$6:$CL$3108,">0",Events!$CM$6:$CM$3108,"Yes")/COUNTIFS(Events!$F$6:$F$3108,$A12,Events!$CL$6:$CL$3108,"<>",Events!$CM$6:$CM$3108,"Yes"),"") -> 0.4137931
A13: Cement And Cement Products | B13: =COUNTIFS(Events!$F$6:$F$3108,$A13) -> 60 | C13: =COUNTIFS(Events!$F$6:$F$3108,$A13,Events!$K$6:$K$3108,"After close") -> 20 | D13: =COUNTIFS(Events!$F$6:$F$3108,$A13,Events!$K$6:$K$3108,"During market") -> 34 | E13: =COUNTIFS(Events!$F$6:$F$3108,$A13,Events!$K$6:$K$3108,"Non-trading day") -> 5 | F13: =IFERROR(AVERAGEIFS(Events!$T$6:$T$3108,Events!$F$6:$F$3108,$A13),"") -> 0.001099614 | G13: =IFERROR(COUNTIFS(Events!$F$6:$F$3108,$A13,Events!$T$6:$T$3108,">0")/COUNTIFS(Events!$F$6:$F$3108,$A13,Events!$T$6:$T$3108,"<>"),"") -> 0.45 | H13: =IFERROR(AVERAGEIFS(Events!$W$6:$W$3108,Events!$F$6:$F$3108,$A13),"") -> -0.0003175078 | I13: =IFERROR(AVERAGEIFS(Events!$AC$6:$AC$3108,Events!$F$6:$F$3108,$A13),"") -> 0.018975664 | J13: =IFERROR(COUNTIFS(Events!$F$6:$F$3108,$A13,Events!$AU$6:$AU$3108,">0")/COUNTIFS(Events!$F$6:$F$3108,$A13,Events!$AU$6:$AU$3108,"<>"),"") -> 0.9137931 | K13: =IFERROR(COUNTIFS(Events!$F$6:$F$3108,$A13,Events!$BA$6:$BA$3108,">0")/COUNTIFS(Events!$F$6:$F$3108,$A13,Events!$BA$6:$BA$3108,"<>"),"") -> 0.5862069 | L13: =IFERROR(AVERAGEIFS(Events!$AY$6:$AY$3108,Events!$F$6:$F$3108,$A13),"") -> 0.0020745859 | M13: =IFERROR(AVERAGEIFS(Events!$CJ$6:$CJ$3108,Events!$F$6:$F$3108,$A13),"") -> 0.056537442 | N13: =IFERROR(AVERAGEIFS(Events!$CK$6:$CK$3108,Events!$F$6:$F$3108,$A13),"") -> 0.36405658 | O13: =IFERROR(AVERAGEIFS(Events!$CI$6:$CI$3108,Events!$F$6:$F$3108,$A13),"") -> -0.088350378 | P13: =COUNTIFS(Events!$F$6:$F$3108,$A13,Events!$CM$6:$CM$3108,"Yes",Events!$CL$6:$CL$3108,"<>") -> 29 | Q13: =IFERROR(AVERAGEIFS(Events!$CL$6:$CL$3108,Events!$F$6:$F$3108,$A13,Events!$CM$6:$CM$3108,"Yes"),"") -> -0.015352254 | R13: =IFERROR(COUNTIFS(Events!$F$6:$F$3108,$A13,Events!$CL$6:$CL$3108,">0",Events!$CM$6:$CM$3108,"Yes")/COUNTIFS(Events!$F$6:$F$3108,$A13,Events!$CL$6:$CL$3108,"<>",Events!$CM$6:$CM$3108,"Yes"),"") -> 0.34482759
A14: Miscellaneous | B14: =COUNTIFS(Events!$F$6:$F$3108,$A14) -> 60 | C14: =COUNTIFS(Events!$F$6:$F$3108,$A14,Events!$K$6:$K$3108,"After close") -> 48 | D14: =COUNTIFS(Events!$F$6:$F$3108,$A14,Events!$K$6:$K$3108,"During market") -> 12 | E14: =COUNTIFS(Events!$F$6:$F$3108,$A14,Events!$K$6:$K$3108,"Non-trading day") -> 0 | F14: =IFERROR(AVERAGEIFS(Events!$T$6:$T$3108,Events!$F$6:$F$3108,$A14),"") -> 0.011690731 | G14: =IFERROR(COUNTIFS(Events!$F$6:$F$3108,$A14,Events!$T$6:$T$3108,">0")/COUNTIFS(Events!$F$6:$F$3108,$A14,Events!$T$6:$T$3108,"<>"),"") -> 0.55 | H14: =IFERROR(AVERAGEIFS(Events!$W$6:$W$3108,Events!$F$6:$F$3108,$A14),"") -> 0.011323143 | I14: =IFERROR(AVERAGEIFS(Events!$AC$6:$AC$3108,Events!$F$6:$F$3108,$A14),"") -> 0.036730765 | J14: =IFERROR(COUNTIFS(Events!$F$6:$F$3108,$A14,Events!$AU$6:$AU$3108,">0")/COUNTIFS(Events!$F$6:$F$3108,$A14,Events!$AU$6:$AU$3108,"<>"),"") -> 1 | K14: =IFERROR(COUNTIFS(Events!$F$6:$F$3108,$A14,Events!$BA$6:$BA$3108,">0")/COUNTIFS(Events!$F$6:$F$3108,$A14,Events!$BA$6:$BA$3108,"<>"),"") -> 0.88135593 | L14: =IFERROR(AVERAGEIFS(Events!$AY$6:$AY$3108,Events!$F$6:$F$3108,$A14),"") -> 0.0068212859 | M14: =IFERROR(AVERAGEIFS(Events!$CJ$6:$CJ$3108,Events!$F$6:$F$3108,$A14),"") -> 0.068390157 | N14: =IFERROR(AVERAGEIFS(Events!$CK$6:$CK$3108,Events!$F$6:$F$3108,$A14),"") -> 0.59067721 | O14: =IFERROR(AVERAGEIFS(Events!$CI$6:$CI$3108,Events!$F$6:$F$3108,$A14),"") -> -0.15156753 | P14: =COUNTIFS(Events!$F$6:$F$3108,$A14,Events!$CM$6:$CM$3108,"Yes",Events!$CL$6:$CL$3108,"<>") -> 26 | Q14: =IFERROR(AVERAGEIFS(Events!$CL$6:$CL$3108,Events!$F$6:$F$3108,$A14,Events!$CM$6:$CM$3108,"Yes"),"") -> 0.013619865 | R14: =IFERROR(COUNTIFS(Events!$F$6:$F$3108,$A14,Events!$CL$6:$CL$3108,">0",Events!$CM$6:$CM$3108,"Yes")/COUNTIFS(Events!$F$6:$F$3108,$A14,Events!$CL$6:$CL$3108,"<>",Events!$CM$6:$CM$3108,"Yes"),"") -> 0.42307692
A15: Personal Care | B15: =COUNTIFS(Events!$F$6:$F$3108,$A15) -> 60 | C15: =COUNTIFS(Events!$F$6:$F$3108,$A15,Events!$K$6:$K$3108,"After close") -> 37 | D15: =COUNTIFS(Events!$F$6:$F$3108,$A15,Events!$K$6:$K$3108,"During market") -> 22 | E15: =COUNTIFS(Events!$F$6:$F$3108,$A15,Events!$K$6:$K$3108,"Non-trading day") -> 1 | F15: =IFERROR(AVERAGEIFS(Events!$T$6:$T$3108,Events!$F$6:$F$3108,$A15),"") -> 0.0019405102 | G15: =IFERROR(COUNTIFS(Events!$F$6:$F$3108,$A15,Events!$T$6:$T$3108,">0")/COUNTIFS(Events!$F$6:$F$3108,$A15,Events!$T$6:$T$3108,"<>"),"") -> 0.43333333 | H15: =IFERROR(AVERAGEIFS(Events!$W$6:$W$3108,Events!$F$6:$F$3108,$A15),"") -> 0.001629057 | I15: =IFERROR(AVERAGEIFS(Events!$AC$6:$AC$3108,Events!$F$6:$F$3108,$A15),"") -> 0.026487864 | J15: =IFERROR(COUNTIFS(Events!$F$6:$F$3108,$A15,Events!$AU$6:$AU$3108,">0")/COUNTIFS(Events!$F$6:$F$3108,$A15,Events!$AU$6:$AU$3108,"<>"),"") -> 0.86666667 | K15: =IFERROR(COUNTIFS(Events!$F$6:$F$3108,$A15,Events!$BA$6:$BA$3108,">0")/COUNTIFS(Events!$F$6:$F$3108,$A15,Events!$BA$6:$BA$3108,"<>"),"") -> 0.76271186 | L15: =IFERROR(AVERAGEIFS(Events!$AY$6:$AY$3108,Events!$F$6:$F$3108,$A15),"") -> -0.00012932181 | M15: =IFERROR(AVERAGEIFS(Events!$CJ$6:$CJ$3108,Events!$F$6:$F$3108,$A15),"") -> 0.057657326 | N15: =IFERROR(AVERAGEIFS(Events!$CK$6:$CK$3108,Events!$F$6:$F$3108,$A15),"") -> 0.47447817 | O15: =IFERROR(AVERAGEIFS(Events!$CI$6:$CI$3108,Events!$F$6:$F$3108,$A15),"") -> -0.13283822 | P15: =COUNTIFS(Events!$F$6:$F$3108,$A15,Events!$CM$6:$CM$3108,"Yes",Events!$CL$6:$CL$3108,"<>") -> 15 | Q15: =IFERROR(AVERAGEIFS(Events!$CL$6:$CL$3108,Events!$F$6:$F$3108,$A15,Events!$CM$6:$CM$3108,"Yes"),"") -> 0.036853097 | R15: =IFERROR(COUNTIFS(Events!$F$6:$F$3108,$A15,Events!$CL$6:$CL$3108,">0",Events!$CM$6:$CM$3108,"Yes")/COUNTIFS(Events!$F$6:$F$3108,$A15,Events!$CL$6:$CL$3108,"<>",Events!$CM$6:$CM$3108,"Yes"),"") -> 0.4
... A47: Brew/Distilleries | B47: =COUNTIFS(Events!$F$6:$F$3108,$A47) -> 15 | C47: =COUNTIFS(Events!$F$6:$F$3108,$A47,Events!$K$6:$K$3108,"After close") -> 9 | D47: =COUNTIFS(Events!$F$6:$F$3108,$A47,Events!$K$6:$K$3108,"During market") -> 6 | E47: =COUNTIFS(Events!$F$6:$F$3108,$A47,Events!$K$6:$K$3108,"Non-trading day") -> 0 | F47: =IFERROR(AVERAGEIFS(Events!$T$6:$T$3108,Events!$F$6:$F$3108,$A47),"") -> 0.020078375 | G47: =IFERROR(COUNTIFS(Events!$F$6:$F$3108,$A47,Events!$T$6:$T$3108,">0")/COUNTIFS(Events!$F$6:$F$3108,$A47,Events!$T$6:$T$3108,"<>"),"") -> 0.73333333 | H47: =IFERROR(AVERAGEIFS(Events!$W$6:$W$3108,Events!$F$6:$F$3108,$A47),"") -> 0.016717512 | I47: =IFERROR(AVERAGEIFS(Events!$AC$6:$AC$3108,Events!$F$6:$F$3108,$A47),"") -> 0.021710635 | J47: =IFERROR(COUNTIFS(Events!$F$6:$F$3108,$A47,Events!$AU$6:$AU$3108,">0")/COUNTIFS(Events!$F$6:$F$3108,$A47,Events!$AU$6:$AU$3108,"<>"),"") -> 0.93333333 | K47: =IFERROR(COUNTIFS(Events!$F$6:$F$3108,$A47,Events!$BA$6:$BA$3108,">0")/COUNTIFS(Events!$F$6:$F$3108,$A47,Events!$BA$6:$BA$3108,"<>"),"") -> 0.71428571 | L47: =IFERROR(AVERAGEIFS(Events!$AY$6:$AY$3108,Events!$F$6:$F$3108,$A47),"") -> 0.0057940756 | M47: =IFERROR(AVERAGEIFS(Events!$CJ$6:$CJ$3108,Events!$F$6:$F$3108,$A47),"") -> 0.080913363 | N47: =IFERROR(AVERAGEIFS(Events!$CK$6:$CK$3108,Events!$F$6:$F$3108,$A47),"") -> 0.4175726 | O47: =IFERROR(AVERAGEIFS(Events!$CI$6:$CI$3108,Events!$F$6:$F$3108,$A47),"") -> 0.081386043 | P47: =COUNTIFS(Events!$F$6:$F$3108,$A47,Events!$CM$6:$CM$3108,"Yes",Events!$CL$6:$CL$3108,"<>") -> 0 | Q47: =IFERROR(AVERAGEIFS(Events!$CL$6:$CL$3108,Events!$F$6:$F$3108,$A47,Events!$CM$6:$CM$3108,"Yes"),"") | R47: =IFERROR(COUNTIFS(Events!$F$6:$F$3108,$A47,Events!$CL$6:$CL$3108,">0",Events!$CM$6:$CM$3108,"Yes")/COUNTIFS(Events!$F$6:$F$3108,$A47,Events!$CL$6:$CL$3108,"<>",Events!$CM$6:$CM$3108,"Yes"),"")
A48: All industries | B48: =COUNTIFS(Events!$F$6:$F$3108,"<>") -> 1917 | C48: =COUNTIFS(Events!$F$6:$F$3108,"<>",Events!$K$6:$K$3108,"After close") -> 1147 | D48: =COUNTIFS(Events!$F$6:$F$3108,"<>",Events!$K$6:$K$3108,"During market") -> 607 | E48: =COUNTIFS(Events!$F$6:$F$3108,"<>",Events!$K$6:$K$3108,"Non-trading day") -> 154 | F48: =IFERROR(AVERAGEIFS(Events!$T$6:$T$3108,Events!$F$6:$F$3108,"<>"),"") -> 0.0019821077 | G48: =IFERROR(COUNTIFS(Events!$F$6:$F$3108,"<>",Events!$T$6:$T$3108,">0")/COUNTIFS(Events!$F$6:$F$3108,"<>",Events!$T$6:$T$3108,"<>"),"") -> 0.50653424 | H48: =IFERROR(AVERAGEIFS(Events!$W$6:$W$3108,Events!$F$6:$F$3108,"<>"),"") -> 0.0018268191 | I48: =IFERROR(AVERAGEIFS(Events!$AC$6:$AC$3108,Events!$F$6:$F$3108,"<>"),"") -> 0.028900134 | J48: =IFERROR(COUNTIFS(Events!$F$6:$F$3108,"<>",Events!$AU$6:$AU$3108,">0")/COUNTIFS(Events!$F$6:$F$3108,"<>",Events!$AU$6:$AU$3108,"<>"),"") -> 0.84734869 | K48: =IFERROR(COUNTIFS(Events!$F$6:$F$3108,"<>",Events!$BA$6:$BA$3108,">0")/COUNTIFS(Events!$F$6:$F$3108,"<>",Events!$BA$6:$BA$3108,"<>"),"") -> 0.71156138 | L48: =IFERROR(AVERAGEIFS(Events!$AY$6:$AY$3108,Events!$F$6:$F$3108,"<>"),"") -> 0.0016517823 | M48: =IFERROR(AVERAGEIFS(Events!$CJ$6:$CJ$3108,Events!$F$6:$F$3108,"<>"),"") -> 0.063233345 | N48: =IFERROR(AVERAGEIFS(Events!$CK$6:$CK$3108,Events!$F$6:$F$3108,"<>"),"") -> 0.47873148 | O48: =IFERROR(AVERAGEIFS(Events!$CI$6:$CI$3108,Events!$F$6:$F$3108,"<>"),"") -> -0.13143158 | P48: =COUNTIFS(Events!$F$6:$F$3108,"<>",Events!$CM$6:$CM$3108,"Yes",Events!$CL$6:$CL$3108,"<>") -> 847 | Q48: =IFERROR(AVERAGEIFS(Events!$CL$6:$CL$3108,Events!$F$6:$F$3108,"<>",Events!$CM$6:$CM$3108,"Yes"),"") -> 0.030142693 | R48: =IFERROR(COUNTIFS(Events!$F$6:$F$3108,"<>",Events!$CL$6:$CL$3108,">0",Events!$CM$6:$CM$3108,"Yes")/COUNTIFS(Events!$F$6:$F$3108,"<>",Events!$CL$6:$CL$3108,"<>",Events!$CM$6:$CM$3108,"Yes"),"") -> 0.42502952

Sheet By stock
A1: By stock
A2: Formulas over the Events sheet, all 15 quarters.
A3: Symbol | B3: Company | C3: Industry | D3: Results events | E3: After close | F3: Avg three-day sum % | G3: % three-day positive | H3: Avg excess vs Nifty % | I3: Avg size of reaction move % | J3: % sales up YoY | K3: % profit up YoY | L3: Avg EBITDA margin chg YoY (pts) | M3: Avg expected move % (options) | N3: Avg actual / expected move (x) | O3: Avg IV drop % | P3: Run-up trades (rule pass) | Q3: Run-up avg return % (rule pass) | R3: Run-up win rate (rule pass)
A4: 360ONE | B4: =INDEX(Events!$E$6:$E$3108,MATCH($A4,Events!$D$6:$D$3108,0)) -> 360 ONE WAM LIMITED | C4: =INDEX(Events!$F$6:$F$3108,MATCH($A4,Events!$D$6:$D$3108,0)) -> 0 | D4: =COUNTIFS(Events!$D$6:$D$3108,$A4) -> 15 | E4: =COUNTIFS(Events!$D$6:$D$3108,$A4,Events!$K$6:$K$3108,"After close") -> 12 | F4: =IFERROR(AVERAGEIFS(Events!$T$6:$T$3108,Events!$D$6:$D$3108,$A4),"") -> 0.00059493517 | G4: =IFERROR(COUNTIFS(Events!$D$6:$D$3108,$A4,Events!$T$6:$T$3108,">0")/COUNTIFS(Events!$D$6:$D$3108,$A4,Events!$T$6:$T$3108,"<>"),"") -> 0.64285714 | H4: =IFERROR(AVERAGEIFS(Events!$W$6:$W$3108,Events!$D$6:$D$3108,$A4),"") -> 8.5437957e-05 | I4: =IFERROR(AVERAGEIFS(Events!$AC$6:$AC$3108,Events!$D$6:$D$3108,$A4),"") -> 0.032123706 | J4: =IFERROR(COUNTIFS(Events!$D$6:$D$3108,$A4,Events!$AU$6:$AU$3108,">0")/COUNTIFS(Events!$D$6:$D$3108,$A4,Events!$AU$6:$AU$3108,"<>"),"") -> 0.92857143 | K4: =IFERROR(COUNTIFS(Events!$D$6:$D$3108,$A4,Events!$BA$6:$BA$3108,">0")/COUNTIFS(Events!$D$6:$D$3108,$A4,Events!$BA$6:$BA$3108,"<>"),"") -> 1 | L4: =IFERROR(AVERAGEIFS(Events!$AY$6:$AY$3108,Events!$D$6:$D$3108,$A4),"") | M4: =IFERROR(AVERAGEIFS(Events!$CJ$6:$CJ$3108,Events!$D$6:$D$3108,$A4),"") -> 0.058463763 | N4: =IFERROR(AVERAGEIFS(Events!$CK$6:$CK$3108,Events!$D$6:$D$3108,$A4),"") -> 0.44387782 | O4: =IFERROR(AVERAGEIFS(Events!$CI$6:$CI$3108,Events!$D$6:$D$3108,$A4),"") -> -0.15649243 | P4: =COUNTIFS(Events!$D$6:$D$3108,$A4,Events!$CM$6:$CM$3108,"Yes",Events!$CL$6:$CL$3108,"<>") -> 5 | Q4: =IFERROR(AVERAGEIFS(Events!$CL$6:$CL$3108,Events!$D$6:$D$3108,$A4,Events!$CM$6:$CM$3108,"Yes"),"") -> 0.069709918 | R4: =IFERROR(COUNTIFS(Events!$D$6:$D$3108,$A4,Events!$CL$6:$CL$3108,">0",Events!$CM$6:$CM$3108,"Yes")/COUNTIFS(Events!$D$6:$D$3108,$A4,Events!$CL$6:$CL$3108,"<>",Events!$CM$6:$CM$3108,"Yes"),"") -> 0.4
A5: ABB | B5: =INDEX(Events!$E$6:$E$3108,MATCH($A5,Events!$D$6:$D$3108,0)) -> ABB India Limited | C5: =INDEX(Events!$F$6:$F$3108,MATCH($A5,Events!$D$6:$D$3108,0)) -> Electrical Equipment | D5: =COUNTIFS(Events!$D$6:$D$3108,$A5) -> 15 | E5: =COUNTIFS(Events!$D$6:$D$3108,$A5,Events!$K$6:$K$3108,"After close") -> 13 | F5: =IFERROR(AVERAGEIFS(Events!$T$6:$T$3108,Events!$D$6:$D$3108,$A5),"") -> 0.0058053874 | G5: =IFERROR(COUNTIFS(Events!$D$6:$D$3108,$A5,Events!$T$6:$T$3108,">0")/COUNTIFS(Events!$D$6:$D$3108,$A5,Events!$T$6:$T$3108,"<>"),"") -> 0.6 | H5: =IFERROR(AVERAGEIFS(Events!$W$6:$W$3108,Events!$D$6:$D$3108,$A5),"") -> 0.0057663658 | I5: =IFERROR(AVERAGEIFS(Events!$AC$6:$AC$3108,Events!$D$6:$D$3108,$A5),"") -> 0.046552597 | J5: =IFERROR(COUNTIFS(Events!$D$6:$D$3108,$A5,Events!$AU$6:$AU$3108,">0")/COUNTIFS(Events!$D$6:$D$3108,$A5,Events!$AU$6:$AU$3108,"<>"),"") -> 1 | K5: =IFERROR(COUNTIFS(Events!$D$6:$D$3108,$A5,Events!$BA$6:$BA$3108,">0")/COUNTIFS(Events!$D$6:$D$3108,$A5,Events!$BA$6:$BA$3108,"<>"),"") -> 0.76923077 | L5: =IFERROR(AVERAGEIFS(Events!$AY$6:$AY$3108,Events!$D$6:$D$3108,$A5),"") -> 0.0089011877 | M5: =IFERROR(AVERAGEIFS(Events!$CJ$6:$CJ$3108,Events!$D$6:$D$3108,$A5),"") -> 0.073012832 | N5: =IFERROR(AVERAGEIFS(Events!$CK$6:$CK$3108,Events!$D$6:$D$3108,$A5),"") -> 0.6361731 | O5: =IFERROR(AVERAGEIFS(Events!$CI$6:$CI$3108,Events!$D$6:$D$3108,$A5),"") -> -0.13998456 | P5: =COUNTIFS(Events!$D$6:$D$3108,$A5,Events!$CM$6:$CM$3108,"Yes",Events!$CL$6:$CL$3108,"<>") -> 10 | Q5: =IFERROR(AVERAGEIFS(Events!$CL$6:$CL$3108,Events!$D$6:$D$3108,$A5,Events!$CM$6:$CM$3108,"Yes"),"") -> 0.12724421 | R5: =IFERROR(COUNTIFS(Events!$D$6:$D$3108,$A5,Events!$CL$6:$CL$3108,">0",Events!$CM$6:$CM$3108,"Yes")/COUNTIFS(Events!$D$6:$D$3108,$A5,Events!$CL$6:$CL$3108,"<>",Events!$CM$6:$CM$3108,"Yes"),"") -> 0.7
A6: ABCAPITAL | B6: =INDEX(Events!$E$6:$E$3108,MATCH($A6,Events!$D$6:$D$3108,0)) -> Aditya Birla Capital Limited | C6: =INDEX(Events!$F$6:$F$3108,MATCH($A6,Events!$D$6:$D$3108,0)) -> 0 | D6: =COUNTIFS(Events!$D$6:$D$3108,$A6) -> 15 | E6: =COUNTIFS(Events!$D$6:$D$3108,$A6,Events!$K$6:$K$3108,"After close") -> 3 | F6: =IFERROR(AVERAGEIFS(Events!$T$6:$T$3108,Events!$D$6:$D$3108,$A6),"") -> 0.027439865 | G6: =IFERROR(COUNTIFS(Events!$D$6:$D$3108,$A6,Events!$T$6:$T$3108,">0")/COUNTIFS(Events!$D$6:$D$3108,$A6,Events!$T$6:$T$3108,"<>"),"") -> 0.73333333 | H6: =IFERROR(AVERAGEIFS(Events!$W$6:$W$3108,Events!$D$6:$D$3108,$A6),"") -> 0.020257381 | I6: =IFERROR(AVERAGEIFS(Events!$AC$6:$AC$3108,Events!$D$6:$D$3108,$A6),"") -> 0.0278737 | J6: =IFERROR(COUNTIFS(Events!$D$6:$D$3108,$A6,Events!$AU$6:$AU$3108,">0")/COUNTIFS(Events!$D$6:$D$3108,$A6,Events!$AU$6:$AU$3108,"<>"),"") -> 1 | K6: =IFERROR(COUNTIFS(Events!$D$6:$D$3108,$A6,Events!$BA$6:$BA$3108,">0")/COUNTIFS(Events!$D$6:$D$3108,$A6,Events!$BA$6:$BA$3108,"<>"),"") -> 0.71428571 | L6: =IFERROR(AVERAGEIFS(Events!$AY$6:$AY$3108,Events!$D$6:$D$3108,$A6),"") | M6: =IFERROR(AVERAGEIFS(Events!$CJ$6:$CJ$3108,Events!$D$6:$D$3108,$A6),"") -> 0.075392046 | N6: =IFERROR(AVERAGEIFS(Events!$CK$6:$CK$3108,Events!$D$6:$D$3108,$A6),"") -> 0.37906816 | O6: =IFERROR(AVERAGEIFS(Events!$CI$6:$CI$3108,Events!$D$6:$D$3108,$A6),"") -> -0.076674509 | P6: =COUNTIFS(Events!$D$6:$D$3108,$A6,Events!$CM$6:$CM$3108,"Yes",Events!$CL$6:$CL$3108,"<>") -> 3 | Q6: =IFERROR(AVERAGEIFS(Events!$CL$6:$CL$3108,Events!$D$6:$D$3108,$A6,Events!$CM$6:$CM$3108,"Yes"),"") -> 0.080976809 | R6: =IFERROR(COUNTIFS(Events!$D$6:$D$3108,$A6,Events!$CL$6:$CL$3108,">0",Events!$CM$6:$CM$3108,"Yes")/COUNTIFS(Events!$D$6:$D$3108,$A6,Events!$CL$6:$CL$3108,"<>",Events!$CM$6:$CM$3108,"Yes"),"") -> 0.66666667
